Workbook

Sheet Testes estatísticos
A1: TESTES ESTATÍSTICOS — cálculo passo a passo, verificável célula a célula
A2: Todos os valores desta folha são calculados por fórmula a partir dos dados em bruto das colunas B e C. Nada está escrito à mão.
A4: 1. DADOS EMPARELHADOS — os 138 pares concluídos com sucesso pelas duas estratégias (Secção 5.4) | I4: 2. WILCOXON EMPARELHADO
A5: Cenário | B5: Temporal (s) | C5: Estados (s) | D5: Diferença d | E5: |d| | F5: Posto de |d| | G5: Sinal | I5: Número de pares (n) | J5: =COUNT(D6:D143) -> 138
A6: R01 | B6: 53.251825 | C6: 51.604 | D6: =C6-B6 -> -1.647825 | E6: =ABS(D6) -> 1.647825 | F6: =_xlfn.RANK.AVG(E6,$E$6:$E$143,1) -> 29 | G6: =IF(D6<0,-1,1) -> -1 | I6: Vitórias dos estados (d < 0) | J6: =COUNTIF(D6:D143,"<0") -> 109
A7: R01 | B7: 54.482239 | C7: 48.698 | D7: =C7-B7 -> -5.784239 | E7: =ABS(D7) -> 5.784239 | F7: =_xlfn.RANK.AVG(E7,$E$6:$E$143,1) -> 114 | G7: =IF(D7<0,-1,1) -> -1 | I7: Vitórias do temporal (d > 0) | J7: =COUNTIF(D6:D143,">0") -> 29
A8: R01 | B8: 50.47051 | C8: 53.615 | D8: =C8-B8 -> 3.14449 | E8: =ABS(D8) -> 3.14449 | F8: =_xlfn.RANK.AVG(E8,$E$6:$E$143,1) -> 65 | G8: =IF(D8<0,-1,1) -> 1 | I8: Soma dos postos com d < 0 (W−) | J8: =SUMIF(G6:G143,-1,F6:F143) -> 7875
A9: R01 | B9: 49.497041 | C9: 43.335 | D9: =C9-B9 -> -6.162041 | E9: =ABS(D9) -> 6.162041 | F9: =_xlfn.RANK.AVG(E9,$E$6:$E$143,1) -> 117 | G9: =IF(D9<0,-1,1) -> -1 | I9: Soma dos postos com d > 0 (W+) | J9: =SUMIF(G6:G143,1,F6:F143) -> 1716
A10: R01 | B10: 49.449316 | C10: 47.987 | D10: =C10-B10 -> -1.462316 | E10: =ABS(D10) -> 1.462316 | F10: =_xlfn.RANK.AVG(E10,$E$6:$E$143,1) -> 26 | G10: =IF(D10<0,-1,1) -> -1 | I10: Estatística W (a menor das duas) | J10: =MIN(J8,J9) -> 1716
A11: R01 | B11: 45.471912 | C11: 50.185 | D11: =C11-B11 -> 4.713088 | E11: =ABS(D11) -> 4.713088 | F11: =_xlfn.RANK.AVG(E11,$E$6:$E$143,1) -> 108 | G11: =IF(D11<0,-1,1) -> 1 | I11: Média esperada de W se não houvesse diferença | J11: =J5*(J5+1)/4 -> 4795.5
A12: R01 | B12: 52.219331 | C12: 43.218 | D12: =C12-B12 -> -9.001331 | E12: =ABS(D12) -> 9.001331 | F12: =_xlfn.RANK.AVG(E12,$E$6:$E$143,1) -> 135 | G12: =IF(D12<0,-1,1) -> -1 | I12: Desvio-padrão de W | J12: =SQRT(J5*(J5+1)*(2*J5+1)/24) -> 470.52338
A13: R01 | B13: 49.492879 | C13: 48.232 | D13: =C13-B13 -> -1.260879 | E13: =ABS(D13) -> 1.260879 | F13: =_xlfn.RANK.AVG(E13,$E$6:$E$143,1) -> 21 | G13: =IF(D13<0,-1,1) -> -1 | I13: z = (W − média) / desvio-padrão | J13: =(J10-J11)/J12 -> -6.5448395
A14: R01 | B14: 48.123761 | C14: 48.169 | D14: =C14-B14 -> 0.045239 | E14: =ABS(D14) -> 0.045239 | F14: =_xlfn.RANK.AVG(E14,$E$6:$E$143,1) -> 1 | G14: =IF(D14<0,-1,1) -> 1 | I14: p (bilateral, aproximação normal) | J14: =2*_xlfn.NORM.S.DIST(-ABS(J13),TRUE()) -> 5.9559311e-11
A15: R01 | B15: 48.266391 | C15: 47.696 | D15: =C15-B15 -> -0.570391 | E15: =ABS(D15) -> 0.570391 | F15: =_xlfn.RANK.AVG(E15,$E$6:$E$143,1) -> 11 | G15: =IF(D15<0,-1,1) -> -1
A16: R01 | B16: 45.297633 | C16: 43.54 | D16: =C16-B16 -> -1.757633 | E16: =ABS(D16) -> 1.757633 | F16: =_xlfn.RANK.AVG(E16,$E$6:$E$143,1) -> 30 | G16: =IF(D16<0,-1,1) -> -1
A17: R01 | B17: 54.362179 | C17: 46.066 | D17: =C17-B17 -> -8.296179 | E17: =ABS(D17) -> 8.296179 | F17: =_xlfn.RANK.AVG(E17,$E$6:$E$143,1) -> 129 | G17: =IF(D17<0,-1,1) -> -1 | I17: 3. TESTE t EMPARELHADO (verificação — função nativa do Excel)
A18: R01 | B18: 48.153807 | C18: 51.565 | D18: =C18-B18 -> 3.411193 | E18: =ABS(D18) -> 3.411193 | F18: =_xlfn.RANK.AVG(E18,$E$6:$E$143,1) -> 73 | G18: =IF(D18<0,-1,1) -> 1 | I18: p do teste t emparelhado bilateral | J18: =_xlfn.T.TEST(B6:B143,C6:C143,2,1) -> 7.7483042e-12
A19: R01 | B19: 51.603393 | C19: 52.33 | D19: =C19-B19 -> 0.726607 | E19: =ABS(D19) -> 0.726607 | F19: =_xlfn.RANK.AVG(E19,$E$6:$E$143,1) -> 14 | G19: =IF(D19<0,-1,1) -> 1 | I19: Diferença média (s) | J19: =AVERAGE(D6:D143) -> -2.3932968
A20: R01 | B20: 45.411986 | C20: 48.978 | D20: =C20-B20 -> 3.566014 | E20: =ABS(D20) -> 3.566014 | F20: =_xlfn.RANK.AVG(E20,$E$6:$E$143,1) -> 77 | G20: =IF(D20<0,-1,1) -> 1 | I20: Melhoria relativa (%) | J20: =-J19/AVERAGE(B6:B143)*100 -> 4.8443214
A21: R01 | B21: 54.482655 | C21: 43.449 | D21: =C21-B21 -> -11.033655 | E21: =ABS(D21) -> 11.033655 | F21: =_xlfn.RANK.AVG(E21,$E$6:$E$143,1) -> 136 | G21: =IF(D21<0,-1,1) -> -1 | I21: Correlação rank-biserial (dimensão do efeito) | J21: =2*J10/(138*(138+1)/2)-1 -> -0.64216453
A22: R01 | B22: 50.355967 | C22: 46.245 | D22: =C22-B22 -> -4.110967 | E22: =ABS(D22) -> 4.110967 | F22: =_xlfn.RANK.AVG(E22,$E$6:$E$143,1) -> 99 | G22: =IF(D22<0,-1,1) -> -1
A23: R01 | B23: 54.446194 | C23: 48.187 | D23: =C23-B23 -> -6.259194 | E23: =ABS(D23) -> 6.259194 | F23: =_xlfn.RANK.AVG(E23,$E$6:$E$143,1) -> 119 | G23: =IF(D23<0,-1,1) -> -1 | I23: 4. VERIFICAÇÃO DA NORMALIDADE DAS DIFERENÇAS
A24: R04 | B24: 50.219495 | C24: 44.757183 | D24: =C24-B24 -> -5.462312 | E24: =ABS(D24) -> 5.462312 | F24: =_xlfn.RANK.AVG(E24,$E$6:$E$143,1) -> 112 | G24: =IF(D24<0,-1,1) -> -1 | I24: Assimetria das diferenças (0 = simétrica) | J24: =SKEW(D6:D143) -> 0.026800293
A25: R04 | B25: 50.164877 | C25: 42.811829 | D25: =C25-B25 -> -7.353048 | E25: =ABS(D25) -> 7.353048 | F25: =_xlfn.RANK.AVG(E25,$E$6:$E$143,1) -> 127 | G25: =IF(D25<0,-1,1) -> -1 | I25: Curtose das diferenças (0 = normal) | J25: =KURT(D6:D143) -> 1.4382284
A26: R04 | B26: 46.285962 | C26: 42.650284 | D26: =C26-B26 -> -3.635678 | E26: =ABS(D26) -> 3.635678 | F26: =_xlfn.RANK.AVG(E26,$E$6:$E$143,1) -> 80 | G26: =IF(D26<0,-1,1) -> -1 | I26: Shapiro-Wilk (calculado fora do Excel) | J26: 0.00256
A27: R04 | B27: 46.446044 | C27: 42.737907 | D27: =C27-B27 -> -3.708137 | E27: =ABS(D27) -> 3.708137 | F27: =_xlfn.RANK.AVG(E27,$E$6:$E$143,1) -> 81 | G27: =IF(D27<0,-1,1) -> -1 | I27: Conclusão: normalidade rejeitada. O teste principal é o de Wilcoxon, definido por robustez e consistência entre métricas; o teste t fica como verificação.
A28: R04 | B28: 46.752469 | C28: 42.798577 | D28: =C28-B28 -> -3.953892 | E28: =ABS(D28) -> 3.953892 | F28: =_xlfn.RANK.AVG(E28,$E$6:$E$143,1) -> 95 | G28: =IF(D28<0,-1,1) -> -1
A29: R04 | B29: 50.397911 | C29: 47.57038 | D29: =C29-B29 -> -2.827531 | E29: =ABS(D29) -> 2.827531 | F29: =_xlfn.RANK.AVG(E29,$E$6:$E$143,1) -> 60 | G29: =IF(D29<0,-1,1) -> -1 | I29: 5. TESTE EXATO DE FISHER — SUBSTITUÍDO, ver folha «Testes emparelhados»
A30: R04 | B30: 47.55613 | C30: 45.355725 | D30: =C30-B30 -> -2.200405 | E30: =ABS(D30) -> 2.200405 | F30: =_xlfn.RANK.AVG(E30,$E$6:$E$143,1) -> 45 | G30: =IF(D30<0,-1,1) -> -1 | I30: As duas estratégias executaram as mesmas 147 condições auditadas, pelo que os resultados são emparelhados e o teste de Fisher, que pressupõe amostras independentes, não é aplicável. O capítulo usa o teste exato de McNemar, na folha «Testes emparelhados» (p = 1,000). O cálculo abaixo fica como registo do que foi feito antes da auditoria. | J30: Sucessos | K30: Falhas | L30: Total
A31: R04 | B31: 44.995549 | C31: 42.802085 | D31: =C31-B31 -> -2.193464 | E31: =ABS(D31) -> 2.193464 | F31: =_xlfn.RANK.AVG(E31,$E$6:$E$143,1) -> 44 | G31: =IF(D31<0,-1,1) -> -1 | I31: Temporal | J31: 143 | K31: 4 | L31: =J31+K31 -> 147
A32: R04 | B32: 45.070175 | C32: 42.667493 | D32: =C32-B32 -> -2.402682 | E32: =ABS(D32) -> 2.402682 | F32: =_xlfn.RANK.AVG(E32,$E$6:$E$143,1) -> 54 | G32: =IF(D32<0,-1,1) -> -1 | I32: Estados | J32: 142 | K32: 5 | L32: =J32+K32 -> 147
A33: R04 | B33: 45.011853 | C33: 42.7286 | D33: =C33-B33 -> -2.283253 | E33: =ABS(D33) -> 2.283253 | F33: =_xlfn.RANK.AVG(E33,$E$6:$E$143,1) -> 50 | G33: =IF(D33<0,-1,1) -> -1 | I33: Total | J33: =J31+J32 -> 285 | K33: =K31+K32 -> 9 | L33: =L31+L32 -> 294
A34: R04 | B34: 44.945807 | C34: 44.121078 | D34: =C34-B34 -> -0.824729 | E34: =ABS(D34) -> 0.824729 | F34: =_xlfn.RANK.AVG(E34,$E$6:$E$143,1) -> 15 | G34: =IF(D34<0,-1,1) -> -1
A35: R04 | B35: 46.232729 | C35: 42.780908 | D35: =C35-B35 -> -3.451821 | E35: =ABS(D35) -> 3.451821 | F35: =_xlfn.RANK.AVG(E35,$E$6:$E$143,1) -> 75 | G35: =IF(D35<0,-1,1) -> -1 | I35: Tabelas possíveis com as mesmas margens (falhas na temporal, de 0 a 10):
A36: R04 | B36: 46.792262 | C36: 42.655652 | D36: =C36-B36 -> -4.13661 | E36: =ABS(D36) -> 4.13661 | F36: =_xlfn.RANK.AVG(E36,$E$6:$E$143,1) -> 100 | G36: =IF(D36<0,-1,1) -> -1 | I36: Falhas temporal | J36: Probabilidade
A37: R04 | B37: 44.793365 | C37: 42.863996 | D37: =C37-B37 -> -1.929369 | E37: =ABS(D37) -> 1.929369 | F37: =_xlfn.RANK.AVG(E37,$E$6:$E$143,1) -> 31 | G37: =IF(D37<0,-1,1) -> -1 | I37: 0 | J37: =COMBIN($L$31,$L$31-I37)*COMBIN($L$32,$J$33-($L$31-I37))/COMBIN($L$33,$J$33) -> 0.0017217099
A38: R04 | B38: 44.94033 | C38: 42.679882 | D38: =C38-B38 -> -2.260448 | E38: =ABS(D38) -> 2.260448 | F38: =_xlfn.RANK.AVG(E38,$E$6:$E$143,1) -> 49 | G38: =IF(D38<0,-1,1) -> -1 | I38: 1 | J38: =COMBIN($L$31,$L$31-I38)*COMBIN($L$32,$J$33-($L$31-I38))/COMBIN($L$33,$J$33) -> 0.01638721
A39: R04 | B39: 44.956658 | C39: 48.329302 | D39: =C39-B39 -> 3.372644 | E39: =ABS(D39) -> 3.372644 | F39: =_xlfn.RANK.AVG(E39,$E$6:$E$143,1) -> 72 | G39: =IF(D39<0,-1,1) -> 1 | I39: 2 | J39: =COMBIN($L$31,$L$31-I39)*COMBIN($L$32,$J$33-($L$31-I39))/COMBIN($L$33,$J$33) -> 0.068358075
A40: R04 | B40: 45.054292 | C40: 42.94394 | D40: =C40-B40 -> -2.110352 | E40: =ABS(D40) -> 2.110352 | F40: =_xlfn.RANK.AVG(E40,$E$6:$E$143,1) -> 39 | G40: =IF(D40<0,-1,1) -> -1 | I40: 3 | J40: =COMBIN($L$31,$L$31-I40)*COMBIN($L$32,$J$33-($L$31-I40))/COMBIN($L$33,$J$33) -> 0.16402706
A41: R04 | B41: 44.984539 | C41: 47.410076 | D41: =C41-B41 -> 2.425537 | E41: =ABS(D41) -> 2.425537 | F41: =_xlfn.RANK.AVG(E41,$E$6:$E$143,1) -> 56 | G41: =IF(D41<0,-1,1) -> 1 | I41: 4 | J41: =COMBIN($L$31,$L$31-I41)*COMBIN($L$32,$J$33-($L$31-I41))/COMBIN($L$33,$J$33) -> 0.24950595
...

Sheet Estatística descritiva
A1: ESTATÍSTICA DESCRITIVA E INTERVALOS DE CONFIANÇA A 95 %
A2: Tudo o que está nesta folha é fórmula. Altere um valor nos dados de origem e todos os resumos, margens de erro e intervalos se atualizam. O IC 95 % é o intervalo em que se situa a média verdadeira da população, com 95 % de confiança.
A4: 1. TEMPO DE CICLO — os 138 pares concluídos com sucesso pelas duas estratégias (Secção 5.4)
A5: Condição | B5: n | C5: Média | D5: Mediana | E5: Desvio-padrão | F5: Mínimo | G5: Máximo | H5: Q1 | I5: Q3 | J5: IQR | K5: Erro-padrão | L5: t crítico | M5: Margem de erro | N5: IC 95 % inferior | O5: IC 95 % superior
A6: Arquitetura temporal | B6: =COUNT('Testes estatísticos'!B6:B143) -> 138 | C6: =AVERAGE('Testes estatísticos'!B6:B143) -> 49.404171 | D6: =MEDIAN('Testes estatísticos'!B6:B143) -> 49.471097 | E6: =_xlfn.STDEV.S('Testes estatísticos'!B6:B143) -> 3.0233209 | F6: =MIN('Testes estatísticos'!B6:B143) -> 44.793365 | G6: =MAX('Testes estatísticos'!B6:B143) -> 60.471985 | H6: =QUARTILE('Testes estatísticos'!B6:B143,1) -> 47.147709 | I6: =QUARTILE('Testes estatísticos'!B6:B143,3) -> 51.201511 | J6: =I6-H6 -> 4.0538025 | K6: =E6/SQRT(B6) -> 0.25736217 | L6: =TINV(0.05,B6-1) -> 1.9774312 | M6: =L6*K6 -> 0.50891599 | N6: =C6-M6 -> 48.895255 | O6: =C6+M6 -> 49.913087
A7: Arquitetura por respostas | B7: =COUNT('Testes estatísticos'!C6:C143) -> 138 | C7: =AVERAGE('Testes estatísticos'!C6:C143) -> 47.010874 | D7: =MEDIAN('Testes estatísticos'!C6:C143) -> 46.771963 | E7: =_xlfn.STDEV.S('Testes estatísticos'!C6:C143) -> 3.2383158 | F7: =MIN('Testes estatísticos'!C6:C143) -> 42.650284 | G7: =MAX('Testes estatísticos'!C6:C143) -> 56.05236 | H7: =QUARTILE('Testes estatísticos'!C6:C143,1) -> 45.01256 | I7: =QUARTILE('Testes estatísticos'!C6:C143,3) -> 48.1825 | J7: =I7-H7 -> 3.1699395 | K7: =E7/SQRT(B7) -> 0.27566374 | L7: =TINV(0.05,B7-1) -> 1.9774312 | M7: =L7*K7 -> 0.54510609 | N7: =C7-M7 -> 46.465768 | O7: =C7+M7 -> 47.55598
A8: Diferença (respostas − temporal) | B8: =COUNT('Testes estatísticos'!D6:D143) -> 138 | C8: =AVERAGE('Testes estatísticos'!D6:D143) -> -2.3932968 | D8: =MEDIAN('Testes estatísticos'!D6:D143) -> -2.3160935 | E8: =_xlfn.STDEV.S('Testes estatísticos'!D6:D143) -> 3.7549527 | F8: =MIN('Testes estatísticos'!D6:D143) -> -15.416956 | G8: =MAX('Testes estatísticos'!D6:D143) -> 8.877868 | H8: =QUARTILE('Testes estatísticos'!D6:D143,1) -> -4.0051845 | I8: =QUARTILE('Testes estatísticos'!D6:D143,3) -> -0.592563 | J8: =I8-H8 -> 3.4126215 | K8: =E8/SQRT(B8) -> 0.3196428 | L8: =TINV(0.05,B8-1) -> 1.9774312 | M8: =L8*K8 -> 0.63207165 | N8: =C8-M8 -> -3.0253685 | O8: =C8+M8 -> -1.7612252
A10: O IC 95 % da diferença não contém o zero, o que confirma que a redução do tempo de ciclo não é atribuível ao acaso. É a leitura equivalente à do valor de p do teste de Wilcoxon.
A12: 2. TEMPO DE CICLO POR CENÁRIO — arquitetura temporal
A13: Condição | B13: n | C13: Média | D13: Mediana | E13: Desvio-padrão | F13: Mínimo | G13: Máximo | H13: Q1 | I13: Q3 | J13: IQR | K13: Erro-padrão | L13: t crítico | M13: Margem de erro | N13: IC 95 % inferior | O13: IC 95 % superior
A14: R01 | B14: =COUNT('Testes estatísticos'!B6:B23) -> 18 | C14: =AVERAGE('Testes estatísticos'!B6:B23) -> 50.268834 | D14: =MEDIAN('Testes estatísticos'!B6:B23) -> 49.926504 | E14: =_xlfn.STDEV.S('Testes estatísticos'!B6:B23) -> 3.1670451 | F14: =MIN('Testes estatísticos'!B6:B23) -> 45.297633 | G14: =MAX('Testes estatísticos'!B6:B23) -> 54.482655 | H14: =QUARTILE('Testes estatísticos'!B6:B23,1) -> 48.181953 | I14: =QUARTILE('Testes estatísticos'!B6:B23,3) -> 52.993702 | J14: =I14-H14 -> 4.8117485 | K14: =E14/SQRT(B14) -> 0.7464797 | L14: =TINV(0.05,B14-1) -> 2.1098156 | M14: =L14*K14 -> 1.5749345 | N14: =C14-M14 -> 48.6939 | O14: =C14+M14 -> 51.843769
A15: R04 | B15: =COUNT('Testes estatísticos'!B24:B43) -> 20 | C15: =AVERAGE('Testes estatísticos'!B24:B43) -> 46.273134 | D15: =MEDIAN('Testes estatísticos'!B24:B43) -> 45.062233 | E15: =_xlfn.STDEV.S('Testes estatísticos'!B24:B43) -> 1.9028096 | F15: =MIN('Testes estatísticos'!B24:B43) -> 44.793365 | G15: =MAX('Testes estatísticos'!B24:B43) -> 50.397911 | H15: =QUARTILE('Testes estatísticos'!B24:B43,1) -> 44.968973 | I15: =QUARTILE('Testes estatísticos'!B24:B43,3) -> 46.762417 | J15: =I15-H15 -> 1.7934443 | K15: =E15/SQRT(B15) -> 0.42548116 | L15: =TINV(0.05,B15-1) -> 2.0930241 | M15: =L15*K15 -> 0.89054231 | N15: =C15-M15 -> 45.382591 | O15: =C15+M15 -> 47.163676
A16: R08 | B16: =COUNT('Testes estatísticos'!B44:B60) -> 17 | C16: =AVERAGE('Testes estatísticos'!B44:B60) -> 48.12439 | D16: =MEDIAN('Testes estatísticos'!B44:B60) -> 48.137439 | E16: =_xlfn.STDEV.S('Testes estatísticos'!B44:B60) -> 2.3514482 | F16: =MIN('Testes estatísticos'!B44:B60) -> 45.230344 | G16: =MAX('Testes estatísticos'!B44:B60) -> 52.309505 | H16: =QUARTILE('Testes estatísticos'!B44:B60,1) -> 45.473462 | I16: =QUARTILE('Testes estatísticos'!B44:B60,3) -> 50.125838 | J16: =I16-H16 -> 4.652376 | K16: =E16/SQRT(B16) -> 0.57030995 | L16: =TINV(0.05,B16-1) -> 2.1199053 | M16: =L16*K16 -> 1.2090031 | N16: =C16-M16 -> 46.915387 | O16: =C16+M16 -> 49.333393
A17: R10 | B17: =COUNT('Testes estatísticos'!B61:B75) -> 15 | C17: =AVERAGE('Testes estatísticos'!B61:B75) -> 50.620336 | D17: =MEDIAN('Testes estatísticos'!B61:B75) -> 50.322402 | E17: =_xlfn.STDEV.S('Testes estatísticos'!B61:B75) -> 2.6411362 | F17: =MIN('Testes estatísticos'!B61:B75) -> 46.490771 | G17: =MAX('Testes estatísticos'!B61:B75) -> 54.488682 | H17: =QUARTILE('Testes estatísticos'!B61:B75,1) -> 49.602298 | I17: =QUARTILE('Testes estatísticos'!B61:B75,3) -> 52.297612 | J17: =I17-H17 -> 2.695314 | K17: =E17/SQRT(B17) -> 0.68193844 | L17: =TINV(0.05,B17-1) -> 2.1447867 | M17: =L17*K17 -> 1.4626125 | N17: =C17-M17 -> 49.157724 | O17: =C17+M17 -> 52.082948
A18: O07 | B18: =COUNT('Testes estatísticos'!B76:B95) -> 20 | C18: =AVERAGE('Testes estatísticos'!B76:B95) -> 50.888972 | D18: =MEDIAN('Testes estatísticos'!B76:B95) -> 50.16863 | E18: =_xlfn.STDEV.S('Testes estatísticos'!B76:B95) -> 1.5545822 | F18: =MIN('Testes estatísticos'!B76:B95) -> 49.151743 | G18: =MAX('Testes estatísticos'!B76:B95) -> 56.114478 | H18: =QUARTILE('Testes estatísticos'!B76:B95,1) -> 50.0424 | I18: =QUARTILE('Testes estatísticos'!B76:B95,3) -> 51.597563 | J18: =I18-H18 -> 1.5551635 | K18: =E18/SQRT(B18) -> 0.34761515 | L18: =TINV(0.05,B18-1) -> 2.0930241 | M18: =L18*K18 -> 0.72756686 | N18: =C18-M18 -> 50.161405 | O18: =C18+M18 -> 51.616538
A19: O03 | B19: =COUNT('Testes estatísticos'!B96:B110) -> 15 | C19: =AVERAGE('Testes estatísticos'!B96:B110) -> 51.017659 | D19: =MEDIAN('Testes estatísticos'!B96:B110) -> 50.907726 | E19: =_xlfn.STDEV.S('Testes estatísticos'!B96:B110) -> 0.27498313 | F19: =MIN('Testes estatísticos'!B96:B110) -> 50.651345 | G19: =MAX('Testes estatísticos'!B96:B110) -> 51.59837 | H19: =QUARTILE('Testes estatísticos'!B96:B110,1) -> 50.829741 | I19: =QUARTILE('Testes estatísticos'!B96:B110,3) -> 51.177815 | J19: =I19-H19 -> 0.3480735 | K19: =E19/SQRT(B19) -> 0.071000338 | L19: =TINV(0.05,B19-1) -> 2.1447867 | M19: =L19*K19 -> 0.15228058 | N19: =C19-M19 -> 50.865379 | O19: =C19+M19 -> 51.16994
A20: O13 | B20: =COUNT('Testes estatísticos'!B111:B126) -> 16 | C20: =AVERAGE('Testes estatísticos'!B111:B126) -> 47.863755 | D20: =MEDIAN('Testes estatísticos'!B111:B126) -> 47.166024 | E20: =_xlfn.STDEV.S('Testes estatísticos'!B111:B126) -> 2.7910772 | F20: =MIN('Testes estatísticos'!B111:B126) -> 47.047639 | G20: =MAX('Testes estatísticos'!B111:B126) -> 58.322647 | H20: =QUARTILE('Testes estatísticos'!B111:B126,1) -> 47.088555 | I20: =QUARTILE('Testes estatísticos'!B111:B126,3) -> 47.226414 | J20: =I20-H20 -> 0.137859 | K20: =E20/SQRT(B20) -> 0.69776929 | L20: =TINV(0.05,B20-1) -> 2.1314495 | M20: =L20*K20 -> 1.48726 | N20: =C20-M20 -> 46.376495 | O20: =C20+M20 -> 49.351015
A21: O17 | B21: =COUNT('Testes estatísticos'!B127:B143) -> 17 | C21: =AVERAGE('Testes estatísticos'!B127:B143) -> 50.658226 | D21: =MEDIAN('Testes estatísticos'!B127:B143) -> 48.943417 | E21: =_xlfn.STDEV.S('Testes estatísticos'!B127:B143) -> 3.996751 | F21: =MIN('Testes estatísticos'!B127:B143) -> 47.24907 | G21: =MAX('Testes estatísticos'!B127:B143) -> 60.471985 | H21: =QUARTILE('Testes estatísticos'!B127:B143,1) -> 48.814803 | I21: =QUARTILE('Testes estatísticos'!B127:B143,3) -> 53.423732 | J21: =I21-H21 -> 4.608929 | K21: =E21/SQRT(B21) -> 0.9693545 | L21: =TINV(0.05,B21-1) -> 2.1199053 | M21: =L21*K21 -> 2.0549397 | N21: =C21-M21 -> 48.603286 | O21: =C21+M21 -> 52.713166
A24: 3. TEMPO DE CICLO POR CENÁRIO — arquitetura por respostas
A25: Condição | B25: n | C25: Média | D25: Mediana | E25: Desvio-padrão | F25: Mínimo | G25: Máximo | H25: Q1 | I25: Q3 | J25: IQR | K25: Erro-padrão | L25: t crítico | M25: Margem de erro | N25: IC 95 % inferior | O25: IC 95 % superior
A26: R01 | B26: =COUNT('Testes estatísticos'!C6:C23) -> 18 | C26: =AVERAGE('Testes estatísticos'!C6:C23) -> 47.949944 | D26: =MEDIAN('Testes estatísticos'!C6:C23) -> 48.178 | E26: =_xlfn.STDEV.S('Testes estatísticos'!C6:C23) -> 3.2030431 | F26: =MIN('Testes estatísticos'!C6:C23) -> 43.218 | G26: =MAX('Testes estatísticos'!C6:C23) -> 53.615 | H26: =QUARTILE('Testes estatísticos'!C6:C23,1) -> 46.11075 | I26: =QUARTILE('Testes estatísticos'!C6:C23,3) -> 49.88325 | J26: =I26-H26 -> 3.7725 | K26: =E26/SQRT(B26) -> 0.7549645 | L26: =TINV(0.05,B26-1) -> 2.1098156 | M26: =L26*K26 -> 1.5928359 | N26: =C26-M26 -> 46.357109 | O26: =C26+M26 -> 49.54278
A27: R04 | B27: =COUNT('Testes estatísticos'!C24:C43) -> 20 | C27: =AVERAGE('Testes estatísticos'!C24:C43) -> 43.814484 | D27: =MEDIAN('Testes estatísticos'!C24:C43) -> 42.806957 | E27: =_xlfn.STDEV.S('Testes estatísticos'!C24:C43) -> 1.8668581 | F27: =MIN('Testes estatísticos'!C24:C43) -> 42.650284 | G27: =MAX('Testes estatísticos'!C24:C43) -> 48.329302 | H27: =QUARTILE('Testes estatísticos'!C24:C43,1) -> 42.73558 | I27: =QUARTILE('Testes estatísticos'!C24:C43,3) -> 44.280104 | J27: =I27-H27 -> 1.544524 | K27: =E27/SQRT(B27) -> 0.41744215 | L27: =TINV(0.05,B27-1) -> 2.0930241 | M27: =L27*K27 -> 0.87371646 | N27: =C27-M27 -> 42.940767 | O27: =C27+M27 -> 44.6882
A28: R08 | B28: =COUNT('Testes estatísticos'!C44:C60) -> 17 | C28: =AVERAGE('Testes estatísticos'!C44:C60) -> 46.989981 | D28: =MEDIAN('Testes estatísticos'!C44:C60) -> 45.612313 | E28: =_xlfn.STDEV.S('Testes estatísticos'!C44:C60) -> 4.1399701 | F28: =MIN('Testes estatísticos'!C44:C60) -> 43.715068 | G28: =MAX('Testes estatísticos'!C44:C60) -> 55.879504 | H28: =QUARTILE('Testes estatísticos'!C44:C60,1) -> 43.975354 | I28: =QUARTILE('Testes estatísticos'!C44:C60,3) -> 48.53652 | J28: =I28-H28 -> 4.561166 | K28: =E28/SQRT(B28) -> 1.0040902 | L28: =TINV(0.05,B28-1) -> 2.1199053 | M28: =L28*K28 -> 2.1285762 | N28: =C28-M28 -> 44.861405 | O28: =C28+M28 -> 49.118558
A29: R10 | B29: =COUNT('Testes estatísticos'!C61:C75) -> 15 | C29: =AVERAGE('Testes estatísticos'!C61:C75) -> 49.261627 | D29: =MEDIAN('Testes estatísticos'!C61:C75) -> 48.941153 | E29: =_xlfn.STDEV.S('Testes estatísticos'!C61:C75) -> 3.1783693 | F29: =MIN('Testes estatísticos'!C61:C75) -> 43.675383 | G29: =MAX('Testes estatísticos'!C61:C75) -> 53.955051 | H29: =QUARTILE('Testes estatísticos'!C61:C75,1) -> 47.486624 | I29: =QUARTILE('Testes estatísticos'!C61:C75,3) -> 51.864558 | J29: =I29-H29 -> 4.377934 | K29: =E29/SQRT(B29) -> 0.82065143 | L29: =TINV(0.05,B29-1) -> 2.1447867 | M29: =L29*K29 -> 1.7601223 | N29: =C29-M29 -> 47.501504 | O29: =C29+M29 -> 51.021749
A30: O07 | B30: =COUNT('Testes estatísticos'!C76:C95) -> 20 | C30: =AVERAGE('Testes estatísticos'!C76:C95) -> 47.742953 | D30: =MEDIAN('Testes estatísticos'!C76:C95) -> 46.922506 | E30: =_xlfn.STDEV.S('Testes estatísticos'!C76:C95) -> 2.9635511 | F30: =MIN('Testes estatísticos'!C76:C95) -> 45.363616 | G30: =MAX('Testes estatísticos'!C76:C95) -> 55.880272 | H30: =QUARTILE('Testes estatísticos'!C76:C95,1) -> 45.967743 | I30: =QUARTILE('Testes estatísticos'!C76:C95,3) -> 47.735731 | J30: =I30-H30 -> 1.7679873 | K30: =E30/SQRT(B30) -> 0.66267016 | L30: =TINV(0.05,B30-1) -> 2.0930241 | M30: =L30*K30 -> 1.3869846 | N30: =C30-M30 -> 46.355968 | O30: =C30+M30 -> 49.129937
A31: O03 | B31: =COUNT('Testes estatísticos'!C96:C110) -> 15 | C31: =AVERAGE('Testes estatísticos'!C96:C110) -> 47.479288 | D31: =MEDIAN('Testes estatísticos'!C96:C110) -> 47.074399 | E31: =_xlfn.STDEV.S('Testes estatísticos'!C96:C110) -> 1.1440191 | F31: =MIN('Testes estatísticos'!C96:C110) -> 46.964322 | G31: =MAX('Testes estatísticos'!C96:C110) -> 51.5289 | H31: =QUARTILE('Testes estatísticos'!C96:C110,1) -> 47.011245 | I31: =QUARTILE('Testes estatísticos'!C96:C110,3) -> 47.450646 | J31: =I31-H31 -> 0.439401 | K31: =E31/SQRT(B31) -> 0.29538447 | L31: =TINV(0.05,B31-1) -> 2.1447867 | M31: =L31*K31 -> 0.63353668 | N31: =C31-M31 -> 46.845751 | O31: =C31+M31 -> 48.112824
A32: O13 | B32: =COUNT('Testes estatísticos'!C111:C126) -> 16 | C32: =AVERAGE('Testes estatísticos'!C111:C126) -> 46.578391 | D32: =MEDIAN('Testes estatísticos'!C111:C126) -> 45.036305 | E32: =_xlfn.STDEV.S('Testes estatísticos'!C111:C126) -> 3.3892838 | F32: =MIN('Testes estatísticos'!C111:C126) -> 44.921168 | G32: =MAX('Testes estatísticos'!C111:C126) -> 56.05236 | H32: =QUARTILE('Testes estatísticos'!C111:C126,1) -> 45.001781 | I32: =QUARTILE('Testes estatísticos'!C111:C126,3) -> 45.250195 | J32: =I32-H32 -> 0.248414 | K32: =E32/SQRT(B32) -> 0.84732096 | L32: =TINV(0.05,B32-1) -> 2.1314495 | M32: =L32*K32 -> 1.8060219 | N32: =C32-M32 -> 44.772369 | O32: =C32+M32 -> 48.384413
A33: O17 | B33: =COUNT('Testes estatísticos'!C127:C143) -> 17 | C33: =AVERAGE('Testes estatísticos'!C127:C143) -> 46.944427 | D33: =MEDIAN('Testes estatísticos'!C127:C143) -> 46.732589 | E33: =_xlfn.STDEV.S('Testes estatísticos'!C127:C143) -> 2.6172792 | F33: =MIN('Testes estatísticos'!C127:C143) -> 45.050001 | G33: =MAX('Testes estatísticos'!C127:C143) -> 55.756136 | H33: =QUARTILE('Testes estatísticos'!C127:C143,1) -> 45.117579 | I33: =QUARTILE('Testes estatísticos'!C127:C143,3) -> 47.535028 | J33: =I33-H33 -> 2.417449 | K33: =E33/SQRT(B33) -> 0.63478345 | L33: =TINV(0.05,B33-1) -> 2.1199053 | M33: =L33*K33 -> 1.3456808 | N33: =C33-M33 -> 45.598746 | O33: =C33+M33 -> 48.290108
A36: 4. DIFERENÇA EMPARELHADA POR CENÁRIO (respostas − temporal)
A37: Condição | B37: n | C37: Média | D37: Mediana | E37: Desvio-padrão | F37: Mínimo | G37: Máximo | H37: Q1 | I37: Q3 | J37: IQR | K37: Erro-padrão | L37: t crítico | M37: Margem de erro | N37: IC 95 % inferior | O37: IC 95 % superior
A38: R01 | B38: =COUNT('Testes estatísticos'!D6:D23) -> 18 | C38: =AVERAGE('Testes estatísticos'!D6:D23) -> -2.3188899 | D38: =MEDIAN('Testes estatísticos'!D6:D23) -> -1.5550705 | E38: =_xlfn.STDEV.S('Testes estatísticos'!D6:D23) -> 4.6598987 | F38: =MIN('Testes estatísticos'!D6:D23) -> -11.033655 | G38: =MAX('Testes estatísticos'!D6:D23) -> 4.713088 | H38: =QUARTILE('Testes estatísticos'!D6:D23,1) -> -6.0675905 | I38: =QUARTILE('Testes estatísticos'!D6:D23,3) -> 0.556265 | J38: =I38-H38 -> 6.6238555 | K38: =E38/SQRT(B38) -> 1.0983487 | L38: =TINV(0.05,B38-1) -> 2.1098156 | M38: =L38*K38 -> 2.3173131 | N38: =C38-M38 -> -4.6362031 | O38: =C38+M38 -> -0.0015768331
A39: R04 | B39: =COUNT('Testes estatísticos'!D24:D43) -> 20 | C39: =AVERAGE('Testes estatísticos'!D24:D43) -> -2.4586501 | D39: =MEDIAN('Testes estatísticos'!D24:D43) -> -2.2718505 | E39: =_xlfn.STDEV.S('Testes estatísticos'!D24:D43) -> 2.3336163 | F39: =MIN('Testes estatísticos'!D24:D43) -> -7.353048 | G39: =MAX('Testes estatísticos'!D24:D43) -> 3.372644 | H39: =QUARTILE('Testes estatísticos'!D24:D43,1) -> -3.6537927 | I39: =QUARTILE('Testes estatísticos'!D24:D43,3) -> -2.1092305 | J39: =I39-H39 -> 1.5445623 | K39: =E39/SQRT(B39) -> 0.52181246 | L39: =TINV(0.05,B39-1) -> 2.0930241 | M39: =L39*K39 -> 1.092166 | N39: =C39-M39 -> -3.5508161 | O39: =C39+M39 -> -1.366484
A40: R08 | B40: =COUNT('Testes estatísticos'!D44:D60) -> 17 | C40: =AVERAGE('Testes estatísticos'!D44:D60) -> -1.1344082 | D40: =MEDIAN('Testes estatísticos'!D44:D60) -> -1.25499 | E40: =_xlfn.STDEV.S('Testes estatísticos'!D44:D60) -> 3.3694982 | F40: =MIN('Testes estatísticos'!D44:D60) -> -6.721471 | G40: =MAX('Testes estatísticos'!D44:D60) -> 4.758812 | H40: =QUARTILE('Testes estatísticos'!D44:D60,1) -> -2.933606 | I40: =QUARTILE('Testes estatísticos'!D44:D60,3) -> 0.406755 | J40: =I40-H40 -> 3.340361 | K40: =E40/SQRT(B40) -> 0.81722334 | L40: =TINV(0.05,B40-1) -> 2.1199053 | M40: =L40*K40 -> 1.7324361 | N40: =C40-M40 -> -2.8668443 | O40: =C40+M40 -> 0.59802791
A41: R10 | B41: =COUNT('Testes estatísticos'!D61:D75) -> 15 | C41: =AVERAGE('Testes estatísticos'!D61:D75) -> -1.3587094 | D41: =MEDIAN('Testes estatísticos'!D61:D75) -> -0.501125 | E41: =_xlfn.STDEV.S('Testes estatísticos'!D61:D75) -> 3.9345248 | F41: =MIN('Testes estatísticos'!D61:D75) -> -8.45694 | G41: =MAX('Testes estatísticos'!D61:D75) -> 3.501079 | H41: =QUARTILE('Testes estatísticos'!D61:D75,1) -> -4.031148 | I41: =QUARTILE('Testes estatísticos'!D61:D75,3) -> 1.3416125 | J41: =I41-H41 -> 5.3727605 | K41: =E41/SQRT(B41) -> 1.0158899 | L41: =TINV(0.05,B41-1) -> 2.1447867 | M41: =L41*K41 -> 2.1788672 | N41: =C41-M41 -> -3.5375766 | O41: =C41+M41 -> 0.82015779
A42: O07 | B42: =COUNT('Testes estatísticos'!D76:D95) -> 20 | C42: =AVERAGE('Testes estatísticos'!D76:D95) -> -3.1460188 | D42: =MEDIAN('Testes estatísticos'!D76:D95) -> -3.4062355 | E42: =_xlfn.STDEV.S('Testes estatísticos'!D76:D95) -> 3.2701672 | F42: =MIN('Testes estatísticos'!D76:D95) -> -8.406321 | G42: =MAX('Testes estatísticos'!D76:D95) -> 4.64088 | H42: =QUARTILE('Testes estatísticos'!D76:D95,1) -> -5.6336125 | I42: =QUARTILE('Testes estatísticos'!D76:D95,3) -> -2.4464348 | J42: =I42-H42 -> 3.1871777 | K42: =E42/SQRT(B42) -> 0.73123162 | L42: =TINV(0.05,B42-1) -> 2.0930241 | M42: =L42*K42 -> 1.5304854 | N42: =C42-M42 -> -4.6765041 | O42: =C42+M42 -> -1.6155334
A43: O03 | B43: =COUNT('Testes estatísticos'!D96:D110) -> 15 | C43: =AVERAGE('Testes estatísticos'!D96:D110) -> -3.5383717 | D43: =MEDIAN('Testes estatísticos'!D96:D110) -> -3.800793 | E43: =_xlfn.STDEV.S('Testes estatísticos'!D96:D110) -> 1.0464297 | F43: =MIN('Testes estatísticos'!D96:D110) -> -4.431786 | G43: =MAX('Testes estatísticos'!D96:D110) -> -0.06947 | H43: =QUARTILE('Testes estatísticos'!D96:D110,1) -> -4.0521315 | I43: =QUARTILE('Testes estatísticos'!D96:D110,3) -> -3.328128 | J43: =I43-H43 -> 0.7240035 | K43: =E43/SQRT(B43) -> 0.27018698 | L43: =TINV(0.05,B43-1) -> 2.1447867 | M43: =L43*K43 -> 0.57949343 | N43: =C43-M43 -> -4.1178652 | O43: =C43+M43 -> -2.9588783
A44: O13 | B44: =COUNT('Testes estatísticos'!D111:D126) -> 16 | C44: =AVERAGE('Testes estatísticos'!D111:D126) -> -1.2853644 | D44: =MEDIAN('Testes estatísticos'!D111:D126) -> -2.058848 | E44: =_xlfn.STDEV.S('Testes estatísticos'!D111:D126) -> 4.624311 | F44: =MIN('Testes estatísticos'!D111:D126) -> -13.340673 | G44: =MAX('Testes estatísticos'!D111:D126) -> 8.877868 | H44: =QUARTILE('Testes estatísticos'!D111:D126,1) -> -2.1900965 | I44: =QUARTILE('Testes estatísticos'!D111:D126,3) -> -1.859223 | J44: =I44-H44 -> 0.3308735 | K44: =E44/SQRT(B44) -> 1.1560778 | L44: =TINV(0.05,B44-1) -> 2.1314495 | M44: =L44*K44 -> 2.4641214 | N44: =C44-M44 -> -3.7494858 | O44: =C44+M44 -> 1.178757
A45: O17 | B45: =COUNT('Testes estatísticos'!D127:D143) -> 17 | C45: =AVERAGE('Testes estatísticos'!D127:D143) -> -3.7137989 | D45: =MEDIAN('Testes estatísticos'!D127:D143) -> -3.774814 | E45: =_xlfn.STDEV.S('Testes estatísticos'!D127:D143) -> 4.9869051 | F45: =MIN('Testes estatísticos'!D127:D143) -> -15.416956 | G45: =MAX('Testes estatísticos'!D127:D143) -> 8.507066 | H45: =QUARTILE('Testes estatísticos'!D127:D143,1) -> -6.691143 | I45: =QUARTILE('Testes estatísticos'!D127:D143,3) -> -1.284477 | J45: =I45-H45 -> 5.406666 | K45: =E45/SQRT(B45) -> 1.2095021 | L45: =TINV(0.05,B45-1) -> 2.1199053 | M45: =L45*K45 -> 2.56403 | N45: =C45-M45 -> -6.2778289 | O45: =C45+M45 -> -1.1497689
A47: Um IC 95 % que atravessa o zero significa que, nesse cenário, a diferença observada é compatível com a ausência de efeito. É o que sucede nos cenários em que o teste de Wilcoxon por cenário também não é significativo.
A49: 5. OUTRAS GRANDEZAS COM IC 95 % (Secções 5.5 e 5.6)
...

Sheet Testes emparelhados
A1: TESTES EMPARELHADOS — FRIEDMAN, WILCOXON COM HOLM, Q DE COCHRAN E McNEMAR
A2: O desenho é emparelhado: cada movimento foi executado pelos três planeadores e cada ciclo pelas duas arquiteturas. Os testes para grupos independentes não são aplicáveis. Tudo o que está abaixo é fórmula.
A4: CAMPANHA 1 — ciclo completo, sem obstáculos
A5: Blocos totais: 50. Blocos completos (concluídos pelos três planeadores): 49. As métricas contínuas usam os blocos completos; a taxa de sucesso usa todos.
A7: Bloco | B7: RRTConnect — Tempo total (s) | C7: RRTstar — Tempo total (s) | D7: PRMstar — Tempo total (s) | E7: posto RRTConnect | F7: posto RRTstar | G7: posto PRMstar | H7: RRTConnect — Comprimento (m) | I7: RRTstar — Comprimento (m) | J7: PRMstar — Comprimento (m) | K7: posto RRTConnect | L7: posto RRTstar | M7: posto PRMstar | N7: RRTConnect — Tempo de planeamento (s) | O7: RRTstar — Tempo de planeamento (s) | P7: PRMstar — Tempo de planeamento (s) | Q7: posto RRTConnect | R7: posto RRTstar | S7: posto PRMstar
A8: (1, 1) | B8: 44.045 | C8: 43.239 | D8: 39.8734 | E8: =RANK(B8,$B8:$D8,1) -> 3 | F8: =RANK(C8,$B8:$D8,1) -> 2 | G8: =RANK(D8,$B8:$D8,1) -> 1 | H8: 3.7939 | I8: 3.8195 | J8: 3.5204 | K8: =RANK(H8,$H8:$J8,1) -> 2 | L8: =RANK(I8,$H8:$J8,1) -> 3 | M8: =RANK(J8,$H8:$J8,1) -> 1 | N8: 3.251 | O8: 3.217 | P8: 4.0674 | Q8: =RANK(N8,$N8:$P8,1) -> 2 | R8: =RANK(O8,$N8:$P8,1) -> 1 | S8: =RANK(P8,$N8:$P8,1) -> 3
A9: (1, 10) | B9: 36.202 | C9: 40.206 | D9: 31.156 | E9: =RANK(B9,$B9:$D9,1) -> 2 | F9: =RANK(C9,$B9:$D9,1) -> 3 | G9: =RANK(D9,$B9:$D9,1) -> 1 | H9: 3.8107 | I9: 4.0243 | J9: 4.3946 | K9: =RANK(H9,$H9:$J9,1) -> 1 | L9: =RANK(I9,$H9:$J9,1) -> 2 | M9: =RANK(J9,$H9:$J9,1) -> 3 | N9: 3.651 | O9: 3.465 | P9: 4.142 | Q9: =RANK(N9,$N9:$P9,1) -> 2 | R9: =RANK(O9,$N9:$P9,1) -> 1 | S9: =RANK(P9,$N9:$P9,1) -> 3
A10: (1, 2) | B10: 40.629 | C10: 42.28 | D10: 43.539 | E10: =RANK(B10,$B10:$D10,1) -> 1 | F10: =RANK(C10,$B10:$D10,1) -> 2 | G10: =RANK(D10,$B10:$D10,1) -> 3 | H10: 3.8026 | I10: 3.6699 | J10: 4.4645 | K10: =RANK(H10,$H10:$J10,1) -> 2 | L10: =RANK(I10,$H10:$J10,1) -> 1 | M10: =RANK(J10,$H10:$J10,1) -> 3 | N10: 3.111 | O10: 3.422 | P10: 3.401 | Q10: =RANK(N10,$N10:$P10,1) -> 1 | R10: =RANK(O10,$N10:$P10,1) -> 3 | S10: =RANK(P10,$N10:$P10,1) -> 2
A11: (1, 3) | B11: 46.782 | C11: 42.844 | D11: 44.841 | E11: =RANK(B11,$B11:$D11,1) -> 3 | F11: =RANK(C11,$B11:$D11,1) -> 1 | G11: =RANK(D11,$B11:$D11,1) -> 2 | H11: 3.8583 | I11: 3.8889 | J11: 4.2954 | K11: =RANK(H11,$H11:$J11,1) -> 1 | L11: =RANK(I11,$H11:$J11,1) -> 2 | M11: =RANK(J11,$H11:$J11,1) -> 3 | N11: 3.307 | O11: 3.267 | P11: 3.311 | Q11: =RANK(N11,$N11:$P11,1) -> 2 | R11: =RANK(O11,$N11:$P11,1) -> 1 | S11: =RANK(P11,$N11:$P11,1) -> 3
A12: (1, 4) | B12: 43.931 | C12: 39.998 | D12: 41.488 | E12: =RANK(B12,$B12:$D12,1) -> 3 | F12: =RANK(C12,$B12:$D12,1) -> 1 | G12: =RANK(D12,$B12:$D12,1) -> 2 | H12: 3.4863 | I12: 3.5102 | J12: 4.2357 | K12: =RANK(H12,$H12:$J12,1) -> 1 | L12: =RANK(I12,$H12:$J12,1) -> 2 | M12: =RANK(J12,$H12:$J12,1) -> 3 | N12: 3.413 | O12: 3.406 | P12: 4.127 | Q12: =RANK(N12,$N12:$P12,1) -> 2 | R12: =RANK(O12,$N12:$P12,1) -> 1 | S12: =RANK(P12,$N12:$P12,1) -> 3
A13: (1, 5) | B13: 36.719 | C13: 40.081 | D13: 41.834 | E13: =RANK(B13,$B13:$D13,1) -> 1 | F13: =RANK(C13,$B13:$D13,1) -> 2 | G13: =RANK(D13,$B13:$D13,1) -> 3 | H13: 3.5892 | I13: 3.7815 | J13: 4.4431 | K13: =RANK(H13,$H13:$J13,1) -> 1 | L13: =RANK(I13,$H13:$J13,1) -> 2 | M13: =RANK(J13,$H13:$J13,1) -> 3 | N13: 3.419 | O13: 3.191 | P13: 3.491 | Q13: =RANK(N13,$N13:$P13,1) -> 2 | R13: =RANK(O13,$N13:$P13,1) -> 1 | S13: =RANK(P13,$N13:$P13,1) -> 3
A14: (1, 6) | B14: 38.907 | C14: 41.282 | D14: 37.243 | E14: =RANK(B14,$B14:$D14,1) -> 2 | F14: =RANK(C14,$B14:$D14,1) -> 3 | G14: =RANK(D14,$B14:$D14,1) -> 1 | H14: 3.7914 | I14: 3.8618 | J14: 4.2726 | K14: =RANK(H14,$H14:$J14,1) -> 1 | L14: =RANK(I14,$H14:$J14,1) -> 2 | M14: =RANK(J14,$H14:$J14,1) -> 3 | N14: 3.257 | O14: 4.064 | P14: 3.268 | Q14: =RANK(N14,$N14:$P14,1) -> 1 | R14: =RANK(O14,$N14:$P14,1) -> 3 | S14: =RANK(P14,$N14:$P14,1) -> 2
A15: (1, 7) | B15: 38.448 | C15: 41.08 | D15: 41.066 | E15: =RANK(B15,$B15:$D15,1) -> 1 | F15: =RANK(C15,$B15:$D15,1) -> 3 | G15: =RANK(D15,$B15:$D15,1) -> 2 | H15: 3.4825 | I15: 3.9155 | J15: 4.4906 | K15: =RANK(H15,$H15:$J15,1) -> 1 | L15: =RANK(I15,$H15:$J15,1) -> 2 | M15: =RANK(J15,$H15:$J15,1) -> 3 | N15: 4.086 | O15: 3.39 | P15: 4.088 | Q15: =RANK(N15,$N15:$P15,1) -> 2 | R15: =RANK(O15,$N15:$P15,1) -> 1 | S15: =RANK(P15,$N15:$P15,1) -> 3
A16: (1, 8) | B16: 41.685 | C16: 41.458 | D16: 42.498 | E16: =RANK(B16,$B16:$D16,1) -> 2 | F16: =RANK(C16,$B16:$D16,1) -> 1 | G16: =RANK(D16,$B16:$D16,1) -> 3 | H16: 3.809 | I16: 4.0122 | J16: 4.3687 | K16: =RANK(H16,$H16:$J16,1) -> 1 | L16: =RANK(I16,$H16:$J16,1) -> 2 | M16: =RANK(J16,$H16:$J16,1) -> 3 | N16: 6.274 | O16: 3.339 | P16: 3.351 | Q16: =RANK(N16,$N16:$P16,1) -> 3 | R16: =RANK(O16,$N16:$P16,1) -> 1 | S16: =RANK(P16,$N16:$P16,1) -> 2
A17: (1, 9) | B17: 35.5391 | C17: 42.701 | D17: 50.736 | E17: =RANK(B17,$B17:$D17,1) -> 1 | F17: =RANK(C17,$B17:$D17,1) -> 2 | G17: =RANK(D17,$B17:$D17,1) -> 3 | H17: 3.7821 | I17: 4.2073 | J17: 4.5032 | K17: =RANK(H17,$H17:$J17,1) -> 1 | L17: =RANK(I17,$H17:$J17,1) -> 2 | M17: =RANK(J17,$H17:$J17,1) -> 3 | N17: 3.609 | O17: 4.049 | P17: 4.04 | Q17: =RANK(N17,$N17:$P17,1) -> 1 | R17: =RANK(O17,$N17:$P17,1) -> 3 | S17: =RANK(P17,$N17:$P17,1) -> 2
A18: (2, 1) | B18: 31.708 | C18: 35.934 | D18: 33.033 | E18: =RANK(B18,$B18:$D18,1) -> 1 | F18: =RANK(C18,$B18:$D18,1) -> 3 | G18: =RANK(D18,$B18:$D18,1) -> 2 | H18: 3.502 | I18: 7.0657 | J18: 3.5837 | K18: =RANK(H18,$H18:$J18,1) -> 1 | L18: =RANK(I18,$H18:$J18,1) -> 3 | M18: =RANK(J18,$H18:$J18,1) -> 2 | N18: 4.422 | O18: 4.461 | P18: 3.926 | Q18: =RANK(N18,$N18:$P18,1) -> 2 | R18: =RANK(O18,$N18:$P18,1) -> 3 | S18: =RANK(P18,$N18:$P18,1) -> 1
A19: (2, 2) | B19: 30.063 | C19: 28.3075 | D19: 30.743 | E19: =RANK(B19,$B19:$D19,1) -> 2 | F19: =RANK(C19,$B19:$D19,1) -> 1 | G19: =RANK(D19,$B19:$D19,1) -> 3 | H19: 3.3711 | I19: 3.1452 | J19: 3.3897 | K19: =RANK(H19,$H19:$J19,1) -> 2 | L19: =RANK(I19,$H19:$J19,1) -> 1 | M19: =RANK(J19,$H19:$J19,1) -> 3 | N19: 3.955 | O19: 3.5421 | P19: 4.366 | Q19: =RANK(N19,$N19:$P19,1) -> 2 | R19: =RANK(O19,$N19:$P19,1) -> 1 | S19: =RANK(P19,$N19:$P19,1) -> 3
... A56: (5, 9) | B56: 31.234 | C56: 37.701 | D56: 31.889 | E56: =RANK(B56,$B56:$D56,1) -> 1 | F56: =RANK(C56,$B56:$D56,1) -> 3 | G56: =RANK(D56,$B56:$D56,1) -> 2 | H56: 4.593 | I56: 4.2073 | J56: 4.7817 | K56: =RANK(H56,$H56:$J56,1) -> 2 | L56: =RANK(I56,$H56:$J56,1) -> 1 | M56: =RANK(J56,$H56:$J56,1) -> 3 | N56: 3.656 | O56: 4.049 | P56: 3.746 | Q56: =RANK(N56,$N56:$P56,1) -> 1 | R56: =RANK(O56,$N56:$P56,1) -> 3 | S56: =RANK(P56,$N56:$P56,1) -> 2
A58: Métrica | B58: n blocos | C58: ΣR RRTConnect | D58: ΣR RRTstar | E58: ΣR PRMstar | F58: χ² de Friedman | G58: gl | H58: p
A59: Tempo total (s) | B59: 49 | C59: =SUM(E8:E56) -> 80 | D59: =SUM(F8:F56) -> 109 | E59: =SUM(G8:G56) -> 105 | F59: =12/(49*3*4)*(C59^2+D59^2+E59^2)-3*49*4 -> 10.081633 | G59: 2 | H59: =CHIDIST(F59,G59) -> 0.0064684658
A60: Comprimento (m) | B60: 49 | C60: =SUM(K8:K56) -> 66 | D60: =SUM(L8:L56) -> 105 | E60: =SUM(M8:M56) -> 123 | F60: =12/(49*3*4)*(C60^2+D60^2+E60^2)-3*49*4 -> 34.653061 | G60: 2 | H60: =CHIDIST(F60,G60) -> 2.9866434e-08
A61: Tempo de planeamento (s) | B61: 49 | C61: =SUM(Q8:Q56) -> 102 | D61: =SUM(R8:R56) -> 79 | E61: =SUM(S8:S56) -> 113 | F61: =12/(49*3*4)*(C61^2+D61^2+E61^2)-3*49*4 -> 12.285714 | G61: 2 | H61: =CHIDIST(F61,G61) -> 0.0021487755
A63: Taxa de sucesso | B63: Sucessos RRTConnect | C63: Sucessos RRTstar | D63: Sucessos PRMstar | E63: Blocos | F63: Q de Cochran | G63: gl | H63: p
A64: Blocos concluídos | B64: 49 | C64: 50 | D64: 50 | E64: 50 | F64: =2*(3*(B64^2+C64^2+D64^2)-149^2)/(3*149-445) -> 2 | G64: 2 | H64: =CHIDIST(F64,G64) -> 0.36787944
A67: CAMPANHA 2 — movimento isolado, com obstáculos
A68: Blocos totais: 85. Blocos completos (concluídos pelos três planeadores): 78. As métricas contínuas usam os blocos completos; a taxa de sucesso usa todos.
A70: Bloco | B70: RRTConnect — Tempo total (s) | C70: RRTstar — Tempo total (s) | D70: PRMstar — Tempo total (s) | E70: posto RRTConnect | F70: posto RRTstar | G70: posto PRMstar | H70: RRTConnect — Comprimento (m) | I70: RRTstar — Comprimento (m) | J70: PRMstar — Comprimento (m) | K70: posto RRTConnect | L70: posto RRTstar | M70: posto PRMstar | N70: RRTConnect — Tempo de planeamento (s) | O70: RRTstar — Tempo de planeamento (s) | P70: PRMstar — Tempo de planeamento (s) | Q70: posto RRTConnect | R70: posto RRTstar | S70: posto PRMstar
A71: ('O03_1', 1) | B71: 4.611154 | C71: 3.779868 | D71: 3.81281 | E71: =RANK(B71,$B71:$D71,1) -> 3 | F71: =RANK(C71,$B71:$D71,1) -> 1 | G71: =RANK(D71,$B71:$D71,1) -> 2 | H71: 2.831715 | I71: 2.255318 | J71: 2.255818 | K71: =RANK(H71,$H71:$J71,1) -> 3 | L71: =RANK(I71,$H71:$J71,1) -> 1 | M71: =RANK(J71,$H71:$J71,1) -> 2 | N71: 0.11664 | O71: 0.093886 | P71: 0.074256 | Q71: =RANK(N71,$N71:$P71,1) -> 3 | R71: =RANK(O71,$N71:$P71,1) -> 2 | S71: =RANK(P71,$N71:$P71,1) -> 1
A72: ('O03_1', 2) | B72: 3.822604 | C72: 3.787466 | D72: 3.830618 | E72: =RANK(B72,$B72:$D72,1) -> 2 | F72: =RANK(C72,$B72:$D72,1) -> 1 | G72: =RANK(D72,$B72:$D72,1) -> 3 | H72: 2.25386 | I72: 2.254267 | J72: 2.253931 | K72: =RANK(H72,$H72:$J72,1) -> 1 | L72: =RANK(I72,$H72:$J72,1) -> 3 | M72: =RANK(J72,$H72:$J72,1) -> 2 | N72: 0.082687 | O72: 0.08838 | P72: 0.083433 | Q72: =RANK(N72,$N72:$P72,1) -> 1 | R72: =RANK(O72,$N72:$P72,1) -> 3 | S72: =RANK(P72,$N72:$P72,1) -> 2
A73: ('O03_1', 3) | B73: 3.83817 | C73: 3.834708 | D73: 3.86916 | E73: =RANK(B73,$B73:$D73,1) -> 2 | F73: =RANK(C73,$B73:$D73,1) -> 1 | G73: =RANK(D73,$B73:$D73,1) -> 3 | H73: 2.255704 | I73: 2.254643 | J73: 2.375162 | K73: =RANK(H73,$H73:$J73,1) -> 2 | L73: =RANK(I73,$H73:$J73,1) -> 1 | M73: =RANK(J73,$H73:$J73,1) -> 3 | N73: 0.090152 | O73: 0.092525 | P73: 0.122015 | Q73: =RANK(N73,$N73:$P73,1) -> 1 | R73: =RANK(O73,$N73:$P73,1) -> 2 | S73: =RANK(P73,$N73:$P73,1) -> 3
A74: ('O03_1', 4) | B74: 4.571304 | C74: 3.814986 | D74: 3.830618 | E74: =RANK(B74,$B74:$D74,1) -> 3 | F74: =RANK(C74,$B74:$D74,1) -> 1 | G74: =RANK(D74,$B74:$D74,1) -> 2 | H74: 2.831955 | I74: 2.253944 | J74: 2.253931 | K74: =RANK(H74,$H74:$J74,1) -> 3 | L74: =RANK(I74,$H74:$J74,1) -> 2 | M74: =RANK(J74,$H74:$J74,1) -> 1 | N74: 0.085305 | O74: 0.068699 | P74: 0.083433 | Q74: =RANK(N74,$N74:$P74,1) -> 3 | R74: =RANK(O74,$N74:$P74,1) -> 1 | S74: =RANK(P74,$N74:$P74,1) -> 2
A75: ('O03_1', 5) | B75: 4.326673 | C75: 3.778892 | D75: 3.81281 | E75: =RANK(B75,$B75:$D75,1) -> 3 | F75: =RANK(C75,$B75:$D75,1) -> 1 | G75: =RANK(D75,$B75:$D75,1) -> 2 | H75: 2.460937 | I75: 2.254707 | J75: 2.255818 | K75: =RANK(H75,$H75:$J75,1) -> 3 | L75: =RANK(I75,$H75:$J75,1) -> 1 | M75: =RANK(J75,$H75:$J75,1) -> 2 | N75: 0.089686 | O75: 0.08246 | P75: 0.074256 | Q75: =RANK(N75,$N75:$P75,1) -> 3 | R75: =RANK(O75,$N75:$P75,1) -> 2 | S75: =RANK(P75,$N75:$P75,1) -> 1
A76: ('O03_2', 1) | B76: 5.416736 | C76: 3.548406 | D76: 3.515584 | E76: =RANK(B76,$B76:$D76,1) -> 3 | F76: =RANK(C76,$B76:$D76,1) -> 2 | G76: =RANK(D76,$B76:$D76,1) -> 1 | H76: 4.304988 | I76: 1.41831 | J76: 1.417461 | K76: =RANK(H76,$H76:$J76,1) -> 3 | L76: =RANK(I76,$H76:$J76,1) -> 2 | M76: =RANK(J76,$H76:$J76,1) -> 1 | N76: 0.123007 | O76: 0.10512 | P76: 0.068455 | Q76: =RANK(N76,$N76:$P76,1) -> 3 | R76: =RANK(O76,$N76:$P76,1) -> 2 | S76: =RANK(P76,$N76:$P76,1) -> 1
A77: ('O03_2', 2) | B77: 3.527538 | C77: 3.558404 | D77: 3.533697 | E77: =RANK(B77,$B77:$D77,1) -> 1 | F77: =RANK(C77,$B77:$D77,1) -> 3 | G77: =RANK(D77,$B77:$D77,1) -> 2 | H77: 1.413859 | I77: 1.414253 | J77: 1.418623 | K77: =RANK(H77,$H77:$J77,1) -> 1 | L77: =RANK(I77,$H77:$J77,1) -> 2 | M77: =RANK(J77,$H77:$J77,1) -> 3 | N77: 0.077683 | O77: 0.106917 | P77: 0.078604 | Q77: =RANK(N77,$N77:$P77,1) -> 1 | R77: =RANK(O77,$N77:$P77,1) -> 3 | S77: =RANK(P77,$N77:$P77,1) -> 2
A78: ('O03_2', 4) | B78: 4.951307 | C78: 3.475664 | D78: 3.533697 | E78: =RANK(B78,$B78:$D78,1) -> 3 | F78: =RANK(C78,$B78:$D78,1) -> 1 | G78: =RANK(D78,$B78:$D78,1) -> 2 | H78: 3.471767 | I78: 1.414523 | J78: 1.418623 | K78: =RANK(H78,$H78:$J78,1) -> 3 | L78: =RANK(I78,$H78:$J78,1) -> 1 | M78: =RANK(J78,$H78:$J78,1) -> 2 | N78: 0.10453 | O78: 0.074032 | P78: 0.078604 | Q78: =RANK(N78,$N78:$P78,1) -> 3 | R78: =RANK(O78,$N78:$P78,1) -> 1 | S78: =RANK(P78,$N78:$P78,1) -> 2
A79: ('O03_2', 5) | B79: 3.583387 | C79: 3.546077 | D79: 3.86916 | E79: =RANK(B79,$B79:$D79,1) -> 2 | F79: =RANK(C79,$B79:$D79,1) -> 1 | G79: =RANK(D79,$B79:$D79,1) -> 3 | H79: 1.215574 | I79: 1.420021 | J79: 2.375162 | K79: =RANK(H79,$H79:$J79,1) -> 1 | L79: =RANK(I79,$H79:$J79,1) -> 2 | M79: =RANK(J79,$H79:$J79,1) -> 3 | N79: 0.075212 | O79: 0.087819 | P79: 0.122015 | Q79: =RANK(N79,$N79:$P79,1) -> 1 | R79: =RANK(O79,$N79:$P79,1) -> 2 | S79: =RANK(P79,$N79:$P79,1) -> 3
A80: ('O07_1', 1) | B80: 4.550112 | C80: 3.816007 | D80: 8.437969 | E80: =RANK(B80,$B80:$D80,1) -> 2 | F80: =RANK(C80,$B80:$D80,1) -> 1 | G80: =RANK(D80,$B80:$D80,1) -> 3 | H80: 3.661822 | I80: 2.376257 | J80: 4.425095 | K80: =RANK(H80,$H80:$J80,1) -> 2 | L80: =RANK(I80,$H80:$J80,1) -> 1 | M80: =RANK(J80,$H80:$J80,1) -> 3 | N80: 0.108201 | O80: 0.086584 | P80: 0.190614 | Q80: =RANK(N80,$N80:$P80,1) -> 2 | R80: =RANK(O80,$N80:$P80,1) -> 1 | S80: =RANK(P80,$N80:$P80,1) -> 3
A81: ('O07_1', 2) | B81: 7.039058 | C81: 4.530242 | D81: 4.528642 | E81: =RANK(B81,$B81:$D81,1) -> 3 | F81: =RANK(C81,$B81:$D81,1) -> 2 | G81: =RANK(D81,$B81:$D81,1) -> 1 | H81: 2.498504 | I81: 3.031576 | J81: 3.653151 | K81: =RANK(H81,$H81:$J81,1) -> 1 | L81: =RANK(I81,$H81:$J81,1) -> 2 | M81: =RANK(J81,$H81:$J81,1) -> 3 | N81: 0.187847 | O81: 0.105006 | P81: 0.085344 | Q81: =RANK(N81,$N81:$P81,1) -> 3 | R81: =RANK(O81,$N81:$P81,1) -> 2 | S81: =RANK(P81,$N81:$P81,1) -> 1
A82: ('O07_1', 3) | B82: 3.779637 | C82: 4.557892 | D82: 4.587465 | E82: =RANK(B82,$B82:$D82,1) -> 1 | F82: =RANK(C82,$B82:$D82,1) -> 2 | G82: =RANK(D82,$B82:$D82,1) -> 3 | H82: 2.377428 | I82: 3.241821 | J82: 3.916854 | K82: =RANK(H82,$H82:$J82,1) -> 1 | L82: =RANK(I82,$H82:$J82,1) -> 2 | M82: =RANK(J82,$H82:$J82,1) -> 3 | N82: 0.083336 | O82: 0.108406 | P82: 0.083906 | Q82: =RANK(N82,$N82:$P82,1) -> 1 | R82: =RANK(O82,$N82:$P82,1) -> 3 | S82: =RANK(P82,$N82:$P82,1) -> 2
... A148: ('O22_2', 5) | B148: 3.466704 | C148: 3.52069 | D148: 3.86916 | E148: =RANK(B148,$B148:$D148,1) -> 1 | F148: =RANK(C148,$B148:$D148,1) -> 2 | G148: =RANK(D148,$B148:$D148,1) -> 3 | H148: 1.16331 | I148: 1.417354 | J148: 1.675162 | K148: =RANK(H148,$H148:$J148,1) -> 1 | L148: =RANK(I148,$H148:$J148,1) -> 2 | M148: =RANK(J148,$H148:$J148,1) -> 3 | N148: 0.055748 | O148: 0.072486 | P148: 0.122015 | Q148: =RANK(N148,$N148:$P148,1) -> 1 | R148: =RANK(O148,$N148:$P148,1) -> 2 | S148: =RANK(P148,$N148:$P148,1) -> 3
...

Sheet Hodges-Lehmann
A1: ESTIMATIVA DE HODGES-LEHMANN E INTERVALO DE CONFIANÇA A 95 % — TUDO EM FÓRMULA
A2: A mediana e os quartis descrevem a amostra. Para a diferença emparelhada é preciso um intervalo que não pressuponha normalidade, porque o teste de Shapiro-Wilk a rejeita. O método é o de Hodges-Lehmann: calculam-se as médias de todos os pares de diferenças — as médias de Walsh —, a estimativa é a mediana desse conjunto e os limites do intervalo são a k-ésima menor e a k-ésima maior, com k dado pela distribuição de Wilcoxon. Base: os 138 pares concluídos com sucesso pelas duas estratégias.
A3: k = ARRED(n(n+1)/4 − 1,959964 × RAIZ(n(n+1)(2n+1)/24); 0) + 1. As grelhas triangulares abaixo contêm as médias de Walsh; as células vazias são texto e não entram em MED, MENOR nem MAIOR.
A5: Cenário | B5: n | C5: k | D5: Redução HL (s) | E5: IC 95 % inferior | F5: IC 95 % superior | G5: Exclui o zero?
A6: R01 | B6: 18 | C6: =ROUND(B6*(B6+1)/4-1.959964*SQRT(B6*(B6+1)*(2*B6+1)/24),0)+1 -> 41 | D6: =MEDIAN($B$17:$S$34) -> -2.1441215 | E6: =SMALL($B$17:$S$34,C6) -> -4.8792475 | F6: =LARGE($B$17:$S$34,C6) -> 0.3010605 | G6: =IF(OR(AND(E6<0,F6<0),AND(E6>0,F6>0)),"sim","não") -> não
A7: R04 | B7: 20 | C7: =ROUND(B7*(B7+1)/4-1.959964*SQRT(B7*(B7+1)*(2*B7+1)/24),0)+1 -> 54 | D7: =MEDIAN($B$38:$U$57) -> -2.5122328 | E7: =SMALL($B$38:$U$57,C7) -> -3.2316045 | F7: =LARGE($B$38:$U$57,C7) -> -2.0614165 | G7: =IF(OR(AND(E7<0,F7<0),AND(E7>0,F7>0)),"sim","não") -> sim
A8: R08 | B8: 17 | C8: =ROUND(B8*(B8+1)/4-1.959964*SQRT(B8*(B8+1)*(2*B8+1)/24),0)+1 -> 36 | D8: =MEDIAN($B$61:$R$77) -> -1.045384 | E8: =SMALL($B$61:$R$77,C8) -> -3.0020075 | F8: =LARGE($B$61:$R$77,C8) -> 0.62425 | G8: =IF(OR(AND(E8<0,F8<0),AND(E8>0,F8>0)),"sim","não") -> não
A9: R10 | B9: 15 | C9: =ROUND(B9*(B9+1)/4-1.959964*SQRT(B9*(B9+1)*(2*B9+1)/24),0)+1 -> 26 | D9: =MEDIAN($B$81:$P$95) -> -0.9801525 | E9: =SMALL($B$81:$P$95,C9) -> -3.6329325 | F9: =LARGE($B$81:$P$95,C9) -> 1.191075 | G9: =IF(OR(AND(E9<0,F9<0),AND(E9>0,F9>0)),"sim","não") -> não
A10: O07 | B10: 20 | C10: =ROUND(B10*(B10+1)/4-1.959964*SQRT(B10*(B10+1)*(2*B10+1)/24),0)+1 -> 54 | D10: =MEDIAN($B$99:$U$118) -> -3.3705913 | E10: =SMALL($B$99:$U$118,C10) -> -4.6128405 | F10: =LARGE($B$99:$U$118,C10) -> -2.237429 | G10: =IF(OR(AND(E10<0,F10<0),AND(E10>0,F10>0)),"sim","não") -> sim
A11: O03 | B11: 15 | C11: =ROUND(B11*(B11+1)/4-1.959964*SQRT(B11*(B11+1)*(2*B11+1)/24),0)+1 -> 26 | D11: =MEDIAN($B$122:$P$136) -> -3.7304032 | E11: =SMALL($B$122:$P$136,C11) -> -4.0369975 | F11: =LARGE($B$122:$P$136,C11) -> -3.328128 | G11: =IF(OR(AND(E11<0,F11<0),AND(E11>0,F11>0)),"sim","não") -> sim
A12: O13 | B12: 16 | C12: =ROUND(B12*(B12+1)/4-1.959964*SQRT(B12*(B12+1)*(2*B12+1)/24),0)+1 -> 31 | D12: =MEDIAN($B$140:$Q$155) -> -2.0547032 | E12: =SMALL($B$140:$Q$155,C12) -> -2.18749 | F12: =LARGE($B$140:$Q$155,C12) -> 1.17822 | G12: =IF(OR(AND(E12<0,F12<0),AND(E12>0,F12>0)),"sim","não") -> não
A13: O17 | B13: 17 | C13: =ROUND(B13*(B13+1)/4-1.959964*SQRT(B13*(B13+1)*(2*B13+1)/24),0)+1 -> 36 | D13: =MEDIAN($B$159:$R$175) -> -3.7519925 | E13: =SMALL($B$159:$R$175,C13) -> -5.8310055 | F13: =LARGE($B$159:$R$175,C13) -> -1.7988725 | G13: =IF(OR(AND(E13<0,F13<0),AND(E13>0,F13>0)),"sim","não") -> sim
A14: Agregado | B14: 138 | C14: =ROUND(B14*(B14+1)/4-1.959964*SQRT(B14*(B14+1)*(2*B14+1)/24),0)+1 -> 3874 | D14: =MEDIAN($B$179:$EI$316) -> -2.508485 | E14: =SMALL($B$179:$EI$316,C14) -> -3.000599 | F14: =LARGE($B$179:$EI$316,C14) -> -1.941315 | G14: =IF(OR(AND(E14<0,F14<0),AND(E14>0,F14>0)),"sim","não") -> sim
A15: As grelhas que se seguem são o cálculo intermédio. Podem ser ocultadas sem afetar os resultados acima.
A16: Médias de Walsh — R01 (n = 18)
B17: =IF(1>=1,('Testes estatísticos'!$D$6+'Testes estatísticos'!$D$6)/2,"") -> -1.647825 | C17: =IF(2>=1,('Testes estatísticos'!$D$6+'Testes estatísticos'!$D$7)/2,"") -> -3.716032 | D17: =IF(3>=1,('Testes estatísticos'!$D$6+'Testes estatísticos'!$D$8)/2,"") -> 0.7483325 | E17: =IF(4>=1,('Testes estatísticos'!$D$6+'Testes estatísticos'!$D$9)/2,"") -> -3.904933 | F17: =IF(5>=1,('Testes estatísticos'!$D$6+'Testes estatísticos'!$D$10)/2,"") -> -1.5550705 | G17: =IF(6>=1,('Testes estatísticos'!$D$6+'Testes estatísticos'!$D$11)/2,"") -> 1.5326315 | H17: =IF(7>=1,('Testes estatísticos'!$D$6+'Testes estatísticos'!$D$12)/2,"") -> -5.324578 | I17: =IF(8>=1,('Testes estatísticos'!$D$6+'Testes estatísticos'!$D$13)/2,"") -> -1.454352 | J17: =IF(9>=1,('Testes estatísticos'!$D$6+'Testes estatísticos'!$D$14)/2,"") -> -0.801293 | K17: =IF(10>=1,('Testes estatísticos'!$D$6+'Testes estatísticos'!$D$15)/2,"") -> -1.109108 | L17: =IF(11>=1,('Testes estatísticos'!$D$6+'Testes estatísticos'!$D$16)/2,"") -> -1.702729 | M17: =IF(12>=1,('Testes estatísticos'!$D$6+'Testes estatísticos'!$D$17)/2,"") -> -4.972002 | N17: =IF(13>=1,('Testes estatísticos'!$D$6+'Testes estatísticos'!$D$18)/2,"") -> 0.881684 | O17: =IF(14>=1,('Testes estatísticos'!$D$6+'Testes estatísticos'!$D$19)/2,"") -> -0.460609 | P17: =IF(15>=1,('Testes estatísticos'!$D$6+'Testes estatísticos'!$D$20)/2,"") -> 0.9590945 | Q17: =IF(16>=1,('Testes estatísticos'!$D$6+'Testes estatísticos'!$D$21)/2,"") -> -6.34074 | R17: =IF(17>=1,('Testes estatísticos'!$D$6+'Testes estatísticos'!$D$22)/2,"") -> -2.879396 | S17: =IF(18>=1,('Testes estatísticos'!$D$6+'Testes estatísticos'!$D$23)/2,"") -> -3.9535095
B18: =IF(1>=2,('Testes estatísticos'!$D$7+'Testes estatísticos'!$D$6)/2,"") | C18: =IF(2>=2,('Testes estatísticos'!$D$7+'Testes estatísticos'!$D$7)/2,"") -> -5.784239 | D18: =IF(3>=2,('Testes estatísticos'!$D$7+'Testes estatísticos'!$D$8)/2,"") -> -1.3198745 | E18: =IF(4>=2,('Testes estatísticos'!$D$7+'Testes estatísticos'!$D$9)/2,"") -> -5.97314 | F18: =IF(5>=2,('Testes estatísticos'!$D$7+'Testes estatísticos'!$D$10)/2,"") -> -3.6232775 | G18: =IF(6>=2,('Testes estatísticos'!$D$7+'Testes estatísticos'!$D$11)/2,"") -> -0.5355755 | H18: =IF(7>=2,('Testes estatísticos'!$D$7+'Testes estatísticos'!$D$12)/2,"") -> -7.392785 | I18: =IF(8>=2,('Testes estatísticos'!$D$7+'Testes estatísticos'!$D$13)/2,"") -> -3.522559 | J18: =IF(9>=2,('Testes estatísticos'!$D$7+'Testes estatísticos'!$D$14)/2,"") -> -2.8695 | K18: =IF(10>=2,('Testes estatísticos'!$D$7+'Testes estatísticos'!$D$15)/2,"") -> -3.177315 | L18: =IF(11>=2,('Testes estatísticos'!$D$7+'Testes estatísticos'!$D$16)/2,"") -> -3.770936 | M18: =IF(12>=2,('Testes estatísticos'!$D$7+'Testes estatísticos'!$D$17)/2,"") -> -7.040209 | N18: =IF(13>=2,('Testes estatísticos'!$D$7+'Testes estatísticos'!$D$18)/2,"") -> -1.186523 | O18: =IF(14>=2,('Testes estatísticos'!$D$7+'Testes estatísticos'!$D$19)/2,"") -> -2.528816 | P18: =IF(15>=2,('Testes estatísticos'!$D$7+'Testes estatísticos'!$D$20)/2,"") -> -1.1091125 | Q18: =IF(16>=2,('Testes estatísticos'!$D$7+'Testes estatísticos'!$D$21)/2,"") -> -8.408947 | R18: =IF(17>=2,('Testes estatísticos'!$D$7+'Testes estatísticos'!$D$22)/2,"") -> -4.947603 | S18: =IF(18>=2,('Testes estatísticos'!$D$7+'Testes estatísticos'!$D$23)/2,"") -> -6.0217165
B19: =IF(1>=3,('Testes estatísticos'!$D$8+'Testes estatísticos'!$D$6)/2,"") | C19: =IF(2>=3,('Testes estatísticos'!$D$8+'Testes estatísticos'!$D$7)/2,"") | D19: =IF(3>=3,('Testes estatísticos'!$D$8+'Testes estatísticos'!$D$8)/2,"") -> 3.14449 | E19: =IF(4>=3,('Testes estatísticos'!$D$8+'Testes estatísticos'!$D$9)/2,"") -> -1.5087755 | F19: =IF(5>=3,('Testes estatísticos'!$D$8+'Testes estatísticos'!$D$10)/2,"") -> 0.841087 | G19: =IF(6>=3,('Testes estatísticos'!$D$8+'Testes estatísticos'!$D$11)/2,"") -> 3.928789 | H19: =IF(7>=3,('Testes estatísticos'!$D$8+'Testes estatísticos'!$D$12)/2,"") -> -2.9284205 | I19: =IF(8>=3,('Testes estatísticos'!$D$8+'Testes estatísticos'!$D$13)/2,"") -> 0.9418055 | J19: =IF(9>=3,('Testes estatísticos'!$D$8+'Testes estatísticos'!$D$14)/2,"") -> 1.5948645 | K19: =IF(10>=3,('Testes estatísticos'!$D$8+'Testes estatísticos'!$D$15)/2,"") -> 1.2870495 | L19: =IF(11>=3,('Testes estatísticos'!$D$8+'Testes estatísticos'!$D$16)/2,"") -> 0.6934285 | M19: =IF(12>=3,('Testes estatísticos'!$D$8+'Testes estatísticos'!$D$17)/2,"") -> -2.5758445 | N19: =IF(13>=3,('Testes estatísticos'!$D$8+'Testes estatísticos'!$D$18)/2,"") -> 3.2778415 | O19: =IF(14>=3,('Testes estatísticos'!$D$8+'Testes estatísticos'!$D$19)/2,"") -> 1.9355485 | P19: =IF(15>=3,('Testes estatísticos'!$D$8+'Testes estatísticos'!$D$20)/2,"") -> 3.355252 | Q19: =IF(16>=3,('Testes estatísticos'!$D$8+'Testes estatísticos'!$D$21)/2,"") -> -3.9445825 | R19: =IF(17>=3,('Testes estatísticos'!$D$8+'Testes estatísticos'!$D$22)/2,"") -> -0.4832385 | S19: =IF(18>=3,('Testes estatísticos'!$D$8+'Testes estatísticos'!$D$23)/2,"") -> -1.557352
B20: =IF(1>=4,('Testes estatísticos'!$D$9+'Testes estatísticos'!$D$6)/2,"") | C20: =IF(2>=4,('Testes estatísticos'!$D$9+'Testes estatísticos'!$D$7)/2,"") | D20: =IF(3>=4,('Testes estatísticos'!$D$9+'Testes estatísticos'!$D$8)/2,"") | E20: =IF(4>=4,('Testes estatísticos'!$D$9+'Testes estatísticos'!$D$9)/2,"") -> -6.162041 | F20: =IF(5>=4,('Testes estatísticos'!$D$9+'Testes estatísticos'!$D$10)/2,"") -> -3.8121785 | G20: =IF(6>=4,('Testes estatísticos'!$D$9+'Testes estatísticos'!$D$11)/2,"") -> -0.7244765 | H20: =IF(7>=4,('Testes estatísticos'!$D$9+'Testes estatísticos'!$D$12)/2,"") -> -7.581686 | I20: =IF(8>=4,('Testes estatísticos'!$D$9+'Testes estatísticos'!$D$13)/2,"") -> -3.71146 | J20: =IF(9>=4,('Testes estatísticos'!$D$9+'Testes estatísticos'!$D$14)/2,"") -> -3.058401 | K20: =IF(10>=4,('Testes estatísticos'!$D$9+'Testes estatísticos'!$D$15)/2,"") -> -3.366216 | L20: =IF(11>=4,('Testes estatísticos'!$D$9+'Testes estatísticos'!$D$16)/2,"") -> -3.959837 | M20: =IF(12>=4,('Testes estatísticos'!$D$9+'Testes estatísticos'!$D$17)/2,"") -> -7.22911 | N20: =IF(13>=4,('Testes estatísticos'!$D$9+'Testes estatísticos'!$D$18)/2,"") -> -1.375424 | O20: =IF(14>=4,('Testes estatísticos'!$D$9+'Testes estatísticos'!$D$19)/2,"") -> -2.717717 | P20: =IF(15>=4,('Testes estatísticos'!$D$9+'Testes estatísticos'!$D$20)/2,"") -> -1.2980135 | Q20: =IF(16>=4,('Testes estatísticos'!$D$9+'Testes estatísticos'!$D$21)/2,"") -> -8.597848 | R20: =IF(17>=4,('Testes estatísticos'!$D$9+'Testes estatísticos'!$D$22)/2,"") -> -5.136504 | S20: =IF(18>=4,('Testes estatísticos'!$D$9+'Testes estatísticos'!$D$23)/2,"") -> -6.2106175
B21: =IF(1>=5,('Testes estatísticos'!$D$10+'Testes estatísticos'!$D$6)/2,"") | C21: =IF(2>=5,('Testes estatísticos'!$D$10+'Testes estatísticos'!$D$7)/2,"") | D21: =IF(3>=5,('Testes estatísticos'!$D$10+'Testes estatísticos'!$D$8)/2,"") | E21: =IF(4>=5,('Testes estatísticos'!$D$10+'Testes estatísticos'!$D$9)/2,"") | F21: =IF(5>=5,('Testes estatísticos'!$D$10+'Testes estatísticos'!$D$10)/2,"") -> -1.462316 | G21: =IF(6>=5,('Testes estatísticos'!$D$10+'Testes estatísticos'!$D$11)/2,"") -> 1.625386 | H21: =IF(7>=5,('Testes estatísticos'!$D$10+'Testes estatísticos'!$D$12)/2,"") -> -5.2318235 | I21: =IF(8>=5,('Testes estatísticos'!$D$10+'Testes estatísticos'!$D$13)/2,"") -> -1.3615975 | J21: =IF(9>=5,('Testes estatísticos'!$D$10+'Testes estatísticos'!$D$14)/2,"") -> -0.7085385 | K21: =IF(10>=5,('Testes estatísticos'!$D$10+'Testes estatísticos'!$D$15)/2,"") -> -1.0163535 | L21: =IF(11>=5,('Testes estatísticos'!$D$10+'Testes estatísticos'!$D$16)/2,"") -> -1.6099745 | M21: =IF(12>=5,('Testes estatísticos'!$D$10+'Testes estatísticos'!$D$17)/2,"") -> -4.8792475 | N21: =IF(13>=5,('Testes estatísticos'!$D$10+'Testes estatísticos'!$D$18)/2,"") -> 0.9744385 | O21: =IF(14>=5,('Testes estatísticos'!$D$10+'Testes estatísticos'!$D$19)/2,"") -> -0.3678545 | P21: =IF(15>=5,('Testes estatísticos'!$D$10+'Testes estatísticos'!$D$20)/2,"") -> 1.051849 | Q21: =IF(16>=5,('Testes estatísticos'!$D$10+'Testes estatísticos'!$D$21)/2,"") -> -6.2479855 | R21: =IF(17>=5,('Testes estatísticos'!$D$10+'Testes estatísticos'!$D$22)/2,"") -> -2.7866415 | S21: =IF(18>=5,('Testes estatísticos'!$D$10+'Testes estatísticos'!$D$23)/2,"") -> -3.860755
B22: =IF(1>=6,('Testes estatísticos'!$D$11+'Testes estatísticos'!$D$6)/2,"") | C22: =IF(2>=6,('Testes estatísticos'!$D$11+'Testes estatísticos'!$D$7)/2,"") | D22: =IF(3>=6,('Testes estatísticos'!$D$11+'Testes estatísticos'!$D$8)/2,"") | E22: =IF(4>=6,('Testes estatísticos'!$D$11+'Testes estatísticos'!$D$9)/2,"") | F22: =IF(5>=6,('Testes estatísticos'!$D$11+'Testes estatísticos'!$D$10)/2,"") | G22: =IF(6>=6,('Testes estatísticos'!$D$11+'Testes estatísticos'!$D$11)/2,"") -> 4.713088 | H22: =IF(7>=6,('Testes estatísticos'!$D$11+'Testes estatísticos'!$D$12)/2,"") -> -2.1441215 | I22: =IF(8>=6,('Testes estatísticos'!$D$11+'Testes estatísticos'!$D$13)/2,"") -> 1.7261045 | J22: =IF(9>=6,('Testes estatísticos'!$D$11+'Testes estatísticos'!$D$14)/2,"") -> 2.3791635 | K22: =IF(10>=6,('Testes estatísticos'!$D$11+'Testes estatísticos'!$D$15)/2,"") -> 2.0713485 | L22: =IF(11>=6,('Testes estatísticos'!$D$11+'Testes estatísticos'!$D$16)/2,"") -> 1.4777275 | M22: =IF(12>=6,('Testes estatísticos'!$D$11+'Testes estatísticos'!$D$17)/2,"") -> -1.7915455 | N22: =IF(13>=6,('Testes estatísticos'!$D$11+'Testes estatísticos'!$D$18)/2,"") -> 4.0621405 | O22: =IF(14>=6,('Testes estatísticos'!$D$11+'Testes estatísticos'!$D$19)/2,"") -> 2.7198475 | P22: =IF(15>=6,('Testes estatísticos'!$D$11+'Testes estatísticos'!$D$20)/2,"") -> 4.139551 | Q22: =IF(16>=6,('Testes estatísticos'!$D$11+'Testes estatísticos'!$D$21)/2,"") -> -3.1602835 | R22: =IF(17>=6,('Testes estatísticos'!$D$11+'Testes estatísticos'!$D$22)/2,"") -> 0.3010605 | S22: =IF(18>=6,('Testes estatísticos'!$D$11+'Testes estatísticos'!$D$23)/2,"") -> -0.773053
B23: =IF(1>=7,('Testes estatísticos'!$D$12+'Testes estatísticos'!$D$6)/2,"") | C23: =IF(2>=7,('Testes estatísticos'!$D$12+'Testes estatísticos'!$D$7)/2,"") | D23: =IF(3>=7,('Testes estatísticos'!$D$12+'Testes estatísticos'!$D$8)/2,"") | E23: =IF(4>=7,('Testes estatísticos'!$D$12+'Testes estatísticos'!$D$9)/2,"") | F23: =IF(5>=7,('Testes estatísticos'!$D$12+'Testes estatísticos'!$D$10)/2,"") | G23: =IF(6>=7,('Testes estatísticos'!$D$12+'Testes estatísticos'!$D$11)/2,"") | H23: =IF(7>=7,('Testes estatísticos'!$D$12+'Testes estatísticos'!$D$12)/2,"") -> -9.001331 | I23: =IF(8>=7,('Testes estatísticos'!$D$12+'Testes estatísticos'!$D$13)/2,"") -> -5.131105 | J23: =IF(9>=7,('Testes estatísticos'!$D$12+'Testes estatísticos'!$D$14)/2,"") -> -4.478046 | K23: =IF(10>=7,('Testes estatísticos'!$D$12+'Testes estatísticos'!$D$15)/2,"") -> -4.785861 | L23: =IF(11>=7,('Testes estatísticos'!$D$12+'Testes estatísticos'!$D$16)/2,"") -> -5.379482 | M23: =IF(12>=7,('Testes estatísticos'!$D$12+'Testes estatísticos'!$D$17)/2,"") -> -8.648755 | N23: =IF(13>=7,('Testes estatísticos'!$D$12+'Testes estatísticos'!$D$18)/2,"") -> -2.795069 | O23: =IF(14>=7,('Testes estatísticos'!$D$12+'Testes estatísticos'!$D$19)/2,"") -> -4.137362 | P23: =IF(15>=7,('Testes estatísticos'!$D$12+'Testes estatísticos'!$D$20)/2,"") -> -2.7176585 | Q23: =IF(16>=7,('Testes estatísticos'!$D$12+'Testes estatísticos'!$D$21)/2,"") -> -10.017493 | R23: =IF(17>=7,('Testes estatísticos'!$D$12+'Testes estatísticos'!$D$22)/2,"") -> -6.556149 | S23: =IF(18>=7,('Testes estatísticos'!$D$12+'Testes estatísticos'!$D$23)/2,"") -> -7.6302625
