Workbook

Sheet Pressupostos
A1: Plano experimental TM12 — Sleep vs. estados 4 cenários de repetibilidade + 4 condições de obstáculos
A4: Condições fixas do estudo | E4: Cenários de repetibilidade — 20 repetições por arquitetura | I4: Condições de obstáculos — 20 repetições por arquitetura
A5: Parâmetro | B5: Valor | E5: ID | F5: Pick XYZ (m) | G5: Place XYZ (m) | I5: ID | J5: Pick XYZ (m) | K5: Place XYZ (m) | L5: Obstáculo
A6: Repetições por cenário e arquitetura | B6: 20 | E6: R01 | F6: (0,55; -0,20; 0,35) | G6: (0,70; 0,20; 0,42) | I6: O07 | J6: (0,88; 0,45; -0,10) | K6: (0,39; 0,93;- 0,14) | L6: (0,577; 0,757; -0,18) | M6: c =0,355 | N6: l= 0,255 | O6: a= 0,12
A7: Project Speed | B7: 0.55 | E7: R04 | F7: (0,70; -0,25; 0,35) | G7: (0,52; -0,25; 0,42) | I7: O03 | J7: (1,050;-0,050;-0,140) | K7: (0,70; 0,32; -0,140) | L7: (0,932; 0,239; -0,18) | M7: c =0,355 | N7: l= 0,255 | O7: a= 0,12
A8: Planeador principal | B8: RRTConnect | E8: R08 | F8: (0,55; 0,30; 0,35) | G8: (0,75; -0,25; 0,42) | I8: O13 | J8: (1,21;0,11;-0,02 | K8: (0,88; 0,48; - 0,030) | L8: (1.0170; 0.3220; -0.0625) | M8: c =0,255 | N8: l= 0,12 | O8: a= 0,355
E9: R10 | F9: (0,75; 0,30; 0,35) | G9: (0,50; -0,30; 0,42) | I9: O17 | J9: (0,72; 0,63; -0,03) | K9: (0,25; 0,97; -0,05) | L9: (0,495; 0,845; -0,0625) | M9: c =0,255 | N9: l= 0,12 | O9: a= 0,355
A11: Configuração temporal | E11: Definições operacionais e análise estatística
A12: Fase | B12: Timeout W/R (ms) | C12: Sleep seguinte (ms) | E12: Métrica | F12: Definição | G12: Métrica | H12: Definição | I12: Nota
A13: STATUS | B13: 2000 | C13: 1000 | E13: Tempo total | F13: PICK até resposta FINISH | G13: Espera improdutiva | H13: Soma dos intervalos resposta → comando seguinte | I13: O Sleep inicial antes de PICK fica documentado, mas fora do ciclo.
A14: PICK | B14: 10000 | C14: 300 | E14: Timeout | F14: Resposta excede o limite | G14: Prematuro | H14: Novo comando com outro pendente | I14: Aproximação normal.
A15: TARGET_PICK | B15: 10000 | C15: 300 | E15: Taxa de sucesso | F15: Ciclos com sucesso / ciclos concluídos | G15: Recuperação | H15: Falha até regresso seguro/PRONTO | I15: Confirmar normalidade das diferenças.
A16: MOVE_PICK | B16: 95000 | C16: 300 | E16: Variabilidade | F16: Desvio-padrão, IQR e CV | G16: Falha | H16: Erro que impede conclusão normal | I16: Executar fora do Excel se necessário.
A17: CLOSE | B17: 35000 | C17: 300 | E17: Fase | F17: Comando individual do ciclo | G17: Resposta fase | H17: Comando até resposta correspondente | I17: Não apagar falhas.
A18: TARGET_PLACE | B18: 10000 | C18: 300
A19: MOVE_PLACE | B19: 95000 | C19: 300
A20: OPEN | B20: 35000 | C20: 300
A21: FINISH_HOME | B21: 95000 | C21: 0
A50: Definição operacional do tempo de recuperação (revisão de 2026-08-18)
A51: Tempo de recuperação = intervalo entre a receção da primeira resposta de erro e a receção da resposta terminal ao cancelamento, medido no registo SentinelProcessEngine20260724 do VisionCore. A arquitetura temporal não possui ramo de erro: não lê a resposta, não deteta a falha e o fluxo não contém blocos de cancelamento. Nas 147 condições incluídas na análise comparativa não existe nenhum CANCEL nesta arquitetura. O único CANCEL presente no ficheiro temporal_ciclos.csv (TEMP_156) pertence a uma sessão posterior, executada fora da sequência de ensaios, e não integra a comparação. Os valores antes inscritos na coluna da arquitetura temporal são anotações manuais do tempo até à retoma pelo operador, não são comparáveis com os da arquitetura por respostas e não são reportados no Capítulo 5.

Sheet Resumo
A1: Resumo estatístico — ciclo completo Média, mediana, variabilidade, IC 95%, outliers e comparação emparelhada
A4: Chave | B4: Conjunto | C4: Cenário | D4: n | E4: Taxa sucesso | F4: Média total (s) | G4: Mediana (s) | H4: Desvio-padrão (s) | I4: CV | J4: Mínimo (s) | K4: Máximo (s) | L4: Q1 | M4: Q3 | N4: IQR | O4: Limite inferior | P4: Limite superior | Q4: IC95 inferior | R4: IC95 superior | S4: Espera média (s) | T4: Timeouts | U4: Prematuros | V4: Falhas | W4: Recuperação média (s)
A5: Repetibilidade|R01|Temporal (Sleep + Write/Read) | B5: Repetibilidade | C5: R01 | D5: =COUNT(Rep_Ciclos!$C$5:$C$24) -> 20 | E5: =IF(D5=0,"",SUM(Rep_Ciclos!$G$5:$G$24)/D5) -> 1 | F5: =IF(D5=0,"",AVERAGE(Rep_Ciclos!$C$5:$C$24)) -> 50.650789 | G5: =IF(D5=0,"",MEDIAN(Rep_Ciclos!$C$5:$C$24)) -> 50.413238 | H5: =IF(D5<2,"",_xlfn.STDEV.S(Rep_Ciclos!$C$5:$C$24)) -> 3.2554115 | I5: =IF(OR(D5<2,F5=0),"",H5/F5) -> 0.064271685 | J5: =IF(D5=0,"",MIN(Rep_Ciclos!$C$5:$C$24)) -> 45.297633 | K5: =IF(D5=0,"",MAX(Rep_Ciclos!$C$5:$C$24)) -> 55.602209 | L5: =IF(D5=0,"",_xlfn.QUARTILE.INC(Rep_Ciclos!$C$5:$C$24,1)) -> 48.238245 | M5: =IF(D5=0,"",_xlfn.QUARTILE.INC(Rep_Ciclos!$C$5:$C$24,3)) -> 53.529413 | N5: =IF(D5=0,"",M5-L5) -> 5.2911685 | O5: =IF(D5=0,"",L5-1.5*N5) -> 40.301492 | P5: =IF(D5=0,"",M5+1.5*N5) -> 61.466166 | Q5: =IF(D5<2,"",F5-1.96*H5/SQRT(D5)) -> 49.224042 | R5: =IF(D5<2,"",F5+1.96*H5/SQRT(D5)) -> 52.077536 | S5: =IF(D5=0,"",AVERAGE(Rep_Ciclos!$D$5:$D$24)) -> 3.2159802 | T5: =IF(D5=0,"",SUM(Rep_Ciclos!$E$5:$E$24)) -> 0 | U5: =IF(D5=0,"",SUM(Rep_Ciclos!$F$5:$F$24)) -> 0 | V5: =IF(D5=0,"",SUM(Rep_Ciclos!$I$5:$I$24)) -> 0 | W5: =IF(D5=0,"",IFERROR(SUMIF(Rep_Ciclos!$I$5:$I$24,">0",Rep_Ciclos!$J$5:$J$24)/COUNTIF(Rep_Ciclos!$I$5:$I$24,">0"),0)) -> 0
A6: Repetibilidade|R01|Estados (respostas + validação) | B6: Repetibilidade | C6: R01E | D6: =COUNT(Rep_Ciclos!$C$27:$C$46) -> 20 | E6: =IF(D6=0,"",SUM(Rep_Ciclos!$G$27:$G$46)/D6) -> 0.9 | F6: =IF(D6=0,"",AVERAGE(Rep_Ciclos!$C$27:$C$46)) -> 46.95605 | G6: =IF(D6=0,"",MEDIAN(Rep_Ciclos!$C$27:$C$46)) -> 48.078 | H6: =IF(D6<2,"",_xlfn.STDEV.S(Rep_Ciclos!$C$27:$C$46)) -> 4.5337113 | I6: =IF(OR(D6<2,F6=0),"",H6/F6) -> 0.096552228 | J6: =IF(D6=0,"",MIN(Rep_Ciclos!$C$27:$C$46)) -> 33.634 | K6: =IF(D6=0,"",MAX(Rep_Ciclos!$C$27:$C$46)) -> 53.615 | L6: =IF(D6=0,"",_xlfn.QUARTILE.INC(Rep_Ciclos!$C$27:$C$46,1)) -> 43.51725 | M6: =IF(D6=0,"",_xlfn.QUARTILE.INC(Rep_Ciclos!$C$27:$C$46,3)) -> 49.27975 | N6: =IF(D6=0,"",M6-L6) -> 5.7625 | O6: =IF(D6=0,"",L6-1.5*N6) -> 34.8735 | P6: =IF(D6=0,"",M6+1.5*N6) -> 57.9235 | Q6: =IF(D6<2,"",F6-1.96*H6/SQRT(D6)) -> 44.969063 | R6: =IF(D6<2,"",F6+1.96*H6/SQRT(D6)) -> 48.943037 | S6: =IF(D6=0,"",AVERAGE(Rep_Ciclos!$D$27:$D$46)) -> 1.0882 | T6: =IF(D6=0,"",SUM(Rep_Ciclos!$E$27:$E$46)) -> 0 | U6: =IF(D6=0,"",SUM(Rep_Ciclos!$F$27:$F$46)) -> 0 | V6: =IF(D6=0,"",SUM(Rep_Ciclos!$I$27:$I$46)) -> 2 | W6: =IF(D6=0,"",IFERROR(SUMIF(Rep_Ciclos!$I$27:$I$46,">0",Rep_Ciclos!$J$27:$J$46)/COUNTIF(Rep_Ciclos!$I$27:$I$46,">0"),0)) -> 6.05
A7: Repetibilidade|R04|Temporal (Sleep + Write/Read) | B7: Repetibilidade | C7: R04 | D7: =COUNT(Rep_Ciclos!$R$5:$R$24) -> 20 | E7: =IF(D7=0,"",SUM(Rep_Ciclos!$V$5:$V$24)/D7) -> 1 | F7: =IF(D7=0,"",AVERAGE(Rep_Ciclos!$R$5:$R$24)) -> 46.273134 | G7: =IF(D7=0,"",MEDIAN(Rep_Ciclos!$R$5:$R$24)) -> 45.062233 | H7: =IF(D7<2,"",_xlfn.STDEV.S(Rep_Ciclos!$R$5:$R$24)) -> 1.9028096 | I7: =IF(OR(D7<2,F7=0),"",H7/F7) -> 0.041121261 | J7: =IF(D7=0,"",MIN(Rep_Ciclos!$R$5:$R$24)) -> 44.793365 | K7: =IF(D7=0,"",MAX(Rep_Ciclos!$R$5:$R$24)) -> 50.397911 | L7: =IF(D7=0,"",_xlfn.QUARTILE.INC(Rep_Ciclos!$R$5:$R$24,1)) -> 44.968973 | M7: =IF(D7=0,"",_xlfn.QUARTILE.INC(Rep_Ciclos!$R$5:$R$24,3)) -> 46.762417 | N7: =IF(D7=0,"",M7-L7) -> 1.7934443 | O7: =IF(D7=0,"",L7-1.5*N7) -> 42.278807 | P7: =IF(D7=0,"",M7+1.5*N7) -> 49.452584 | Q7: =IF(D7<2,"",F7-1.96*H7/SQRT(D7)) -> 45.439191 | R7: =IF(D7<2,"",F7+1.96*H7/SQRT(D7)) -> 47.107077 | S7: =IF(D7=0,"",AVERAGE(Rep_Ciclos!$S$5:$S$24)) -> 3.2367335 | T7: =IF(D7=0,"",SUM(Rep_Ciclos!$T$5:$T$24)) -> 0 | U7: =IF(D7=0,"",SUM(Rep_Ciclos!$U$5:$U$24)) -> 0 | V7: =IF(D7=0,"",SUM(Rep_Ciclos!$X$5:$X$24)) -> 0 | W7: =IF(D7=0,"",IFERROR(SUMIF(Rep_Ciclos!$X$5:$X$24,">0",Rep_Ciclos!$Y$5:$Y$24)/COUNTIF(Rep_Ciclos!$X$5:$X$24,">0"),0)) -> 0
A8: Repetibilidade|R04|Estados (respostas + validação) | B8: Repetibilidade | C8: R04E | D8: =COUNT(Rep_Ciclos!$R$27:$R$46) -> 20 | E8: =IF(D8=0,"",SUM(Rep_Ciclos!$V$27:$V$46)/D8) -> 1 | F8: =IF(D8=0,"",AVERAGE(Rep_Ciclos!$R$27:$R$46)) -> 43.814484 | G8: =IF(D8=0,"",MEDIAN(Rep_Ciclos!$R$27:$R$46)) -> 42.806957 | H8: =IF(D8<2,"",_xlfn.STDEV.S(Rep_Ciclos!$R$27:$R$46)) -> 1.8668581 | I8: =IF(OR(D8<2,F8=0),"",H8/F8) -> 0.04260824 | J8: =IF(D8=0,"",MIN(Rep_Ciclos!$R$27:$R$46)) -> 42.650284 | K8: =IF(D8=0,"",MAX(Rep_Ciclos!$R$27:$R$46)) -> 48.329302 | L8: =IF(D8=0,"",_xlfn.QUARTILE.INC(Rep_Ciclos!$R$27:$R$46,1)) -> 42.73558 | M8: =IF(D8=0,"",_xlfn.QUARTILE.INC(Rep_Ciclos!$R$27:$R$46,3)) -> 44.280104 | N8: =IF(D8=0,"",M8-L8) -> 1.544524 | O8: =IF(D8=0,"",L8-1.5*N8) -> 40.418794 | P8: =IF(D8=0,"",M8+1.5*N8) -> 46.59689 | Q8: =IF(D8<2,"",F8-1.96*H8/SQRT(D8)) -> 42.996297 | R8: =IF(D8<2,"",F8+1.96*H8/SQRT(D8)) -> 44.63267 | S8: =IF(D8=0,"",AVERAGE(Rep_Ciclos!$S$27:$S$46)) -> 1.062422 | T8: =IF(D8=0,"",SUM(Rep_Ciclos!$T$27:$T$46)) -> 0 | U8: =IF(D8=0,"",SUM(Rep_Ciclos!$U$27:$U$46)) -> 0 | V8: =IF(D8=0,"",SUM(Rep_Ciclos!$X$27:$X$46)) -> 0 | W8: =IF(D8=0,"",IFERROR(SUMIF(Rep_Ciclos!$X$27:$X$46,">0",Rep_Ciclos!$Y$27:$Y$46)/COUNTIF(Rep_Ciclos!$X$27:$X$46,">0"),0)) -> 0
A9: Repetibilidade|R08|Temporal (Sleep + Write/Read) | B9: Repetibilidade | C9: R08 | D9: =COUNT(Rep_Ciclos!$AG$5:$AG$24) -> 20 | E9: =IF(D9=0,"",SUM(Rep_Ciclos!$AK$5:$AK$24)/D9) -> 0.95 | F9: =IF(D9=0,"",AVERAGE(Rep_Ciclos!$AG$5:$AG$24)) -> 47.388787 | G9: =IF(D9=0,"",MEDIAN(Rep_Ciclos!$AG$5:$AG$24)) -> 48.145537 | H9: =IF(D9<2,"",_xlfn.STDEV.S(Rep_Ciclos!$AG$5:$AG$24)) -> 5.0999123 | I9: =IF(OR(D9<2,F9=0),"",H9/F9) -> 0.10761855 | J9: =IF(D9=0,"",MIN(Rep_Ciclos!$AG$5:$AG$24)) -> 28.181661 | K9: =IF(D9=0,"",MAX(Rep_Ciclos!$AG$5:$AG$24)) -> 52.341899 | L9: =IF(D9=0,"",_xlfn.QUARTILE.INC(Rep_Ciclos!$AG$5:$AG$24,1)) -> 45.449249 | M9: =IF(D9=0,"",_xlfn.QUARTILE.INC(Rep_Ciclos!$AG$5:$AG$24,3)) -> 50.230511 | N9: =IF(D9=0,"",M9-L9) -> 4.7812613 | O9: =IF(D9=0,"",L9-1.5*N9) -> 38.277357 | P9: =IF(D9=0,"",M9+1.5*N9) -> 57.402402 | Q9: =IF(D9<2,"",F9-1.96*H9/SQRT(D9)) -> 45.153652 | R9: =IF(D9<2,"",F9+1.96*H9/SQRT(D9)) -> 49.623922 | S9: =IF(D9=0,"",AVERAGE(Rep_Ciclos!$AH$5:$AH$24)) -> 3.2173127 | T9: =IF(D9=0,"",SUM(Rep_Ciclos!$AI$5:$AI$24)) -> 0 | U9: =IF(D9=0,"",SUM(Rep_Ciclos!$AJ$5:$AJ$24)) -> 0 | V9: =IF(D9=0,"",SUM(Rep_Ciclos!$AM$5:$AM$24)) -> 1 | W9: =IF(D9=0,"",IFERROR(SUMIF(Rep_Ciclos!$AM$5:$AM$24,">0",Rep_Ciclos!$AN$5:$AN$24)/COUNTIF(Rep_Ciclos!$AM$5:$AM$24,">0"),0)) -> 12.6
A10: Repetibilidade|R08|Estados (respostas + validação) | B10: Repetibilidade | C10: R08E | D10: =COUNT(Rep_Ciclos!$AG$27:$AG$46) -> 20 | E10: =IF(D10=0,"",SUM(Rep_Ciclos!$AK$27:$AK$46)/D10) -> 0.9 | F10: =IF(D10=0,"",AVERAGE(Rep_Ciclos!$AG$27:$AG$46)) -> 43.017507 | G10: =IF(D10=0,"",MEDIAN(Rep_Ciclos!$AG$27:$AG$46)) -> 44.838845 | H10: =IF(D10<2,"",_xlfn.STDEV.S(Rep_Ciclos!$AG$27:$AG$46)) -> 13.147875 | I10: =IF(OR(D10<2,F10=0),"",H10/F10) -> 0.3056401 | J10: =IF(D10=0,"",MIN(Rep_Ciclos!$AG$27:$AG$46)) -> 6.192219 | K10: =IF(D10=0,"",MAX(Rep_Ciclos!$AG$27:$AG$46)) -> 55.879504 | L10: =IF(D10=0,"",_xlfn.QUARTILE.INC(Rep_Ciclos!$AG$27:$AG$46,1)) -> 43.923187 | M10: =IF(D10=0,"",_xlfn.QUARTILE.INC(Rep_Ciclos!$AG$27:$AG$46,3)) -> 48.664011 | N10: =IF(D10=0,"",M10-L10) -> 4.740823 | O10: =IF(D10=0,"",L10-1.5*N10) -> 36.811953 | P10: =IF(D10=0,"",M10+1.5*N10) -> 55.775245 | Q10: =IF(D10<2,"",F10-1.96*H10/SQRT(D10)) -> 37.255196 | R10: =IF(D10<2,"",F10+1.96*H10/SQRT(D10)) -> 48.779817 | S10: =IF(D10=0,"",AVERAGE(Rep_Ciclos!$AH$27:$AH$46)) -> 1.0315359 | T10: =IF(D10=0,"",SUM(Rep_Ciclos!$AI$27:$AI$46)) -> 0 | U10: =IF(D10=0,"",SUM(Rep_Ciclos!$AJ$27:$AJ$46)) -> 0 | V10: =IF(D10=0,"",SUM(Rep_Ciclos!$AM$27:$AM$46)) -> 2 | W10: =IF(D10=0,"",IFERROR(SUMIF(Rep_Ciclos!$AM$27:$AM$46,">0",Rep_Ciclos!$AN$27:$AN$46)/COUNTIF(Rep_Ciclos!$AM$27:$AM$46,">0"),0)) -> 6.75
A11: Repetibilidade|R10|Temporal (Sleep + Write/Read) | B11: Repetibilidade | C11: R10 | D11: =COUNT(Rep_Ciclos!$AV$5:$AV$24) -> 20 | E11: =IF(D11=0,"",SUM(Rep_Ciclos!$AZ$5:$AZ$24)/D11) -> 0.85 | F11: =IF(D11=0,"",AVERAGE(Rep_Ciclos!$AV$5:$AV$24)) -> 47.705359 | G11: =IF(D11=0,"",MEDIAN(Rep_Ciclos!$AV$5:$AV$24)) -> 50.275163 | H11: =IF(D11<2,"",_xlfn.STDEV.S(Rep_Ciclos!$AV$5:$AV$24)) -> 8.3955048 | I11: =IF(OR(D11<2,F11=0),"",H11/F11) -> 0.17598662 | J11: =IF(D11=0,"",MIN(Rep_Ciclos!$AV$5:$AV$24)) -> 28.575338 | K11: =IF(D11=0,"",MAX(Rep_Ciclos!$AV$5:$AV$24)) -> 56.109755 | L11: =IF(D11=0,"",_xlfn.QUARTILE.INC(Rep_Ciclos!$AV$5:$AV$24,1)) -> 46.617645 | M11: =IF(D11=0,"",_xlfn.QUARTILE.INC(Rep_Ciclos!$AV$5:$AV$24,3)) -> 52.214968 | N11: =IF(D11=0,"",M11-L11) -> 5.5973222 | O11: =IF(D11=0,"",L11-1.5*N11) -> 38.221662 | P11: =IF(D11=0,"",M11+1.5*N11) -> 60.610951 | Q11: =IF(D11<2,"",F11-1.96*H11/SQRT(D11)) -> 44.025867 | R11: =IF(D11<2,"",F11+1.96*H11/SQRT(D11)) -> 51.384851 | S11: =IF(D11=0,"",AVERAGE(Rep_Ciclos!$AW$5:$AW$24)) -> 3.3282079 | T11: =IF(D11=0,"",SUM(Rep_Ciclos!$AX$5:$AX$24)) -> 0 | U11: =IF(D11=0,"",SUM(Rep_Ciclos!$AY$5:$AY$24)) -> 0 | V11: =IF(D11=0,"",SUM(Rep_Ciclos!$BB$5:$BB$24)) -> 3 | W11: =IF(D11=0,"",IFERROR(SUMIF(Rep_Ciclos!$BB$5:$BB$24,">0",Rep_Ciclos!$BC$5:$BC$24)/COUNTIF(Rep_Ciclos!$BB$5:$BB$24,">0"),0)) -> 11.966667
A12: Repetibilidade|R10|Estados (respostas + validação) | B12: Repetibilidade | C12: R10E | D12: =COUNT(Rep_Ciclos!$AV$27:$AV$46) -> 20 | E12: =IF(D12=0,"",SUM(Rep_Ciclos!$AZ$27:$AZ$46)/D12) -> 0.95 | F12: =IF(D12=0,"",AVERAGE(Rep_Ciclos!$AV$27:$AV$46)) -> 46.837471 | G12: =IF(D12=0,"",MEDIAN(Rep_Ciclos!$AV$27:$AV$46)) -> 48.73554 | H12: =IF(D12<2,"",_xlfn.STDEV.S(Rep_Ciclos!$AV$27:$AV$46)) -> 9.9886799 | I12: =IF(OR(D12<2,F12=0),"",H12/F12) -> 0.21326258 | J12: =IF(D12=0,"",MIN(Rep_Ciclos!$AV$27:$AV$46)) -> 6.113277 | K12: =IF(D12=0,"",MAX(Rep_Ciclos!$AV$27:$AV$46)) -> 53.955051 | L12: =IF(D12=0,"",_xlfn.QUARTILE.INC(Rep_Ciclos!$AV$27:$AV$46,1)) -> 47.242883 | M12: =IF(D12=0,"",_xlfn.QUARTILE.INC(Rep_Ciclos!$AV$27:$AV$46,3)) -> 50.220708 | N12: =IF(D12=0,"",M12-L12) -> 2.9778245 | O12: =IF(D12=0,"",L12-1.5*N12) -> 42.776146 | P12: =IF(D12=0,"",M12+1.5*N12) -> 54.687444 | Q12: =IF(D12<2,"",F12-1.96*H12/SQRT(D12)) -> 42.459739 | R12: =IF(D12<2,"",F12+1.96*H12/SQRT(D12)) -> 51.215203 | S12: =IF(D12=0,"",AVERAGE(Rep_Ciclos!$AW$27:$AW$46)) -> 1.0657459 | T12: =IF(D12=0,"",SUM(Rep_Ciclos!$AX$27:$AX$46)) -> 0 | U12: =IF(D12=0,"",SUM(Rep_Ciclos!$AY$27:$AY$46)) -> 0 | V12: =IF(D12=0,"",SUM(Rep_Ciclos!$BB$27:$BB$46)) -> 1 | W12: =IF(D12=0,"",IFERROR(SUMIF(Rep_Ciclos!$BB$27:$BB$46,">0",Rep_Ciclos!$BC$27:$BC$46)/COUNTIF(Rep_Ciclos!$BB$27:$BB$46,">0"),0)) -> 6.8
A13: Obstáculos|O07|Temporal (Sleep + Write/Read) | B13: Obstáculos | C13: O07 | D13: =COUNT(Obs_Ciclos!$C$5:$C$24) -> 20 | E13: =IF(D13=0,"",SUM(Obs_Ciclos!$G$5:$G$24)/D13) -> 1 | F13: =IF(D13=0,"",AVERAGE(Obs_Ciclos!$C$5:$C$24)) -> 50.888972 | G13: =IF(D13=0,"",MEDIAN(Obs_Ciclos!$C$5:$C$24)) -> 50.16863 | H13: =IF(D13<2,"",_xlfn.STDEV.S(Obs_Ciclos!$C$5:$C$24)) -> 1.5545822 | I13: =IF(OR(D13<2,F13=0),"",H13/F13) -> 0.030548509 | J13: =IF(D13=0,"",MIN(Obs_Ciclos!$C$5:$C$24)) -> 49.151743 | K13: =IF(D13=0,"",MAX(Obs_Ciclos!$C$5:$C$24)) -> 56.114478 | L13: =IF(D13=0,"",_xlfn.QUARTILE.INC(Obs_Ciclos!$C$5:$C$24,1)) -> 50.0424 | M13: =IF(D13=0,"",_xlfn.QUARTILE.INC(Obs_Ciclos!$C$5:$C$24,3)) -> 51.597563 | N13: =IF(D13=0,"",M13-L13) -> 1.5551635 | O13: =IF(D13=0,"",L13-1.5*N13) -> 47.709655 | P13: =IF(D13=0,"",M13+1.5*N13) -> 53.930309 | Q13: =IF(D13<2,"",F13-1.96*H13/SQRT(D13)) -> 50.207646 | R13: =IF(D13<2,"",F13+1.96*H13/SQRT(D13)) -> 51.570297 | S13: =IF(D13=0,"",AVERAGE(Obs_Ciclos!$D$5:$D$24)) -> 3.3792034 | T13: =IF(D13=0,"",SUM(Obs_Ciclos!$E$5:$E$24)) -> 0 | U13: =IF(D13=0,"",SUM(Obs_Ciclos!$F$5:$F$24)) -> 0 | V13: =IF(D13=0,"",SUM(Obs_Ciclos!$I$5:$I$24)) -> 0 | W13: =IF(D13=0,"",IFERROR(SUMIF(Obs_Ciclos!$I$5:$I$24,">0",Obs_Ciclos!$J$5:$J$24)/COUNTIF(Obs_Ciclos!$I$5:$I$24,">0"),0)) -> 0
A14: Obstáculos|O07|Estados (respostas + validação) | B14: Obstáculos | C14: O07E | D14: =COUNT(Obs_Ciclos!$C$27:$C$46) -> 20 | E14: =IF(D14=0,"",SUM(Obs_Ciclos!$G$27:$G$46)/D14) -> 1 | F14: =IF(D14=0,"",AVERAGE(Obs_Ciclos!$C$27:$C$46)) -> 47.742953 | G14: =IF(D14=0,"",MEDIAN(Obs_Ciclos!$C$27:$C$46)) -> 46.922506 | H14: =IF(D14<2,"",_xlfn.STDEV.S(Obs_Ciclos!$C$27:$C$46)) -> 2.9635511 | I14: =IF(OR(D14<2,F14=0),"",H14/F14) -> 0.062073057 | J14: =IF(D14=0,"",MIN(Obs_Ciclos!$C$27:$C$46)) -> 45.363616 | K14: =IF(D14=0,"",MAX(Obs_Ciclos!$C$27:$C$46)) -> 55.880272 | L14: =IF(D14=0,"",_xlfn.QUARTILE.INC(Obs_Ciclos!$C$27:$C$46,1)) -> 45.967743 | M14: =IF(D14=0,"",_xlfn.QUARTILE.INC(Obs_Ciclos!$C$27:$C$46,3)) -> 47.735731 | N14: =IF(D14=0,"",M14-L14) -> 1.7679873 | O14: =IF(D14=0,"",L14-1.5*N14) -> 43.315763 | P14: =IF(D14=0,"",M14+1.5*N14) -> 50.387712 | Q14: =IF(D14<2,"",F14-1.96*H14/SQRT(D14)) -> 46.444119 | R14: =IF(D14<2,"",F14+1.96*H14/SQRT(D14)) -> 49.041786 | S14: =IF(D14=0,"",AVERAGE(Obs_Ciclos!$D$27:$D$46)) -> 1.0413424 | T14: =IF(D14=0,"",SUM(Obs_Ciclos!$E$27:$E$46)) -> 0 | U14: =IF(D14=0,"",SUM(Obs_Ciclos!$F$27:$F$46)) -> 0 | V14: =IF(D14=0,"",SUM(Obs_Ciclos!$I$27:$I$46)) -> 0 | W14: =IF(D14=0,"",IFERROR(SUMIF(Obs_Ciclos!$I$27:$I$46,">0",Obs_Ciclos!$J$27:$J$46)/COUNTIF(Obs_Ciclos!$I$27:$I$46,">0"),0)) -> 0
A15: Obstáculos|O03|Temporal (Sleep + Write/Read) | B15: Obstáculos | C15: O03 | D15: =COUNT(Obs_Ciclos!$Q$5:$Q$24) -> 20 | E15: =IF(D15=0,"",SUM(Obs_Ciclos!$U$5:$U$24)/D15) -> 1 | F15: =IF(D15=0,"",AVERAGE(Obs_Ciclos!$Q$5:$Q$24)) -> 51.012385 | G15: =IF(D15=0,"",MEDIAN(Obs_Ciclos!$Q$5:$Q$24)) -> 50.966386 | H15: =IF(D15<2,"",_xlfn.STDEV.S(Obs_Ciclos!$Q$5:$Q$24)) -> 0.23792009 | I15: =IF(OR(D15<2,F15=0),"",H15/F15) -> 0.0046639671 | J15: =IF(D15=0,"",MIN(Obs_Ciclos!$Q$5:$Q$24)) -> 50.651345 | K15: =IF(D15=0,"",MAX(Obs_Ciclos!$Q$5:$Q$24)) -> 51.59837 | L15: =IF(D15=0,"",_xlfn.QUARTILE.INC(Obs_Ciclos!$Q$5:$Q$24,1)) -> 50.866733 | M15: =IF(D15=0,"",_xlfn.QUARTILE.INC(Obs_Ciclos!$Q$5:$Q$24,3)) -> 51.08889 | N15: =IF(D15=0,"",M15-L15) -> 0.22215667 | O15: =IF(D15=0,"",L15-1.5*N15) -> 50.533498 | P15: =IF(D15=0,"",M15+1.5*N15) -> 51.422125 | Q15: =IF(D15<2,"",F15-1.96*H15/SQRT(D15)) -> 50.908112 | R15: =IF(D15<2,"",F15+1.96*H15/SQRT(D15)) -> 51.116659 | S15: =IF(D15=0,"",AVERAGE(Obs_Ciclos!$R$5:$R$24)) -> 3.3830233 | T15: =IF(D15=0,"",SUM(Obs_Ciclos!$S$5:$S$24)) -> 0 | U15: =IF(D15=0,"",SUM(Obs_Ciclos!$T$5:$T$24)) -> 0 | V15: =IF(D15=0,"",SUM(Obs_Ciclos!$W$5:$W$24)) -> 0 | W15: =IF(D15=0,"",IFERROR(SUMIF(Obs_Ciclos!$W$5:$W$24,">0",Obs_Ciclos!$X$5:$X$24)/COUNTIF(Obs_Ciclos!$W$5:$W$24,">0"),0)) -> 0
A16: Obstáculos|O03|Estados (respostas + validação) | B16: Obstáculos | C16: O03E | D16: =COUNT(Obs_Ciclos!$Q$27:$Q$46) -> 20 | E16: =IF(D16=0,"",SUM(Obs_Ciclos!$U$27:$U$46)/D16) -> 0.95 | F16: =IF(D16=0,"",AVERAGE(Obs_Ciclos!$Q$27:$Q$46)) -> 46.828729 | G16: =IF(D16=0,"",MEDIAN(Obs_Ciclos!$Q$27:$Q$46)) -> 47.081256 | H16: =IF(D16<2,"",_xlfn.STDEV.S(Obs_Ciclos!$Q$27:$Q$46)) -> 2.8659411 | I16: =IF(OR(D16<2,F16=0),"",H16/F16) -> 0.061200489 | J16: =IF(D16=0,"",MIN(Obs_Ciclos!$Q$27:$Q$46)) -> 35.404106 | K16: =IF(D16=0,"",MAX(Obs_Ciclos!$Q$27:$Q$46)) -> 51.5289 | L16: =IF(D16=0,"",_xlfn.QUARTILE.INC(Obs_Ciclos!$Q$27:$Q$46,1)) -> 46.989756 | M16: =IF(D16=0,"",_xlfn.QUARTILE.INC(Obs_Ciclos!$Q$27:$Q$46,3)) -> 47.444831 | N16: =IF(D16=0,"",M16-L16) -> 0.4550755 | O16: =IF(D16=0,"",L16-1.5*N16) -> 46.307142 | P16: =IF(D16=0,"",M16+1.5*N16) -> 48.127444 | Q16: =IF(D16<2,"",F16-1.96*H16/SQRT(D16)) -> 45.572675 | R16: =IF(D16<2,"",F16+1.96*H16/SQRT(D16)) -> 48.084783 | S16: =IF(D16=0,"",AVERAGE(Obs_Ciclos!$R$27:$R$46)) -> 1.0818488 | T16: =IF(D16=0,"",SUM(Obs_Ciclos!$S$27:$S$46)) -> 0 | U16: =IF(D16=0,"",SUM(Obs_Ciclos!$T$27:$T$46)) -> 0 | V16: =IF(D16=0,"",SUM(Obs_Ciclos!$W$27:$W$46)) -> 1 | W16: =IF(D16=0,"",IFERROR(SUMIF(Obs_Ciclos!$W$27:$W$46,">0",Obs_Ciclos!$X$27:$X$46)/COUNTIF(Obs_Ciclos!$W$27:$W$46,">0"),0)) -> 14.342824
A17: Obstáculos|O13|Temporal (Sleep + Write/Read) | B17: Obstáculos | C17: O13 | D17: =COUNT(Obs_Ciclos!$AE$5:$AE$24) -> 20 | E17: =IF(D17=0,"",SUM(Obs_Ciclos!$AI$5:$AI$24)/D17) -> 1 | F17: =IF(D17=0,"",AVERAGE(Obs_Ciclos!$AE$5:$AE$24)) -> 47.753476 | G17: =IF(D17=0,"",MEDIAN(Obs_Ciclos!$AE$5:$AE$24)) -> 47.172206 | H17: =IF(D17<2,"",_xlfn.STDEV.S(Obs_Ciclos!$AE$5:$AE$24)) -> 2.4924664 | I17: =IF(OR(D17<2,F17=0),"",H17/F17) -> 0.05219445 | J17: =IF(D17=0,"",MIN(Obs_Ciclos!$AE$5:$AE$24)) -> 47.047639 | K17: =IF(D17=0,"",MAX(Obs_Ciclos!$AE$5:$AE$24)) -> 58.322647 | L17: =IF(D17=0,"",_xlfn.QUARTILE.INC(Obs_Ciclos!$AE$5:$AE$24,1)) -> 47.131399 | M17: =IF(D17=0,"",_xlfn.QUARTILE.INC(Obs_Ciclos!$AE$5:$AE$24,3)) -> 47.233413 | N17: =IF(D17=0,"",M17-L17) -> 0.1020145 | O17: =IF(D17=0,"",L17-1.5*N17) -> 46.978377 | P17: =IF(D17=0,"",M17+1.5*N17) -> 47.386435 | Q17: =IF(D17<2,"",F17-1.96*H17/SQRT(D17)) -> 46.661104 | R17: =IF(D17<2,"",F17+1.96*H17/SQRT(D17)) -> 48.845847 | S17: =IF(D17=0,"",AVERAGE(Obs_Ciclos!$AF$5:$AF$24)) -> 3.2444821 | T17: =IF(D17=0,"",SUM(Obs_Ciclos!$AG$5:$AG$24)) -> 0 | U17: =IF(D17=0,"",SUM(Obs_Ciclos!$AH$5:$AH$24)) -> 0 | V17: =IF(D17=0,"",SUM(Obs_Ciclos!$AK$5:$AK$24)) -> 0 | W17: =IF(D17=0,"",IFERROR(SUMIF(Obs_Ciclos!$AK$5:$AK$24,">0",Obs_Ciclos!$AL$5:$AL$24)/COUNTIF(Obs_Ciclos!$AK$5:$AK$24,">0"),0)) -> 0
A18: Obstáculos|O13|Estados (respostas + validação) | B18: Obstáculos | C18: O13E | D18: =COUNT(Obs_Ciclos!$AE$27:$AE$46) -> 20 | E18: =IF(D18=0,"",SUM(Obs_Ciclos!$AI$27:$AI$46)/D18) -> 1 | F18: =IF(D18=0,"",AVERAGE(Obs_Ciclos!$AE$27:$AE$46)) -> 46.603217 | G18: =IF(D18=0,"",MEDIAN(Obs_Ciclos!$AE$27:$AE$46)) -> 45.068642 | H18: =IF(D18<2,"",_xlfn.STDEV.S(Obs_Ciclos!$AE$27:$AE$46)) -> 3.0248676 | I18: =IF(OR(D18<2,F18=0),"",H18/F18) -> 0.064906842 | J18: =IF(D18=0,"",MIN(Obs_Ciclos!$AE$27:$AE$46)) -> 44.921168 | K18: =IF(D18=0,"",MAX(Obs_Ciclos!$AE$27:$AE$46)) -> 56.05236 | L18: =IF(D18=0,"",_xlfn.QUARTILE.INC(Obs_Ciclos!$AE$27:$AE$46,1)) -> 45.020916 | M18: =IF(D18=0,"",_xlfn.QUARTILE.INC(Obs_Ciclos!$AE$27:$AE$46,3)) -> 46.543615 | N18: =IF(D18=0,"",M18-L18) -> 1.5226998 | O18: =IF(D18=0,"",L18-1.5*N18) -> 42.736866 | P18: =IF(D18=0,"",M18+1.5*N18) -> 48.827665 | Q18: =IF(D18<2,"",F18-1.96*H18/SQRT(D18)) -> 45.27751 | R18: =IF(D18<2,"",F18+1.96*H18/SQRT(D18)) -> 47.928924 | S18: =IF(D18=0,"",AVERAGE(Obs_Ciclos!$AF$27:$AF$46)) -> 1.0506336 | T18: =IF(D18=0,"",SUM(Obs_Ciclos!$AG$27:$AG$46)) -> 0 | U18: =IF(D18=0,"",SUM(Obs_Ciclos!$AH$27:$AH$46)) -> 0 | V18: =IF(D18=0,"",SUM(Obs_Ciclos!$AK$27:$AK$46)) -> 0 | W18: =IF(D18=0,"",IFERROR(SUMIF(Obs_Ciclos!$AK$27:$AK$46,">0",Obs_Ciclos!$AL$27:$AL$46)/COUNTIF(Obs_Ciclos!$AK$27:$AK$46,">0"),0)) -> 0
A19: Obstáculos|O17|Temporal (Sleep + Write/Read) | B19: Obstáculos | C19: O17 | D19: =COUNT(Obs_Ciclos!$AS$5:$AS$24) -> 20 | E19: =IF(D19=0,"",SUM(Obs_Ciclos!$AW$5:$AW$24)/D19) -> 1 | F19: =IF(D19=0,"",AVERAGE(Obs_Ciclos!$AS$5:$AS$24)) -> 50.739034 | G19: =IF(D19=0,"",MEDIAN(Obs_Ciclos!$AS$5:$AS$24)) -> 48.948814 | H19: =IF(D19<2,"",_xlfn.STDEV.S(Obs_Ciclos!$AS$5:$AS$24)) -> 3.7074386 | I19: =IF(OR(D19<2,F19=0),"",H19/F19) -> 0.073068767 | J19: =IF(D19=0,"",MIN(Obs_Ciclos!$AS$5:$AS$24)) -> 47.24907 | K19: =IF(D19=0,"",MAX(Obs_Ciclos!$AS$5:$AS$24)) -> 60.471985 | L19: =IF(D19=0,"",_xlfn.QUARTILE.INC(Obs_Ciclos!$AS$5:$AS$24,1)) -> 48.835803 | M19: =IF(D19=0,"",_xlfn.QUARTILE.INC(Obs_Ciclos!$AS$5:$AS$24,3)) -> 52.723672 | N19: =IF(D19=0,"",M19-L19) -> 3.8878693 | O19: =IF(D19=0,"",L19-1.5*N19) -> 43.003999 | P19: =IF(D19=0,"",M19+1.5*N19) -> 58.555476 | Q19: =IF(D19<2,"",F19-1.96*H19/SQRT(D19)) -> 49.114177 | R19: =IF(D19<2,"",F19+1.96*H19/SQRT(D19)) -> 52.36389 | S19: =IF(D19=0,"",AVERAGE(Obs_Ciclos!$AT$5:$AT$24)) -> 3.1526356 | T19: =IF(D19=0,"",SUM(Obs_Ciclos!$AU$5:$AU$24)) -> 0 | U19: =IF(D19=0,"",SUM(Obs_Ciclos!$AV$5:$AV$24)) -> 0 | V19: =IF(D19=0,"",SUM(Obs_Ciclos!$AY$5:$AY$24)) -> 0 | W19: =IF(D19=0,"",IFERROR(SUMIF(Obs_Ciclos!$AY$5:$AY$24,">0",Obs_Ciclos!$AZ$5:$AZ$24)/COUNTIF(Obs_Ciclos!$AY$5:$AY$24,">0"),0)) -> 0
A20: Obstáculos|O17|Estados (respostas + validação) | B20: Obstáculos | C20: O17E | D20: =COUNT(Obs_Ciclos!$AS$27:$AS$46) -> 20 | E20: =IF(D20=0,"",SUM(Obs_Ciclos!$AW$27:$AW$46)/D20) -> 1 | F20: =IF(D20=0,"",AVERAGE(Obs_Ciclos!$AS$27:$AS$46)) -> 46.863415 | G20: =IF(D20=0,"",MEDIAN(Obs_Ciclos!$AS$27:$AS$46)) -> 46.73829 | H20: =IF(D20<2,"",_xlfn.STDEV.S(Obs_Ciclos!$AS$27:$AS$46)) -> 2.4473736 | I20: =IF(OR(D20<2,F20=0),"",H20/F20) -> 0.052223544 | J20: =IF(D20=0,"",MIN(Obs_Ciclos!$AS$27:$AS$46)) -> 44.953144 | K20: =IF(D20=0,"",MAX(Obs_Ciclos!$AS$27:$AS$46)) -> 55.756136 | L20: =IF(D20=0,"",_xlfn.QUARTILE.INC(Obs_Ciclos!$AS$27:$AS$46,1)) -> 45.113622 | M20: =IF(D20=0,"",_xlfn.QUARTILE.INC(Obs_Ciclos!$AS$27:$AS$46,3)) -> 47.520684 | N20: =IF(D20=0,"",M20-L20) -> 2.4070618 | O20: =IF(D20=0,"",L20-1.5*N20) -> 41.50303 | P20: =IF(D20=0,"",M20+1.5*N20) -> 51.131277 | Q20: =IF(D20<2,"",F20-1.96*H20/SQRT(D20)) -> 45.790806 | R20: =IF(D20<2,"",F20+1.96*H20/SQRT(D20)) -> 47.936024 | S20: =IF(D20=0,"",AVERAGE(Obs_Ciclos!$AT$27:$AT$46)) -> 1.0603288 | T20: =IF(D20=0,"",SUM(Obs_Ciclos!$AU$27:$AU$46)) -> 0 | U20: =IF(D20=0,"",SUM(Obs_Ciclos!$AV$27:$AV$46)) -> 0 | V20: =IF(D20=0,"",SUM(Obs_Ciclos!$AY$27:$AY$46)) -> 0 | W20: =IF(D20=0,"",IFERROR(SUMIF(Obs_Ciclos!$AY$27:$AY$46,">0",Obs_Ciclos!$AZ$27:$AZ$46)/COUNTIF(Obs_Ciclos!$AY$27:$AY$46,">0"),0)) -> 0
A23: Comparação emparelhada — Estados vs. Temporal
A24: Conjunto | B24: Cenário | C24: Pares válidos | D24: Δ média Estados−Temporal (s) | E24: Melhoria dos estados (%) | F24: p-value T.TEST | G24: Interpretação | H24: Decisão
A25: Repetibilidade | B25: R01 | C25: =MIN(COUNT(Rep_Ciclos!C5:C24),COUNT(Rep_Ciclos!C27:C46)) -> 20 | D25: =IF(C25=0,"",AVERAGE(Rep_Ciclos!C27:C46)-AVERAGE(Rep_Ciclos!C5:C24)) -> -3.6947387 | E25: =IF(C25=0,"",(AVERAGE(Rep_Ciclos!C5:C24)-AVERAGE(Rep_Ciclos!C27:C46))/AVERAGE(Rep_Ciclos!C5:C24)) -> 0.072945333 | F25: =IF(AND(C25>=2,COUNT(Rep_Ciclos!C5:C24)=COUNT(Rep_Ciclos!C27:C46)),TTEST(Rep_Ciclos!C5:C24,Rep_Ciclos!C27:C46,2,1),"") -> 0.018349303 | G25: =IF(F25="","Aguardar pares",IF(F25<0.05,"Diferença significativa","Sem evidência de diferença")) -> Diferença significativa | H25: =IF(C25<20,"Aumentar amostra",IF(F25<0.05,"Rejeitar H0","Não rejeitar H0")) -> Rejeitar H0
A26: Repetibilidade | B26: R04 | C26: =MIN(COUNT(Rep_Ciclos!R5:R24),COUNT(Rep_Ciclos!R27:R46)) -> 20 | D26: =IF(C26=0,"",AVERAGE(Rep_Ciclos!R27:R46)-AVERAGE(Rep_Ciclos!R5:R24)) -> -2.45865 | E26: =IF(C26=0,"",(AVERAGE(Rep_Ciclos!R5:R24)-AVERAGE(Rep_Ciclos!R27:R46))/AVERAGE(Rep_Ciclos!R5:R24)) -> 0.053133424 | F26: =IF(AND(C26>=2,COUNT(Rep_Ciclos!R5:R24)=COUNT(Rep_Ciclos!R27:R46)),TTEST(Rep_Ciclos!R5:R24,Rep_Ciclos!R27:R46,2,1),"") -> 0.00015184243 | G26: =IF(F26="","Aguardar pares",IF(F26<0.05,"Diferença significativa","Sem evidência de diferença")) -> Diferença significativa | H26: =IF(C26<20,"Aumentar amostra",IF(F26<0.05,"Rejeitar H0","Não rejeitar H0")) -> Rejeitar H0
A27: Repetibilidade | B27: R08 | C27: =MIN(COUNT(Rep_Ciclos!AG5:AG24),COUNT(Rep_Ciclos!AG27:AG46)) -> 20 | D27: =IF(C27=0,"",AVERAGE(Rep_Ciclos!AG27:AG46)-AVERAGE(Rep_Ciclos!AG5:AG24)) -> -4.3712802 | E27: =IF(C27=0,"",(AVERAGE(Rep_Ciclos!AG5:AG24)-AVERAGE(Rep_Ciclos!AG27:AG46))/AVERAGE(Rep_Ciclos!AG5:AG24)) -> 0.092242924 | F27: =IF(AND(C27>=2,COUNT(Rep_Ciclos!AG5:AG24)=COUNT(Rep_Ciclos!AG27:AG46)),TTEST(Rep_Ciclos!AG5:AG24,Rep_Ciclos!AG27:AG46,2,1),"") -> 0.20540175 | G27: =IF(F27="","Aguardar pares",IF(F27<0.05,"Diferença significativa","Sem evidência de diferença")) -> Sem evidência de diferença | H27: =IF(C27<20,"Aumentar amostra",IF(F27<0.05,"Rejeitar H0","Não rejeitar H0")) -> Não rejeitar H0
A28: Repetibilidade | B28: R10 | C28: =MIN(COUNT(Rep_Ciclos!AV5:AV24),COUNT(Rep_Ciclos!AV27:AV46)) -> 20 | D28: =IF(C28=0,"",AVERAGE(Rep_Ciclos!AV27:AV46)-AVERAGE(Rep_Ciclos!AV5:AV24)) -> -0.8678885 | E28: =IF(C28=0,"",(AVERAGE(Rep_Ciclos!AV5:AV24)-AVERAGE(Rep_Ciclos!AV27:AV46))/AVERAGE(Rep_Ciclos!AV5:AV24)) -> 0.018192683 | F28: =IF(AND(C28>=2,COUNT(Rep_Ciclos!AV5:AV24)=COUNT(Rep_Ciclos!AV27:AV46)),TTEST(Rep_Ciclos!AV5:AV24,Rep_Ciclos!AV27:AV46,2,1),"") -> 0.78713428 | G28: =IF(F28="","Aguardar pares",IF(F28<0.05,"Diferença significativa","Sem evidência de diferença")) -> Sem evidência de diferença | H28: =IF(C28<20,"Aumentar amostra",IF(F28<0.05,"Rejeitar H0","Não rejeitar H0")) -> Não rejeitar H0
A29: Obstáculos | B29: O07 | C29: =MIN(COUNT(Obs_Ciclos!C5:C24),COUNT(Obs_Ciclos!C27:C46)) -> 20 | D29: =IF(C29=0,"",AVERAGE(Obs_Ciclos!C27:C46)-AVERAGE(Obs_Ciclos!C5:C24)) -> -3.1460187 | E29: =IF(C29=0,"",(AVERAGE(Obs_Ciclos!C5:C24)-AVERAGE(Obs_Ciclos!C27:C46))/AVERAGE(Obs_Ciclos!C5:C24)) -> 0.061821229 | F29: =IF(AND(C29>=2,COUNT(Obs_Ciclos!C5:C24)=COUNT(Obs_Ciclos!C27:C46)),TTEST(Obs_Ciclos!C5:C24,Obs_Ciclos!C27:C46,2,1),"") -> 0.00038430951 | G29: =IF(F29="","Aguardar pares",IF(F29<0.05,"Diferença significativa","Sem evidência de diferença")) -> Diferença significativa | H29: =IF(C29<20,"Aumentar amostra",IF(F29<0.05,"Rejeitar H0","Não rejeitar H0")) -> Rejeitar H0
A30: Obstáculos | B30: O03 | C30: =MIN(COUNT(Obs_Ciclos!Q5:Q24),COUNT(Obs_Ciclos!Q27:Q46)) -> 20 | D30: =IF(C30=0,"",AVERAGE(Obs_Ciclos!Q27:Q46)-AVERAGE(Obs_Ciclos!Q5:Q24)) -> -4.1836563 | E30: =IF(C30=0,"",(AVERAGE(Obs_Ciclos!Q5:Q24)-AVERAGE(Obs_Ciclos!Q27:Q46))/AVERAGE(Obs_Ciclos!Q5:Q24)) -> 0.082012559 | F30: =IF(AND(C30>=2,COUNT(Obs_Ciclos!Q5:Q24)=COUNT(Obs_Ciclos!Q27:Q46)),TTEST(Obs_Ciclos!Q5:Q24,Obs_Ciclos!Q27:Q46,2,1),"") -> 2.8120825e-06 | G30: =IF(F30="","Aguardar pares",IF(F30<0.05,"Diferença significativa","Sem evidência de diferença")) -> Diferença significativa | H30: =IF(C30<20,"Aumentar amostra",IF(F30<0.05,"Rejeitar H0","Não rejeitar H0")) -> Rejeitar H0
A31: Obstáculos | B31: O13 | C31: =MIN(COUNT(Obs_Ciclos!AE5:AE24),COUNT(Obs_Ciclos!AE27:AE46)) -> 20 | D31: =IF(C31=0,"",AVERAGE(Obs_Ciclos!AE27:AE46)-AVERAGE(Obs_Ciclos!AE5:AE24)) -> -1.1502586 | E31: =IF(C31=0,"",(AVERAGE(Obs_Ciclos!AE5:AE24)-AVERAGE(Obs_Ciclos!AE27:AE46))/AVERAGE(Obs_Ciclos!AE5:AE24)) -> 0.024087432 | F31: =IF(AND(C31>=2,COUNT(Obs_Ciclos!AE5:AE24)=COUNT(Obs_Ciclos!AE27:AE46)),TTEST(Obs_Ciclos!AE5:AE24,Obs_Ciclos!AE27:AE46,2,1),"") -> 0.2278428 | G31: =IF(F31="","Aguardar pares",IF(F31<0.05,"Diferença significativa","Sem evidência de diferença")) -> Sem evidência de diferença | H31: =IF(C31<20,"Aumentar amostra",IF(F31<0.05,"Rejeitar H0","Não rejeitar H0")) -> Não rejeitar H0
A32: Obstáculos | B32: O17 | C32: =MIN(COUNT(Obs_Ciclos!AS5:AS24),COUNT(Obs_Ciclos!AS27:AS46)) -> 20 | D32: =IF(C32=0,"",AVERAGE(Obs_Ciclos!AS27:AS46)-AVERAGE(Obs_Ciclos!AS5:AS24)) -> -3.875619 | E32: =IF(C32=0,"",(AVERAGE(Obs_Ciclos!AS5:AS24)-AVERAGE(Obs_Ciclos!AS27:AS46))/AVERAGE(Obs_Ciclos!AS5:AS24)) -> 0.076383383 | F32: =IF(AND(C32>=2,COUNT(Obs_Ciclos!AS5:AS24)=COUNT(Obs_Ciclos!AS27:AS46)),TTEST(Obs_Ciclos!AS5:AS24,Obs_Ciclos!AS27:AS46,2,1),"") -> 0.0012872069 | G32: =IF(F32="","Aguardar pares",IF(F32<0.05,"Diferença significativa","Sem evidência de diferença")) -> Diferença significativa | H32: =IF(C32<20,"Aumentar amostra",IF(F32<0.05,"Rejeitar H0","Não rejeitar H0")) -> Rejeitar H0

Sheet Rep_Ciclos
A1: Repetibilidade — métricas por ciclo
A3: TEMPORAL | P3: TEMPORAL | AE3: TEMPORAL | AT3: TEMPORAL
A4: ID | B4: Repetição | C4: Tempo total (s) | D4: Espera improdutiva (s) | E4: Nº timeouts | F4: Nº comandos prematuros | G4: Taxa sucesso ciclo (0/1) | H4: Resultado | I4: Nº falhas | J4: Tempo recuperação (s) | K4: Nº comandos | L4: Resultado final | M4: Outlier tempo? | N4: Observações | P4: ID | Q4: Repetição | R4: Tempo total (s) | S4: Espera improdutiva (s) | T4: Nº timeouts | U4: Nº comandos prematuros | V4: Taxa sucesso ciclo (0/1) | W4: Resultado | X4: Nº falhas | Y4: Tempo recuperação (s) | Z4: Nº comandos | AA4: Resultado final | AB4: Outlier tempo? | AC4: Observações | AE4: ID | AF4: Repetição | AG4: Tempo total (s) | AH4: Espera improdutiva (s) | AI4: Nº timeouts | AJ4: Nº comandos prematuros | AK4: Taxa sucesso ciclo (0/1) | AL4: Resultado | AM4: Nº falhas | AN4: Tempo recuperação (s) | AO4: Nº comandos | AP4: Resultado final | AQ4: Outlier tempo? | AR4: Observações | AT4: ID | AU4: Repetição | AV4: Tempo total (s) | AW4: Espera improdutiva (s) | AX4: Nº timeouts | AY4: Nº comandos prematuros | AZ4: Taxa sucesso ciclo (0/1) | BA4: Resultado | BB4: Nº falhas | BC4: Tempo recuperação (s) | BD4: Nº comandos | BE4: Resultado final | BF4: Outlier tempo? | BG4: Observações
A5: R01 | B5: 1 | C5: 53.251825 | D5: 3.176158 | E5: 0 | F5: 0 | G5: 1 | H5: Sucesso | I5: 0 | J5: 0 | K5: 8 | L5: OK FINISH_DONE | M5: =IF(C5="","",IF(OR(C5<Resumo!$O$5,C5>Resumo!$P$5),"Sim","Não")) -> Não | P5: R04 | Q5: 1 | R5: 50.219495 | S5: 3.201638 | T5: 0 | U5: 0 | V5: 1 | W5: Sucesso | X5: 0 | Y5: 0 | Z5: 8 | AA5: OK FINISH_DONE | AB5: =IF(R5="","",IF(OR(R5<Resumo!$O$7,R5>Resumo!$P$7),"Sim","Não")) -> Sim | AE5: R08 | AF5: 1 | AG5: 48.394806 | AH5: 3.22338 | AI5: 0 | AJ5: 0 | AK5: 1 | AL5: Sucesso | AM5: 0 | AN5: 0 | AO5: 8 | AP5: OK FINISH_DONE | AQ5: =IF(AG5="","",IF(OR(AG5<Resumo!$O$9,AG5>Resumo!$P$9),"Sim","Não")) -> Não | AT5: R10 | AU5: 1 | AV5: 50.322402 | AW5: 3.442074 | AX5: 0 | AY5: 0 | AZ5: 1 | BA5: Sucesso | BB5: 0 | BC5: 0 | BD5: 8 | BE5: OK FINISH_DONE | BF5: =IF(AV5="","",IF(OR(AV5<Resumo!$O$11,AV5>Resumo!$P$11),"Sim","Não")) -> Não
A6: R01 | B6: 2 | C6: 54.482239 | D6: 3.21419 | E6: 0 | F6: 0 | G6: 1 | H6: Sucesso | I6: 0 | J6: 0 | K6: 8 | L6: OK FINISH_DONE | M6: =IF(C6="","",IF(OR(C6<Resumo!$O$5,C6>Resumo!$P$5),"Sim","Não")) -> Não | P6: R04 | Q6: 2 | R6: 50.164877 | S6: 3.327182 | T6: 0 | U6: 0 | V6: 1 | W6: Sucesso | X6: 0 | Y6: 0 | Z6: 8 | AA6: OK FINISH_DONE | AB6: =IF(R6="","",IF(OR(R6<Resumo!$O$7,R6>Resumo!$P$7),"Sim","Não")) -> Sim | AE6: R08 | AF6: 2 | AG6: 52.309505 | AH6: 3.205448 | AI6: 0 | AJ6: 0 | AK6: 1 | AL6: Sucesso | AM6: 0 | AN6: 0 | AO6: 8 | AP6: OK FINISH_DONE | AQ6: =IF(AG6="","",IF(OR(AG6<Resumo!$O$9,AG6>Resumo!$P$9),"Sim","Não")) -> Não | AT6: R10 | AU6: 2 | AV6: 51.231883 | AW6: 3.218508 | AX6: 0 | AY6: 0 | AZ6: 1 | BA6: Sucesso | BB6: 0 | BC6: 0 | BD6: 8 | BE6: OK FINISH_DONE | BF6: =IF(AV6="","",IF(OR(AV6<Resumo!$O$11,AV6>Resumo!$P$11),"Sim","Não")) -> Não
A7: R01 | B7: 3 | C7: 50.47051 | D7: 3.283025 | E7: 0 | F7: 0 | G7: 1 | H7: Sucesso | I7: 0 | J7: 0 | K7: 8 | L7: OK FINISH_DONE | M7: =IF(C7="","",IF(OR(C7<Resumo!$O$5,C7>Resumo!$P$5),"Sim","Não")) -> Não | P7: R04 | Q7: 3 | R7: 46.285962 | S7: 3.108938 | T7: 0 | U7: 0 | V7: 1 | W7: Sucesso | X7: 0 | Y7: 0 | Z7: 8 | AA7: OK FINISH_DONE | AB7: =IF(R7="","",IF(OR(R7<Resumo!$O$7,R7>Resumo!$P$7),"Sim","Não")) -> Não | AE7: R08 | AF7: 3 | AG7: 45.473462 | AH7: 3.277731 | AI7: 0 | AJ7: 0 | AK7: 1 | AL7: Sucesso | AM7: 0 | AN7: 0 | AO7: 8 | AP7: OK FINISH_DONE | AQ7: =IF(AG7="","",IF(OR(AG7<Resumo!$O$9,AG7>Resumo!$P$9),"Sim","Não")) -> Não | AT7: R10 | AU7: 3 | AV7: 56.109755 | AW7: 3.291425 | AX7: 0 | AY7: 0 | AZ7: 1 | BA7: Sucesso | BB7: 0 | BC7: 0 | BD7: 8 | BE7: OK FINISH_DONE | BF7: =IF(AV7="","",IF(OR(AV7<Resumo!$O$11,AV7>Resumo!$P$11),"Sim","Não")) -> Não
A8: R01 | B8: 4 | C8: 52.574545 | D8: 3.188045 | E8: 0 | F8: 0 | G8: 1 | H8: Sucesso | I8: 0 | J8: 0 | K8: 8 | L8: OK FINISH_DONE | M8: =IF(C8="","",IF(OR(C8<Resumo!$O$5,C8>Resumo!$P$5),"Sim","Não")) -> Não | P8: R04 | Q8: 4 | R8: 46.446044 | S8: 3.228909 | T8: 0 | U8: 0 | V8: 1 | W8: Sucesso | X8: 0 | Y8: 0 | Z8: 8 | AA8: OK FINISH_DONE | AB8: =IF(R8="","",IF(OR(R8<Resumo!$O$7,R8>Resumo!$P$7),"Sim","Não")) -> Não | AE8: R08 | AF8: 4 | AG8: 45.252817 | AH8: 3.198642 | AI8: 0 | AJ8: 0 | AK8: 1 | AL8: Sucesso | AM8: 0 | AN8: 0 | AO8: 8 | AP8: OK FINISH_DONE | AQ8: =IF(AG8="","",IF(OR(AG8<Resumo!$O$9,AG8>Resumo!$P$9),"Sim","Não")) -> Não | AT8: R10 | AU8: 4 | AV8: 50.19097 | AW8: 3.325774 | AX8: 0 | AY8: 0 | AZ8: 1 | BA8: Sucesso | BB8: 0 | BC8: 0 | BD8: 8 | BE8: OK FINISH_DONE | BF8: =IF(AV8="","",IF(OR(AV8<Resumo!$O$11,AV8>Resumo!$P$11),"Sim","Não")) -> Não
A9: R01 | B9: 5 | C9: 49.497041 | D9: 3.260193 | E9: 0 | F9: 0 | G9: 1 | H9: Sucesso | I9: 0 | J9: 0 | K9: 8 | L9: OK FINISH_DONE | M9: =IF(C9="","",IF(OR(C9<Resumo!$O$5,C9>Resumo!$P$5),"Sim","Não")) -> Não | P9: R04 | Q9: 5 | R9: 46.752469 | S9: 3.211797 | T9: 0 | U9: 0 | V9: 1 | W9: Sucesso | X9: 0 | Y9: 0 | Z9: 8 | AA9: OK FINISH_DONE | AB9: =IF(R9="","",IF(OR(R9<Resumo!$O$7,R9>Resumo!$P$7),"Sim","Não")) -> Não | AE9: R08 | AF9: 5 | AG9: 28.181661 | AH9: 3.11951 | AI9: 0 | AJ9: 0 | AK9: 0 | AL9: Falha | AM9: 1 | AN9: 12.6 | AO9: 8 | AP9: OK FINISH_DONE | AQ9: =IF(AG9="","",IF(OR(AG9<Resumo!$O$9,AG9>Resumo!$P$9),"Sim","Não")) -> Sim | AR9: Falhou no primeiro move | AT9: R10 | AU9: 5 | AV9: 52.132323 | AW9: 3.358261 | AX9: 0 | AY9: 0 | AZ9: 1 | BA9: Sucesso | BB9: 0 | BC9: 0 | BD9: 8 | BE9: OK FINISH_DONE | BF9: =IF(AV9="","",IF(OR(AV9<Resumo!$O$11,AV9>Resumo!$P$11),"Sim","Não")) -> Não
A10: R01 | B10: 6 | C10: 49.449316 | D10: 3.222628 | E10: 0 | F10: 0 | G10: 1 | H10: Sucesso | I10: 0 | J10: 0 | K10: 8 | L10: OK FINISH_DONE | M10: =IF(C10="","",IF(OR(C10<Resumo!$O$5,C10>Resumo!$P$5),"Sim","Não")) -> Não | P10: R04 | Q10: 6 | R10: 50.397911 | S10: 3.251305 | T10: 0 | U10: 0 | V10: 1 | W10: Sucesso | X10: 0 | Y10: 0 | Z10: 8 | AA10: OK FINISH_DONE | AB10: =IF(R10="","",IF(OR(R10<Resumo!$O$7,R10>Resumo!$P$7),"Sim","Não")) -> Sim | AE10: R08 | AF10: 6 | AG10: 45.230344 | AH10: 3.198505 | AI10: 0 | AJ10: 0 | AK10: 1 | AL10: Sucesso | AM10: 0 | AN10: 0 | AO10: 8 | AP10: OK FINISH_DONE | AQ10: =IF(AG10="","",IF(OR(AG10<Resumo!$O$9,AG10>Resumo!$P$9),"Sim","Não")) -> Não | AT10: R10 | AU10: 6 | AV10: 28.575338 | AW10: 3.200829 | AX10: 0 | AY10: 0 | AZ10: 0 | BA10: Falha | BB10: 1 | BC10: 11.8 | BD10: 8 | BE10: OK FINISH_DONE | BF10: =IF(AV10="","",IF(OR(AV10<Resumo!$O$11,AV10>Resumo!$P$11),"Sim","Não")) -> Sim | BG10: Falhou no primeiro move
A11: R01 | B11: 7 | C11: 45.471912 | D11: 3.226259 | E11: 0 | F11: 0 | G11: 1 | H11: Sucesso | I11: 0 | J11: 0 | K11: 8 | L11: OK FINISH_DONE | M11: =IF(C11="","",IF(OR(C11<Resumo!$O$5,C11>Resumo!$P$5),"Sim","Não")) -> Não | P11: R04 | Q11: 7 | R11: 47.55613 | S11: 3.199229 | T11: 0 | U11: 0 | V11: 1 | W11: Sucesso | X11: 0 | Y11: 0 | Z11: 8 | AA11: OK FINISH_DONE | AB11: =IF(R11="","",IF(OR(R11<Resumo!$O$7,R11>Resumo!$P$7),"Sim","Não")) -> Não | AE11: R08 | AF11: 7 | AG11: 48.137439 | AH11: 3.266504 | AI11: 0 | AJ11: 0 | AK11: 1 | AL11: Sucesso | AM11: 0 | AN11: 0 | AO11: 8 | AP11: OK FINISH_DONE | AQ11: =IF(AG11="","",IF(OR(AG11<Resumo!$O$9,AG11>Resumo!$P$9),"Sim","Não")) -> Não | AT11: R10 | AU11: 7 | AV11: 54.488682 | AW11: 3.364713 | AX11: 0 | AY11: 0 | AZ11: 1 | BA11: Sucesso | BB11: 0 | BC11: 0 | BD11: 8 | BE11: OK FINISH_DONE | BF11: =IF(AV11="","",IF(OR(AV11<Resumo!$O$11,AV11>Resumo!$P$11),"Sim","Não")) -> Não
A12: R01 | B12: 8 | C12: 52.219331 | D12: 3.245766 | E12: 0 | F12: 0 | G12: 1 | H12: Sucesso | I12: 0 | J12: 0 | K12: 8 | L12: OK FINISH_DONE | M12: =IF(C12="","",IF(OR(C12<Resumo!$O$5,C12>Resumo!$P$5),"Sim","Não")) -> Não | P12: R04 | Q12: 8 | R12: 44.995549 | S12: 3.255844 | T12: 0 | U12: 0 | V12: 1 | W12: Sucesso | X12: 0 | Y12: 0 | Z12: 8 | AA12: OK FINISH_DONE | AB12: =IF(R12="","",IF(OR(R12<Resumo!$O$7,R12>Resumo!$P$7),"Sim","Não")) -> Não | AE12: R08 | AF12: 8 | AG12: 47.412878 | AH12: 3.210309 | AI12: 0 | AJ12: 0 | AK12: 1 | AL12: Sucesso | AM12: 0 | AN12: 0 | AO12: 8 | AP12: OK FINISH_DONE | AQ12: =IF(AG12="","",IF(OR(AG12<Resumo!$O$9,AG12>Resumo!$P$9),"Sim","Não")) -> Não | AT12: R10 | AU12: 8 | AV12: 46.490771 | AW12: 3.262763 | AX12: 0 | AY12: 0 | AZ12: 1 | BA12: Sucesso | BB12: 0 | BC12: 0 | BD12: 8 | BE12: OK FINISH_DONE | BF12: =IF(AV12="","",IF(OR(AV12<Resumo!$O$11,AV12>Resumo!$P$11),"Sim","Não")) -> Não
A13: R01 | B13: 9 | C13: 49.492879 | D13: 3.077812 | E13: 0 | F13: 0 | G13: 1 | H13: Sucesso | I13: 0 | J13: 0 | K13: 8 | L13: OK FINISH_DONE | M13: =IF(C13="","",IF(OR(C13<Resumo!$O$5,C13>Resumo!$P$5),"Sim","Não")) -> Não | P13: R04 | Q13: 9 | R13: 45.070175 | S13: 3.312335 | T13: 0 | U13: 0 | V13: 1 | W13: Sucesso | X13: 0 | Y13: 0 | Z13: 8 | AA13: OK FINISH_DONE | AB13: =IF(R13="","",IF(OR(R13<Resumo!$O$7,R13>Resumo!$P$7),"Sim","Não")) -> Não | AE13: R08 | AF13: 9 | AG13: 50.786848 | AH13: 3.213018 | AI13: 0 | AJ13: 0 | AK13: 1 | AL13: Sucesso | AM13: 0 | AN13: 0 | AO13: 8 | AP13: OK FINISH_DONE | AQ13: =IF(AG13="","",IF(OR(AG13<Resumo!$O$9,AG13>Resumo!$P$9),"Sim","Não")) -> Não | AT13: R10 | AU13: 9 | AV13: 30.238156 | AW13: 3.352943 | AX13: 0 | AY13: 0 | AZ13: 0 | BA13: Falha | BB13: 1 | BC13: 13.2 | BD13: 8 | BE13: OK FINISH_DONE | BF13: =IF(AV13="","",IF(OR(AV13<Resumo!$O$11,AV13>Resumo!$P$11),"Sim","Não")) -> Sim
A14: R01 | B14: 10 | C14: 48.123761 | D14: 3.196804 | E14: 0 | F14: 0 | G14: 1 | H14: Sucesso | I14: 0 | J14: 0 | K14: 8 | L14: OK FINISH_DONE | M14: =IF(C14="","",IF(OR(C14<Resumo!$O$5,C14>Resumo!$P$5),"Sim","Não")) -> Não | P14: R04 | Q14: 10 | R14: 45.011853 | S14: 3.295133 | T14: 0 | U14: 0 | V14: 1 | W14: Sucesso | X14: 0 | Y14: 0 | Z14: 8 | AA14: OK FINISH_DONE | AB14: =IF(R14="","",IF(OR(R14<Resumo!$O$7,R14>Resumo!$P$7),"Sim","Não")) -> Não | AE14: R08 | AF14: 10 | AG14: 48.153635 | AH14: 3.247537 | AI14: 0 | AJ14: 0 | AK14: 1 | AL14: Sucesso | AM14: 0 | AN14: 0 | AO14: 8 | AP14: OK FINISH_DONE | AQ14: =IF(AG14="","",IF(OR(AG14<Resumo!$O$9,AG14>Resumo!$P$9),"Sim","Não")) -> Não | AT14: R10 | AU14: 10 | AV14: 49.650391 | AW14: 3.396325 | AX14: 0 | AY14: 0 | AZ14: 1 | BA14: Sucesso | BB14: 0 | BC14: 0 | BD14: 8 | BE14: OK FINISH_DONE | BF14: =IF(AV14="","",IF(OR(AV14<Resumo!$O$11,AV14>Resumo!$P$11),"Sim","Não")) -> Não
A15: R01 | B15: 11 | C15: 48.266391 | D15: 3.22789 | E15: 0 | F15: 0 | G15: 1 | H15: Sucesso | I15: 0 | J15: 0 | K15: 8 | L15: OK FINISH_DONE | M15: =IF(C15="","",IF(OR(C15<Resumo!$O$5,C15>Resumo!$P$5),"Sim","Não")) -> Não | P15: R04 | Q15: 11 | R15: 44.945807 | S15: 3.225061 | T15: 0 | U15: 0 | V15: 1 | W15: Sucesso | X15: 0 | Y15: 0 | Z15: 8 | AA15: OK FINISH_DONE | AB15: =IF(R15="","",IF(OR(R15<Resumo!$O$7,R15>Resumo!$P$7),"Sim","Não")) -> Não | AE15: R08 | AF15: 11 | AG15: 52.341899 | AH15: 3.22153 | AI15: 0 | AJ15: 0 | AK15: 1 | AL15: Sucesso | AM15: 0 | AN15: 0 | AO15: 8 | AP15: OK FINISH_DONE | AQ15: =IF(AG15="","",IF(OR(AG15<Resumo!$O$9,AG15>Resumo!$P$9),"Sim","Não")) -> Não | AT15: R10 | AU15: 11 | AV15: 46.493053 | AW15: 3.392623 | AX15: 0 | AY15: 0 | AZ15: 1 | BA15: Sucesso | BB15: 0 | BC15: 0 | BD15: 8 | BE15: OK FINISH_DONE | BF15: =IF(AV15="","",IF(OR(AV15<Resumo!$O$11,AV15>Resumo!$P$11),"Sim","Não")) -> Não
A16: R01 | B16: 12 | C16: 45.297633 | D16: 3.165251 | E16: 0 | F16: 0 | G16: 1 | H16: Sucesso | I16: 0 | J16: 0 | K16: 8 | L16: OK FINISH_DONE | M16: =IF(C16="","",IF(OR(C16<Resumo!$O$5,C16>Resumo!$P$5),"Sim","Não")) -> Não | P16: R04 | Q16: 12 | R16: 46.232729 | S16: 3.187943 | T16: 0 | U16: 0 | V16: 1 | W16: Sucesso | X16: 0 | Y16: 0 | Z16: 8 | AA16: OK FINISH_DONE | AB16: =IF(R16="","",IF(OR(R16<Resumo!$O$7,R16>Resumo!$P$7),"Sim","Não")) -> Não | AE16: R08 | AF16: 12 | AG16: 49.313694 | AH16: 3.212681 | AI16: 0 | AJ16: 0 | AK16: 1 | AL16: Sucesso | AM16: 0 | AN16: 0 | AO16: 8 | AP16: OK FINISH_DONE | AQ16: =IF(AG16="","",IF(OR(AG16<Resumo!$O$9,AG16>Resumo!$P$9),"Sim","Não")) -> Não | AT16: R10 | AU16: 12 | AV16: 50.227924 | AW16: 3.282312 | AX16: 0 | AY16: 0 | AZ16: 1 | BA16: Sucesso | BB16: 0 | BC16: 0 | BD16: 8 | BE16: OK FINISH_DONE | BF16: =IF(AV16="","",IF(OR(AV16<Resumo!$O$11,AV16>Resumo!$P$11),"Sim","Não")) -> Não
A17: R01 | B17: 13 | C17: 54.362179 | D17: 3.265225 | E17: 0 | F17: 0 | G17: 1 | H17: Sucesso | I17: 0 | J17: 0 | K17: 8 | L17: OK FINISH_DONE | M17: =IF(C17="","",IF(OR(C17<Resumo!$O$5,C17>Resumo!$P$5),"Sim","Não")) -> Não | P17: R04 | Q17: 13 | R17: 46.792262 | S17: 3.282927 | T17: 0 | U17: 0 | V17: 1 | W17: Sucesso | X17: 0 | Y17: 0 | Z17: 8 | AA17: OK FINISH_DONE | AB17: =IF(R17="","",IF(OR(R17<Resumo!$O$7,R17>Resumo!$P$7),"Sim","Não")) -> Não | AE17: R08 | AF17: 13 | AG17: 46.748846 | AH17: 3.207834 | AI17: 0 | AJ17: 0 | AK17: 1 | AL17: Sucesso | AM17: 0 | AN17: 0 | AO17: 8 | AP17: OK FINISH_DONE | AQ17: =IF(AG17="","",IF(OR(AG17<Resumo!$O$9,AG17>Resumo!$P$9),"Sim","Não")) -> Não | AT17: R10 | AU17: 13 | AV17: 51.300856 | AW17: 3.345214 | AX17: 0 | AY17: 0 | AZ17: 1 | BA17: Sucesso | BB17: 0 | BC17: 0 | BD17: 8 | BE17: OK FINISH_DONE | BF17: =IF(AV17="","",IF(OR(AV17<Resumo!$O$11,AV17>Resumo!$P$11),"Sim","Não")) -> Não
A18: R01 | B18: 14 | C18: 48.153807 | D18: 3.205528 | E18: 0 | F18: 0 | G18: 1 | H18: Sucesso | I18: 0 | J18: 0 | K18: 8 | L18: OK FINISH_DONE | M18: =IF(C18="","",IF(OR(C18<Resumo!$O$5,C18>Resumo!$P$5),"Sim","Não")) -> Não | P18: R04 | Q18: 14 | R18: 44.793365 | S18: 3.123397 | T18: 0 | U18: 0 | V18: 1 | W18: Sucesso | X18: 0 | Y18: 0 | Z18: 8 | AA18: OK FINISH_DONE | AB18: =IF(R18="","",IF(OR(R18<Resumo!$O$7,R18>Resumo!$P$7),"Sim","Não")) -> Não | AE18: R08 | AF18: 14 | AG18: 45.29559 | AH18: 3.270884 | AI18: 0 | AJ18: 0 | AK18: 1 | AL18: Sucesso | AM18: 0 | AN18: 0 | AO18: 8 | AP18: OK FINISH_DONE | AQ18: =IF(AG18="","",IF(OR(AG18<Resumo!$O$9,AG18>Resumo!$P$9),"Sim","Não")) -> Não | AT18: R10 | AU18: 14 | AV18: 53.618949 | AW18: 3.294668 | AX18: 0 | AY18: 0 | AZ18: 1 | BA18: Sucesso | BB18: 0 | BC18: 0 | BD18: 8 | BE18: OK FINISH_DONE | BF18: =IF(AV18="","",IF(OR(AV18<Resumo!$O$11,AV18>Resumo!$P$11),"Sim","Não")) -> Não
A19: R01 | B19: 15 | C19: 51.603393 | D19: 3.264862 | E19: 0 | F19: 0 | G19: 1 | H19: Sucesso | I19: 0 | J19: 0 | K19: 8 | L19: OK FINISH_DONE | M19: =IF(C19="","",IF(OR(C19<Resumo!$O$5,C19>Resumo!$P$5),"Sim","Não")) -> Não | P19: R04 | Q19: 15 | R19: 44.94033 | S19: 3.29893 | T19: 0 | U19: 0 | V19: 1 | W19: Sucesso | X19: 0 | Y19: 0 | Z19: 8 | AA19: OK FINISH_DONE | AB19: =IF(R19="","",IF(OR(R19<Resumo!$O$7,R19>Resumo!$P$7),"Sim","Não")) -> Não | AE19: R08 | AF19: 15 | AG19: 51.428018 | AH19: 3.13077 | AI19: 0 | AJ19: 0 | AK19: 1 | AL19: Sucesso | AM19: 0 | AN19: 0 | AO19: 8 | AP19: OK FINISH_DONE | AQ19: =IF(AG19="","",IF(OR(AG19<Resumo!$O$9,AG19>Resumo!$P$9),"Sim","Não")) -> Não | AT19: R10 | AU19: 15 | AV19: 54.480554 | AW19: 3.371893 | AX19: 0 | AY19: 0 | AZ19: 1 | BA19: Sucesso | BB19: 0 | BC19: 0 | BD19: 8 | BE19: OK FINISH_DONE | BF19: =IF(AV19="","",IF(OR(AV19<Resumo!$O$11,AV19>Resumo!$P$11),"Sim","Não")) -> Não
A20: R01 | B20: 16 | C20: 45.411986 | D20: 3.112455 | E20: 0 | F20: 0 | G20: 1 | H20: Sucesso | I20: 0 | J20: 0 | K20: 8 | L20: OK FINISH_DONE | M20: =IF(C20="","",IF(OR(C20<Resumo!$O$5,C20>Resumo!$P$5),"Sim","Não")) -> Não | P20: R04 | Q20: 16 | R20: 44.956658 | S20: 3.294571 | T20: 0 | U20: 0 | V20: 1 | W20: Sucesso | X20: 0 | Y20: 0 | Z20: 8 | AA20: OK FINISH_DONE | AB20: =IF(R20="","",IF(OR(R20<Resumo!$O$7,R20>Resumo!$P$7),"Sim","Não")) -> Não | AE20: R08 | AF20: 16 | AG20: 50.125838 | AH20: 3.227258 | AI20: 0 | AJ20: 0 | AK20: 1 | AL20: Sucesso | AM20: 0 | AN20: 0 | AO20: 8 | AP20: OK FINISH_DONE | AQ20: =IF(AG20="","",IF(OR(AG20<Resumo!$O$9,AG20>Resumo!$P$9),"Sim","Não")) -> Não | AT20: R10 | AU20: 16 | AV20: 46.659176 | AW20: 3.377674 | AX20: 0 | AY20: 0 | AZ20: 1 | BA20: Sucesso | BB20: 0 | BC20: 0 | BD20: 8 | BE20: OK FINISH_DONE | BF20: =IF(AV20="","",IF(OR(AV20<Resumo!$O$11,AV20>Resumo!$P$11),"Sim","Não")) -> Não
A21: R01 | B21: 17 | C21: 54.482655 | D21: 3.239886 | E21: 0 | F21: 0 | G21: 1 | H21: Sucesso | I21: 0 | J21: 0 | K21: 8 | L21: OK FINISH_DONE | M21: =IF(C21="","",IF(OR(C21<Resumo!$O$5,C21>Resumo!$P$5),"Sim","Não")) -> Não | P21: R04 | Q21: 17 | R21: 45.054292 | S21: 3.239438 | T21: 0 | U21: 0 | V21: 1 | W21: Sucesso | X21: 0 | Y21: 0 | Z21: 8 | AA21: OK FINISH_DONE | AB21: =IF(R21="","",IF(OR(R21<Resumo!$O$7,R21>Resumo!$P$7),"Sim","Não")) -> Não | AE21: R08 | AF21: 17 | AG21: 49.137551 | AH21: 3.260261 | AI21: 0 | AJ21: 0 | AK21: 1 | AL21: Sucesso | AM21: 0 | AN21: 0 | AO21: 8 | AP21: OK FINISH_DONE | AQ21: =IF(AG21="","",IF(OR(AG21<Resumo!$O$9,AG21>Resumo!$P$9),"Sim","Não")) -> Não | AT21: R10 | AU21: 17 | AV21: 49.554205 | AW21: 3.294342 | AX21: 0 | AY21: 0 | AZ21: 1 | BA21: Sucesso | BB21: 0 | BC21: 0 | BD21: 8 | BE21: OK FINISH_DONE | BF21: =IF(AV21="","",IF(OR(AV21<Resumo!$O$11,AV21>Resumo!$P$11),"Sim","Não")) -> Não
A22: R01 | B22: 18 | C22: 50.355967 | D22: 3.235473 | E22: 0 | F22: 0 | G22: 1 | H22: Sucesso | I22: 0 | J22: 0 | K22: 8 | L22: OK FINISH_DONE | M22: =IF(C22="","",IF(OR(C22<Resumo!$O$5,C22>Resumo!$P$5),"Sim","Não")) -> Não | P22: R04 | Q22: 18 | R22: 44.984539 | S22: 3.224208 | T22: 0 | U22: 0 | V22: 1 | W22: Sucesso | X22: 0 | Y22: 0 | Z22: 8 | AA22: OK FINISH_DONE | AB22: =IF(R22="","",IF(OR(R22<Resumo!$O$7,R22>Resumo!$P$7),"Sim","Não")) -> Não | AE22: R08 | AF22: 18 | AG22: 48.129765 | AH22: 3.211333 | AI22: 0 | AJ22: 0 | AK22: 1 | AL22: Sucesso | AM22: 0 | AN22: 0 | AO22: 8 | AP22: OK FINISH_DONE | AQ22: =IF(AG22="","",IF(OR(AG22<Resumo!$O$9,AG22>Resumo!$P$9),"Sim","Não")) -> Não | AT22: R10 | AU22: 18 | AV22: 28.719438 | AW22: 3.242442 | AX22: 0 | AY22: 0 | AZ22: 0 | BA22: Falha | BB22: 1 | BC22: 10.9 | BD22: 8 | BE22: OK FINISH_DONE | BF22: =IF(AV22="","",IF(OR(AV22<Resumo!$O$11,AV22>Resumo!$P$11),"Sim","Não")) -> Sim
... A24: R01 | B24: 20 | C24: 55.602209 | D24: 3.261051 | E24: 0 | F24: 0 | G24: 1 | H24: Sucesso | I24: 0 | J24: 0 | K24: 8 | L24: OK FINISH_DONE | M24: =IF(C24="","",IF(OR(C24<Resumo!$O$5,C24>Resumo!$P$5),"Sim","Não")) -> Não | P24: R04 | Q24: 20 | R24: 44.889151 | S24: 3.209951 | T24: 0 | U24: 0 | V24: 1 | W24: Sucesso | X24: 0 | Y24: 0 | Z24: 8 | AA24: OK FINISH_DONE | AB24: =IF(R24="","",IF(OR(R24<Resumo!$O$7,R24>Resumo!$P$7),"Sim","Não")) -> Não | AE24: R08 | AF24: 20 | AG24: 50.544528 | AH24: 3.171914 | AI24: 0 | AJ24: 0 | AK24: 1 | AL24: Sucesso | AM24: 0 | AN24: 0 | AO24: 8 | AP24: OK FINISH_DONE | AQ24: =IF(AG24="","",IF(OR(AG24<Resumo!$O$9,AG24>Resumo!$P$9),"Sim","Não")) -> Não | AT24: R10 | AU24: 20 | AV24: 51.159456 | AW24: 3.374309 | AX24: 0 | AY24: 0 | AZ24: 1 | BA24: Sucesso | BB24: 0 | BC24: 0 | BD24: 8 | BE24: OK FINISH_DONE | BF24: =IF(AV24="","",IF(OR(AV24<Resumo!$O$11,AV24>Resumo!$P$11),"Sim","Não")) -> Não
A25: ESTADOS | P25: ESTADOS | AE25: ESTADOS | AT25: ESTADOS
A26: ID | B26: Repetição | C26: Tempo total (s) | D26: Espera improdutiva (s) | E26: Nº timeouts | F26: Nº comandos prematuros | G26: Taxa sucesso ciclo (0/1) | H26: Resultado | I26: Nº falhas | J26: Tempo recuperação (s) | K26: Nº comandos | L26: Resultado final | M26: Outlier tempo? | N26: Observações | P26: ID | Q26: Repetição | R26: Tempo total (s) | S26: Espera improdutiva (s) | T26: Nº timeouts | U26: Nº comandos prematuros | V26: Taxa sucesso ciclo (0/1) | W26: Resultado | X26: Nº falhas | Y26: Tempo recuperação (s) | Z26: Nº comandos | AA26: Resultado final | AB26: Outlier tempo? | AC26: Observações | AE26: ID | AF26: Repetição | AG26: Tempo total (s) | AH26: Espera improdutiva (s) | AI26: Nº timeouts | AJ26: Nº comandos prematuros | AK26: Taxa sucesso ciclo (0/1) | AL26: Resultado | AM26: Nº falhas | AN26: Tempo recuperação (s) | AO26: Nº comandos | AP26: Resultado final | AQ26: Outlier tempo? | AR26: Observações | AT26: ID | AU26: Repetição | AV26: Tempo total (s) | AW26: Espera improdutiva (s) | AX26: Nº timeouts | AY26: Nº comandos prematuros | AZ26: Taxa sucesso ciclo (0/1) | BA26: Resultado | BB26: Nº falhas | BC26: Tempo recuperação (s) | BD26: Nº comandos | BE26: Resultado final | BF26: Outlier tempo? | BG26: Observações
A27: R01E | B27: 1 | C27: 51.604 | D27: 1.101 | E27: 0 | F27: 0 | G27: 1 | H27: Sucesso | I27: 0 | J27: 0 | K27: 8 | L27: OK FINISH_DONE | M27: =IF(C27="","",IF(OR(C27<Resumo!$O$6,C27>Resumo!$P$6),"Sim","Não")) -> Não | P27: R04E | Q27: 1 | R27: 44.757183 | S27: 1.048377 | T27: 0 | U27: 0 | V27: 1 | W27: Sucesso | X27: 0 | Y27: 0 | Z27: 8 | AA27: OK FINISH_DONE | AB27: =IF(R27="","",IF(OR(R27<Resumo!$O$8,R27>Resumo!$P$8),"Sim","Não")) -> Não | AE27: R08E | AF27: 1 | AG27: 44.014952 | AH27: 1.037619 | AI27: 0 | AJ27: 0 | AK27: 1 | AL27: Sucesso | AM27: 0 | AN27: 0 | AO27: 8 | AP27: OK FINISH_DONE | AQ27: =IF(AG27="","",IF(OR(AG27<Resumo!$O$10,AG27>Resumo!$P$10),"Sim","Não")) -> Não | AT27: R10E | AU27: 1 | AV27: 49.821277 | AW27: 1.030375 | AX27: 0 | AY27: 0 | AZ27: 1 | BA27: Sucesso | BB27: 0 | BC27: 0 | BD27: 8 | BE27: OK FINISH_DONE | BF27: =IF(AV27="","",IF(OR(AV27<Resumo!$O$12,AV27>Resumo!$P$12),"Sim","Não")) -> Não
A28: R01E | B28: 2 | C28: 48.698 | D28: 1.133 | E28: 0 | F28: 0 | G28: 1 | H28: Sucesso | I28: 0 | J28: 0 | K28: 8 | L28: OK FINISH_DONE | M28: =IF(C28="","",IF(OR(C28<Resumo!$O$6,C28>Resumo!$P$6),"Sim","Não")) -> Não | P28: R04E | Q28: 2 | R28: 42.811829 | S28: 1.063399 | T28: 0 | U28: 0 | V28: 1 | W28: Sucesso | X28: 0 | Y28: 0 | Z28: 8 | AA28: OK FINISH_DONE | AB28: =IF(R28="","",IF(OR(R28<Resumo!$O$8,R28>Resumo!$P$8),"Sim","Não")) -> Não | AE28: R08E | AF28: 2 | AG28: 55.879504 | AH28: 1.090637 | AI28: 0 | AJ28: 0 | AK28: 1 | AL28: Sucesso | AM28: 0 | AN28: 0 | AO28: 8 | AP28: OK FINISH_DONE | AQ28: =IF(AG28="","",IF(OR(AG28<Resumo!$O$10,AG28>Resumo!$P$10),"Sim","Não")) -> Sim | AT28: R10E | AU28: 2 | AV28: 43.930378 | AW28: 1.070031 | AX28: 0 | AY28: 0 | AZ28: 1 | BA28: Sucesso | BB28: 0 | BC28: 0 | BD28: 8 | BE28: OK FINISH_DONE | BF28: =IF(AV28="","",IF(OR(AV28<Resumo!$O$12,AV28>Resumo!$P$12),"Sim","Não")) -> Não
A29: R01E | B29: 3 | C29: 53.615 | D29: 1.099 | E29: 0 | F29: 0 | G29: 1 | H29: Sucesso | I29: 0 | J29: 0 | K29: 8 | L29: OK FINISH_DONE | M29: =IF(C29="","",IF(OR(C29<Resumo!$O$6,C29>Resumo!$P$6),"Sim","Não")) -> Não | P29: R04E | Q29: 3 | R29: 42.650284 | S29: 1.061196 | T29: 0 | U29: 0 | V29: 1 | W29: Sucesso | X29: 0 | Y29: 0 | Z29: 8 | AA29: OK FINISH_DONE | AB29: =IF(R29="","",IF(OR(R29<Resumo!$O$8,R29>Resumo!$P$8),"Sim","Não")) -> Não | AE29: R08E | AF29: 3 | AG29: 44.031582 | AH29: 1.065288 | AI29: 0 | AJ29: 0 | AK29: 1 | AL29: Sucesso | AM29: 0 | AN29: 0 | AO29: 8 | AP29: OK FINISH_DONE | AQ29: =IF(AG29="","",IF(OR(AG29<Resumo!$O$10,AG29>Resumo!$P$10),"Sim","Não")) -> Não | AT29: R10E | AU29: 3 | AV29: 6.113277 | AW29: 0.715285 | AX29: 0 | AY29: 0 | AZ29: 0 | BA29: Falha | BB29: 1 | BC29: 6.8 | BD29: 4 | BE29: OK CANCEL_DONE | BF29: =IF(AV29="","",IF(OR(AV29<Resumo!$O$12,AV29>Resumo!$P$12),"Sim","Não")) -> Sim | BG29: Falhou no primeiro move
A30: R01E | B30: 4 | C30: 42.388 | D30: 1.085 | E30: 0 | F30: 0 | G30: 0 | H30: Falha | I30: 1 | J30: 5.8 | K30: 8 | L30: ERROR FINISH_FAILED | M30: =IF(C30="","",IF(OR(C30<Resumo!$O$6,C30>Resumo!$P$6),"Sim","Não")) -> Não | N30: Não consegui calcular trajetória para home | P30: R04E | Q30: 4 | R30: 42.737907 | S30: 1.083949 | T30: 0 | U30: 0 | V30: 1 | W30: Sucesso | X30: 0 | Y30: 0 | Z30: 8 | AA30: OK FINISH_DONE | AB30: =IF(R30="","",IF(OR(R30<Resumo!$O$8,R30>Resumo!$P$8),"Sim","Não")) -> Não | AE30: R08E | AF30: 4 | AG30: 46.095655 | AH30: 1.060403 | AI30: 0 | AJ30: 0 | AK30: 1 | AL30: Sucesso | AM30: 0 | AN30: 0 | AO30: 8 | AP30: OK FINISH_DONE | AQ30: =IF(AG30="","",IF(OR(AG30<Resumo!$O$10,AG30>Resumo!$P$10),"Sim","Não")) -> Não | AT30: R10E | AU30: 4 | AV30: 53.421255 | AW30: 1.029132 | AX30: 0 | AY30: 0 | AZ30: 1 | BA30: Sucesso | BB30: 0 | BC30: 0 | BD30: 8 | BE30: OK FINISH_DONE | BF30: =IF(AV30="","",IF(OR(AV30<Resumo!$O$12,AV30>Resumo!$P$12),"Sim","Não")) -> Não
A31: R01E | B31: 5 | C31: 43.335 | D31: 1.082 | E31: 0 | F31: 0 | G31: 1 | H31: Sucesso | I31: 0 | J31: 0 | K31: 8 | L31: OK FINISH_DONE | M31: =IF(C31="","",IF(OR(C31<Resumo!$O$6,C31>Resumo!$P$6),"Sim","Não")) -> Não | P31: R04E | Q31: 5 | R31: 42.798577 | S31: 1.082041 | T31: 0 | U31: 0 | V31: 1 | W31: Sucesso | X31: 0 | Y31: 0 | Z31: 8 | AA31: OK FINISH_DONE | AB31: =IF(R31="","",IF(OR(R31<Resumo!$O$8,R31>Resumo!$P$8),"Sim","Não")) -> Não | AE31: R08E | AF31: 5 | AG31: 49.046482 | AH31: 1.051514 | AI31: 0 | AJ31: 0 | AK31: 1 | AL31: Sucesso | AM31: 0 | AN31: 0 | AO31: 8 | AP31: OK FINISH_DONE | AQ31: =IF(AG31="","",IF(OR(AG31<Resumo!$O$10,AG31>Resumo!$P$10),"Sim","Não")) -> Não | AT31: R10E | AU31: 5 | AV31: 43.675383 | AW31: 1.125366 | AX31: 0 | AY31: 0 | AZ31: 1 | BA31: Sucesso | BB31: 0 | BC31: 0 | BD31: 8 | BE31: OK FINISH_DONE | BF31: =IF(AV31="","",IF(OR(AV31<Resumo!$O$12,AV31>Resumo!$P$12),"Sim","Não")) -> Não
A32: R01E | B32: 6 | C32: 47.987 | D32: 1.07 | E32: 0 | F32: 0 | G32: 1 | H32: Sucesso | I32: 0 | J32: 0 | K32: 8 | L32: OK FINISH_DONE | M32: =IF(C32="","",IF(OR(C32<Resumo!$O$6,C32>Resumo!$P$6),"Sim","Não")) -> Não | P32: R04E | Q32: 6 | R32: 47.57038 | S32: 1.07589 | T32: 0 | U32: 0 | V32: 1 | W32: Sucesso | X32: 0 | Y32: 0 | Z32: 8 | AA32: OK FINISH_DONE | AB32: =IF(R32="","",IF(OR(R32<Resumo!$O$8,R32>Resumo!$P$8),"Sim","Não")) -> Sim | AE32: R08E | AF32: 6 | AG32: 43.975354 | AH32: 1.054144 | AI32: 0 | AJ32: 0 | AK32: 1 | AL32: Sucesso | AM32: 0 | AN32: 0 | AO32: 8 | AP32: OK FINISH_DONE | AQ32: =IF(AG32="","",IF(OR(AG32<Resumo!$O$10,AG32>Resumo!$P$10),"Sim","Não")) -> Não | AT32: R10E | AU32: 6 | AV32: 48.613154 | AW32: 1.112468 | AX32: 0 | AY32: 0 | AZ32: 1 | BA32: Sucesso | BB32: 0 | BC32: 0 | BD32: 8 | BE32: OK FINISH_DONE | BF32: =IF(AV32="","",IF(OR(AV32<Resumo!$O$12,AV32>Resumo!$P$12),"Sim","Não")) -> Não
A33: R01E | B33: 7 | C33: 50.185 | D33: 1.068 | E33: 0 | F33: 0 | G33: 1 | H33: Sucesso | I33: 0 | J33: 0 | K33: 8 | L33: OK FINISH_DONE | M33: =IF(C33="","",IF(OR(C33<Resumo!$O$6,C33>Resumo!$P$6),"Sim","Não")) -> Não | P33: R04E | Q33: 7 | R33: 45.355725 | S33: 1.024798 | T33: 0 | U33: 0 | V33: 1 | W33: Sucesso | X33: 0 | Y33: 0 | Z33: 8 | AA33: OK FINISH_DONE | AB33: =IF(R33="","",IF(OR(R33<Resumo!$O$8,R33>Resumo!$P$8),"Sim","Não")) -> Não | AE33: R08E | AF33: 7 | AG33: 45.820203 | AH33: 1.083473 | AI33: 0 | AJ33: 0 | AK33: 1 | AL33: Sucesso | AM33: 0 | AN33: 0 | AO33: 8 | AP33: OK FINISH_DONE | AQ33: =IF(AG33="","",IF(OR(AG33<Resumo!$O$10,AG33>Resumo!$P$10),"Sim","Não")) -> Não | AT33: R10E | AU33: 7 | AV33: 49.526924 | AW33: 1.105157 | AX33: 0 | AY33: 0 | AZ33: 1 | BA33: Sucesso | BB33: 0 | BC33: 0 | BD33: 8 | BE33: OK FINISH_DONE | BF33: =IF(AV33="","",IF(OR(AV33<Resumo!$O$12,AV33>Resumo!$P$12),"Sim","Não")) -> Não
A34: R01E | B34: 8 | C34: 43.218 | D34: 1.051 | E34: 0 | F34: 0 | G34: 1 | H34: Sucesso | I34: 0 | J34: 0 | K34: 8 | L34: OK FINISH_DONE | M34: =IF(C34="","",IF(OR(C34<Resumo!$O$6,C34>Resumo!$P$6),"Sim","Não")) -> Não | P34: R04E | Q34: 8 | R34: 42.802085 | S34: 1.067796 | T34: 0 | U34: 0 | V34: 1 | W34: Sucesso | X34: 0 | Y34: 0 | Z34: 8 | AA34: OK FINISH_DONE | AB34: =IF(R34="","",IF(OR(R34<Resumo!$O$8,R34>Resumo!$P$8),"Sim","Não")) -> Não | AE34: R08E | AF34: 8 | AG34: 46.753799 | AH34: 1.07909 | AI34: 0 | AJ34: 0 | AK34: 1 | AL34: Sucesso | AM34: 0 | AN34: 0 | AO34: 8 | AP34: OK FINISH_DONE | AQ34: =IF(AG34="","",IF(OR(AG34<Resumo!$O$10,AG34>Resumo!$P$10),"Sim","Não")) -> Não | AT34: R10E | AU34: 8 | AV34: 46.799123 | AW34: 1.1024 | AX34: 0 | AY34: 0 | AZ34: 1 | BA34: Sucesso | BB34: 0 | BC34: 0 | BD34: 8 | BE34: OK FINISH_DONE | BF34: =IF(AV34="","",IF(OR(AV34<Resumo!$O$12,AV34>Resumo!$P$12),"Sim","Não")) -> Não
A35: R01E | B35: 9 | C35: 48.232 | D35: 1.062 | E35: 0 | F35: 0 | G35: 1 | H35: Sucesso | I35: 0 | J35: 0 | K35: 8 | L35: OK FINISH_DONE | M35: =IF(C35="","",IF(OR(C35<Resumo!$O$6,C35>Resumo!$P$6),"Sim","Não")) -> Não | P35: R04E | Q35: 9 | R35: 42.667493 | S35: 1.028286 | T35: 0 | U35: 0 | V35: 1 | W35: Sucesso | X35: 0 | Y35: 0 | Z35: 8 | AA35: OK FINISH_DONE | AB35: =IF(R35="","",IF(OR(R35<Resumo!$O$8,R35>Resumo!$P$8),"Sim","Não")) -> Não | AE35: R08E | AF35: 9 | AG35: 44.065377 | AH35: 1.059648 | AI35: 0 | AJ35: 0 | AK35: 1 | AL35: Sucesso | AM35: 0 | AN35: 0 | AO35: 8 | AP35: OK FINISH_DONE | AQ35: =IF(AG35="","",IF(OR(AG35<Resumo!$O$10,AG35>Resumo!$P$10),"Sim","Não")) -> Não | AT35: R10E | AU35: 9 | AV35: 48.857926 | AW35: 1.076603 | AX35: 0 | AY35: 0 | AZ35: 1 | BA35: Sucesso | BB35: 0 | BC35: 0 | BD35: 8 | BE35: OK FINISH_DONE | BF35: =IF(AV35="","",IF(OR(AV35<Resumo!$O$12,AV35>Resumo!$P$12),"Sim","Não")) -> Não
