Workbook

Sheet Repetibilidade
A1: Repetibilidade — 10 ciclos × 10 repetições
A2: CICLO 1: Pick (0.55, -0.20, 0.35) → Place (0.70, 0.20, 0.42)
A3: Repetições | B3: Execuções avaliadas | C3: Sucessos | D3: Falhas | E3: Taxa de sucesso | F3: Observações gerais
A4: 10 | B4: 90 | C4: =COUNTIF(G6:Z14,"✓ Sucesso execução") -> 90 | D4: =COUNTIF(G6:Z14,"⮾Falha real") -> 0 | E4: =IF(A4=0,"",(C4/9)/A4) -> 1 | F4: Várias trajetórias diferentes todas com sucesso
A5: Ciclo | C5: Passo | D5: Pose / Estado | E5: Comando terminal | F5: Resultado esperado | G5: Resultado 1 | H5: Motivo falha 1 | I5: Resultado 2 | J5: Motivo falha 2 | K5: Resultado 3 | L5: Motivo falha 3 | M5: Resultado 4 | N5: Motivo falha 4 | O5: Resultado 5 | P5: Motivo falha 5 | Q5: Resultado 6 | R5: Motivo falha 6 | S5: Resultado 7 | T5: Motivo falha 7 | U5: Resultado 8 | V5: Motivo falha 8 | W5: Resultado 9 | X5: Motivo falha 9 | Y5: Resultado 10 | Z5: Motivo falha 10
A6: 1 | C6: 1. PICK | D6: x=0.55, y=-0.20, z=0.35, q=(0,1,0,0) | E6: ros2 topic pub --once /pick_pose geometry_msgs/msg/PoseStamped "{header: {frame_id: 'base'}, pose: {position: {x: 0.55, y: -0.20, z: 0.35}, orientation: {x: 0.0, y: 1.0, z: 0.0, w: 0.0}}}" | F6: OK PICK_DONE peca_X | G6: ✓ Sucesso execução | H6: - | I6: ✓ Sucesso execução | J6: - | K6: ✓ Sucesso execução | L6: - | M6: ✓ Sucesso execução | N6: - | O6: ✓ Sucesso execução | P6: - | Q6: ✓ Sucesso execução | R6: - | S6: ✓ Sucesso execução | T6: - | U6: ✓ Sucesso execução | V6: - | W6: ✓ Sucesso execução | X6: - | Y6: ✓ Sucesso execução | Z6: -
C7: 2. TARGET PICK | D7: x=0.55, y=-0.20, z=0.35, q=(0,1,0,0) | E7: ros2 topic pub --once /target_pose geometry_msgs/msg/PoseStamped "{header: {frame_id: 'base'}, pose: {position: {x: 0.55, y: -0.20, z: 0.35}, orientation: {x: 0.0, y: 1.0, z: 0.0, w: 0.0}}}" | F7: OK TARGET_DONE | G7: ✓ Sucesso execução | H7: - | I7: ✓ Sucesso execução | J7: - | K7: ✓ Sucesso execução | L7: - | M7: ✓ Sucesso execução | N7: - | O7: ✓ Sucesso execução | P7: - | Q7: ✓ Sucesso execução | R7: - | S7: ✓ Sucesso execução | T7: - | U7: ✓ Sucesso execução | V7: - | W7: ✓ Sucesso execução | X7: - | Y7: ✓ Sucesso execução | Z7: -
C8: 3. IR_POSE | D8: pose superior → descida | E8: ros2 topic pub --once /tm12_step std_msgs/msg/String "{data: 'IR_POSE'}" | F8: OK MOVE_DONE | G8: ✓ Sucesso execução | H8: - | I8: ✓ Sucesso execução | J8: - | K8: ✓ Sucesso execução | L8: - | M8: ✓ Sucesso execução | N8: - | O8: ✓ Sucesso execução | P8: - | Q8: ✓ Sucesso execução | R8: - | S8: ✓ Sucesso execução | T8: - | U8: ✓ Sucesso execução | V8: - | W8: ✓ Sucesso execução | X8: - | Y8: ✓ Sucesso execução | Z8: -
C9: 4. FECHAR_GARRA | D9: attach virtual | E9: ros2 topic pub --once /tm12_step std_msgs/msg/String "{data: 'FECHAR_GARRA'}" | F9: OK CLOSE_DONE ATTACHED peca_X | G9: ✓ Sucesso execução | H9: - | I9: ✓ Sucesso execução | J9: - | K9: ✓ Sucesso execução | L9: - | M9: ✓ Sucesso execução | N9: - | O9: ✓ Sucesso execução | P9: - | Q9: ✓ Sucesso execução | R9: - | S9: ✓ Sucesso execução | T9: - | U9: ✓ Sucesso execução | V9: - | W9: ✓ Sucesso execução | X9: - | Y9: ✓ Sucesso execução | Z9: -
C10: 5. TARGET PLACE | D10: x=0.70, y=0.20, z=0.42, q=(0,1,0,0) | E10: ros2 topic pub --once /target_pose geometry_msgs/msg/PoseStamped "{header: {frame_id: 'base'}, pose: {position: {x: 0.70, y: 0.20, z: 0.42}, orientation: {x: 0.0, y: 1.0, z: 0.0, w: 0.0}}}" | F10: OK TARGET_DONE | G10: ✓ Sucesso execução | H10: - | I10: ✓ Sucesso execução | J10: - | K10: ✓ Sucesso execução | L10: - | M10: ✓ Sucesso execução | N10: - | O10: ✓ Sucesso execução | P10: - | Q10: ✓ Sucesso execução | R10: - | S10: ✓ Sucesso execução | T10: - | U10: ✓ Sucesso execução | V10: - | W10: ✓ Sucesso execução | X10: - | Y10: ✓ Sucesso execução | Z10: -
C11: 6. IR_POSE | D11: transporte para place | E11: ros2 topic pub --once /tm12_step std_msgs/msg/String "{data: 'IR_POSE'}" | F11: OK MOVE_DONE | G11: ✓ Sucesso execução | H11: - | I11: ✓ Sucesso execução | J11: - | K11: ✓ Sucesso execução | L11: - | M11: ✓ Sucesso execução | N11: - | O11: ✓ Sucesso execução | P11: - | Q11: ✓ Sucesso execução | R11: - | S11: ✓ Sucesso execução | T11: - | U11: ✓ Sucesso execução | V11: - | W11: ✓ Sucesso execução | X11: - | Y11: ✓ Sucesso execução | Z11: -
C12: 7. ABRIR_GARRA | D12: detach virtual | E12: ros2 topic pub --once /tm12_step std_msgs/msg/String "{data: 'ABRIR_GARRA'}" | F12: OK OPEN_DONE | G12: ✓ Sucesso execução | H12: - | I12: ✓ Sucesso execução | J12: - | K12: ✓ Sucesso execução | L12: - | M12: ✓ Sucesso execução | N12: - | O12: ✓ Sucesso execução | P12: - | Q12: ✓ Sucesso execução | R12: - | S12: ✓ Sucesso execução | T12: - | U12: ✓ Sucesso execução | V12: - | W12: ✓ Sucesso execução | X12: - | Y12: ✓ Sucesso execução | Z12: -
C13: 8. TERMINAR_TAREFA | D13: ir para home | E13: ros2 topic pub --once /tm12_step std_msgs/msg/String "{data: 'TERMINAR_TAREFA'}" | F13: OK FINISH_DONE | G13: ✓ Sucesso execução | H13: - | I13: ✓ Sucesso execução | J13: - | K13: ✓ Sucesso execução | L13: - | M13: ✓ Sucesso execução | N13: - | O13: ✓ Sucesso execução | P13: - | Q13: ✓ Sucesso execução | R13: - | S13: ✓ Sucesso execução | T13: - | U13: ✓ Sucesso execução | V13: - | W13: ✓ Sucesso execução | X13: - | Y13: ✓ Sucesso execução | Z13: -
C14: 9. REMOVER_PEÇA | D14: eliminar peça do planning | E14: ros2 topic pub --once /tm12_step std_msgs/msg/String "{data: 'REMOVER_PECA:peca_1'}" | F14: OK REMOVE_DONE peca_ | G14: ✓ Sucesso execução | H14: - | I14: ✓ Sucesso execução | J14: - | K14: ✓ Sucesso execução | L14: - | M14: ✓ Sucesso execução | N14: - | O14: ✓ Sucesso execução | P14: - | Q14: ✓ Sucesso execução | R14: - | S14: ✓ Sucesso execução | T14: - | U14: ✓ Sucesso execução | V14: - | W14: ✓ Sucesso execução | X14: - | Y14: ✓ Sucesso execução | Z14: -
A16: CICLO 2: Pick (0.60, 0.00, 0.35) → Place (0.50, 0.25, 0.42)
A17: Repetições | B17: Execuções avaliadas | C17: Sucessos | D17: Falhas | E17: Taxa de sucesso | F17: Observações gerais
A18: 10 | B18: 90 | C18: =COUNTIF(G20:Z28,"✓ Sucesso execução") -> 90 | D18: =COUNTIF(G20:Z28,"⮾Falha real") -> 0 | E18: =IF(A18=0,"",(C18/9)/A18) -> 1 | F18: Várias trajetórias diferentes todas com sucesso
A19: Ciclo | C19: Passo | D19: Pose / Estado | E19: Comando terminal | F19: Resultado esperado | G19: Resultado 1 | H19: Motivo falha 1 | I19: Resultado 2 | J19: Motivo falha 2 | K19: Resultado 3 | L19: Motivo falha 3 | M19: Resultado 4 | N19: Motivo falha 4 | O19: Resultado 5 | P19: Motivo falha 5 | Q19: Resultado 6 | R19: Motivo falha 6 | S19: Resultado 7 | T19: Motivo falha 7 | U19: Resultado 8 | V19: Motivo falha 8 | W19: Resultado 9 | X19: Motivo falha 9 | Y19: Resultado 10 | Z19: Motivo falha 10
A20: 2 | C20: 1. PICK | D20: x=0.60, y=0.00, z=0.35, q=(0,1,0,0) | E20: ros2 topic pub --once /pick_pose geometry_msgs/msg/PoseStamped "{header: {frame_id: 'base'}, pose: {position: {x: 0.60, y: 0.00, z: 0.35}, orientation: {x: 0.0, y: 1.0, z: 0.0, w: 0.0}}}" | F20: OK PICK_DONE peca_X | G20: ✓ Sucesso execução | H20: - | I20: ✓ Sucesso execução | J20: - | K20: ✓ Sucesso execução | L20: - | M20: ✓ Sucesso execução | N20: - | O20: ✓ Sucesso execução | P20: - | Q20: ✓ Sucesso execução | R20: - | S20: ✓ Sucesso execução | T20: - | U20: ✓ Sucesso execução | V20: - | W20: ✓ Sucesso execução | X20: - | Y20: ✓ Sucesso execução | Z20: -
C21: 2. TARGET PICK | D21: x=0.60, y=0.00, z=0.35, q=(0,1,0,0) | E21: ros2 topic pub --once /target_pose geometry_msgs/msg/PoseStamped "{header: {frame_id: 'base'}, pose: {position: {x: 0.60, y: 0.00, z: 0.35}, orientation: {x: 0.0, y: 1.0, z: 0.0, w: 0.0}}}" | F21: OK TARGET_DONE | G21: ✓ Sucesso execução | H21: - | I21: ✓ Sucesso execução | J21: - | K21: ✓ Sucesso execução | L21: - | M21: ✓ Sucesso execução | N21: - | O21: ✓ Sucesso execução | P21: - | Q21: ✓ Sucesso execução | R21: - | S21: ✓ Sucesso execução | T21: - | U21: ✓ Sucesso execução | V21: - | W21: ✓ Sucesso execução | X21: - | Y21: ✓ Sucesso execução | Z21: -
C22: 3. IR_POSE | D22: pose superior → descida | E22: ros2 topic pub --once /tm12_step std_msgs/msg/String "{data: 'IR_POSE'}" | F22: OK MOVE_DONE | G22: ✓ Sucesso execução | H22: - | I22: ✓ Sucesso execução | J22: - | K22: ✓ Sucesso execução | L22: - | M22: ✓ Sucesso execução | N22: - | O22: ✓ Sucesso execução | P22: - | Q22: ✓ Sucesso execução | R22: - | S22: ✓ Sucesso execução | T22: - | U22: ✓ Sucesso execução | V22: - | W22: ✓ Sucesso execução | X22: - | Y22: ✓ Sucesso execução | Z22: -
C23: 4. FECHAR_GARRA | D23: attach virtual | E23: ros2 topic pub --once /tm12_step std_msgs/msg/String "{data: 'FECHAR_GARRA'}" | F23: OK CLOSE_DONE ATTACHED peca_X | G23: ✓ Sucesso execução | H23: - | I23: ✓ Sucesso execução | J23: - | K23: ✓ Sucesso execução | L23: - | M23: ✓ Sucesso execução | N23: - | O23: ✓ Sucesso execução | P23: - | Q23: ✓ Sucesso execução | R23: - | S23: ✓ Sucesso execução | T23: - | U23: ✓ Sucesso execução | V23: - | W23: ✓ Sucesso execução | X23: - | Y23: ✓ Sucesso execução | Z23: -
C24: 5. TARGET PLACE | D24: x=0.50, y=0.25, z=0.42, q=(0,1,0,0) | E24: ros2 topic pub --once /target_pose geometry_msgs/msg/PoseStamped "{header: {frame_id: 'base'}, pose: {position: {x: 0.50, y: 0.25, z: 0.42}, orientation: {x: 0.0, y: 1.0, z: 0.0, w: 0.0}}}" | F24: OK TARGET_DONE | G24: ✓ Sucesso execução | H24: - | I24: ✓ Sucesso execução | J24: - | K24: ✓ Sucesso execução | L24: - | M24: ✓ Sucesso execução | N24: - | O24: ✓ Sucesso execução | P24: - | Q24: ✓ Sucesso execução | R24: - | S24: ✓ Sucesso execução | T24: - | U24: ✓ Sucesso execução | V24: - | W24: ✓ Sucesso execução | X24: - | Y24: ✓ Sucesso execução | Z24: -
C25: 6. IR_POSE | D25: transporte para place | E25: ros2 topic pub --once /tm12_step std_msgs/msg/String "{data: 'IR_POSE'}" | F25: OK MOVE_DONE | G25: ✓ Sucesso execução | H25: - | I25: ✓ Sucesso execução | J25: - | K25: ✓ Sucesso execução | L25: - | M25: ✓ Sucesso execução | N25: - | O25: ✓ Sucesso execução | P25: - | Q25: ✓ Sucesso execução | R25: - | S25: ✓ Sucesso execução | T25: - | U25: ✓ Sucesso execução | V25: - | W25: ✓ Sucesso execução | X25: - | Y25: ✓ Sucesso execução | Z25: -
C26: 7. ABRIR_GARRA | D26: detach virtual | E26: ros2 topic pub --once /tm12_step std_msgs/msg/String "{data: 'ABRIR_GARRA'}" | F26: OK OPEN_DONE | G26: ✓ Sucesso execução | H26: - | I26: ✓ Sucesso execução | J26: - | K26: ✓ Sucesso execução | L26: - | M26: ✓ Sucesso execução | N26: - | O26: ✓ Sucesso execução | P26: - | Q26: ✓ Sucesso execução | R26: - | S26: ✓ Sucesso execução | T26: - | U26: ✓ Sucesso execução | V26: - | W26: ✓ Sucesso execução | X26: - | Y26: ✓ Sucesso execução | Z26: -
C27: 8. TERMINAR_TAREFA | D27: ir para home | E27: ros2 topic pub --once /tm12_step std_msgs/msg/String "{data: 'TERMINAR_TAREFA'}" | F27: OK FINISH_DONE | G27: ✓ Sucesso execução | H27: - | I27: ✓ Sucesso execução | J27: - | K27: ✓ Sucesso execução | L27: - | M27: ✓ Sucesso execução | N27: - | O27: ✓ Sucesso execução | P27: - | Q27: ✓ Sucesso execução | R27: - | S27: ✓ Sucesso execução | T27: - | U27: ✓ Sucesso execução | V27: - | W27: ✓ Sucesso execução | X27: - | Y27: ✓ Sucesso execução | Z27: -
C28: 9. REMOVER_PEÇA | D28: eliminar peça do planning | E28: ros2 topic pub --once /tm12_step std_msgs/msg/String "{data: 'REMOVER_PECA:peca_1'}" | F28: OK REMOVE_DONE peca_ | G28: ✓ Sucesso execução | H28: - | I28: ✓ Sucesso execução | J28: - | K28: ✓ Sucesso execução | L28: - | M28: ✓ Sucesso execução | N28: - | O28: ✓ Sucesso execução | P28: - | Q28: ✓ Sucesso execução | R28: - | S28: ✓ Sucesso execução | T28: - | U28: ✓ Sucesso execução | V28: - | W28: ✓ Sucesso execução | X28: - | Y28: ✓ Sucesso execução | Z28: -
A30: CICLO 3: Pick (0.52, 0.25, 0.35) → Place (0.72, -0.20, 0.42)
A31: Repetições | B31: Execuções avaliadas | C31: Sucessos | D31: Falhas | E31: Taxa de sucesso | F31: Observações gerais
A32: 10 | B32: 90 | C32: =COUNTIF(G34:Z42,"✓ Sucesso execução") -> 90 | D32: =COUNTIF(G34:Z42,"⮾Falha real") -> 0 | E32: =IF(A32=0,"",(C32/9)/A32) -> 1 | F32: Executou diferentes trajetórias mas repetiu bastantes todas com sucesso
A33: Ciclo | C33: Passo | D33: Pose / Estado | E33: Comando terminal | F33: Resultado esperado | G33: Resultado 1 | H33: Motivo falha 1 | I33: Resultado 2 | J33: Motivo falha 2 | K33: Resultado 3 | L33: Motivo falha 3 | M33: Resultado 4 | N33: Motivo falha 4 | O33: Resultado 5 | P33: Motivo falha 5 | Q33: Resultado 6 | R33: Motivo falha 6 | S33: Resultado 7 | T33: Motivo falha 7 | U33: Resultado 8 | V33: Motivo falha 8 | W33: Resultado 9 | X33: Motivo falha 9 | Y33: Resultado 10 | Z33: Motivo falha 10
A34: 3 | C34: 1. PICK | D34: x=0.52, y=0.25, z=0.35, q=(0,1,0,0) | E34: ros2 topic pub --once /pick_pose geometry_msgs/msg/PoseStamped "{header: {frame_id: 'base'}, pose: {position: {x: 0.52, y: 0.25, z: 0.35}, orientation: {x: 0.0, y: 1.0, z: 0.0, w: 0.0}}}" | F34: OK PICK_DONE peca_X | G34: ✓ Sucesso execução | H34: - | I34: ✓ Sucesso execução | J34: - | K34: ✓ Sucesso execução | L34: - | M34: ✓ Sucesso execução | N34: - | O34: ✓ Sucesso execução | P34: - | Q34: ✓ Sucesso execução | R34: - | S34: ✓ Sucesso execução | T34: - | U34: ✓ Sucesso execução | V34: - | W34: ✓ Sucesso execução | X34: - | Y34: ✓ Sucesso execução | Z34: -
C35: 2. TARGET PICK | D35: x=0.52, y=0.25, z=0.35, q=(0,1,0,0) | E35: ros2 topic pub --once /target_pose geometry_msgs/msg/PoseStamped "{header: {frame_id: 'base'}, pose: {position: {x: 0.52, y: 0.25, z: 0.35}, orientation: {x: 0.0, y: 1.0, z: 0.0, w: 0.0}}}" | F35: OK TARGET_DONE | G35: ✓ Sucesso execução | H35: - | I35: ✓ Sucesso execução | J35: - | K35: ✓ Sucesso execução | L35: - | M35: ✓ Sucesso execução | N35: - | O35: ✓ Sucesso execução | P35: - | Q35: ✓ Sucesso execução | R35: - | S35: ✓ Sucesso execução | T35: - | U35: ✓ Sucesso execução | V35: - | W35: ✓ Sucesso execução | X35: - | Y35: ✓ Sucesso execução | Z35: -
C36: 3. IR_POSE | D36: pose superior → descida | E36: ros2 topic pub --once /tm12_step std_msgs/msg/String "{data: 'IR_POSE'}" | F36: OK MOVE_DONE | G36: ✓ Sucesso execução | H36: - | I36: ✓ Sucesso execução | J36: - | K36: ✓ Sucesso execução | L36: - | M36: ✓ Sucesso execução | N36: - | O36: ✓ Sucesso execução | P36: - | Q36: ✓ Sucesso execução | R36: - | S36: ✓ Sucesso execução | T36: - | U36: ✓ Sucesso execução | V36: - | W36: ✓ Sucesso execução | X36: - | Y36: ✓ Sucesso execução | Z36: -
C37: 4. FECHAR_GARRA | D37: attach virtual | E37: ros2 topic pub --once /tm12_step std_msgs/msg/String "{data: 'FECHAR_GARRA'}" | F37: OK CLOSE_DONE ATTACHED peca_X | G37: ✓ Sucesso execução | H37: - | I37: ✓ Sucesso execução | J37: - | K37: ✓ Sucesso execução | L37: - | M37: ✓ Sucesso execução | N37: - | O37: ✓ Sucesso execução | P37: - | Q37: ✓ Sucesso execução | R37: - | S37: ✓ Sucesso execução | T37: - | U37: ✓ Sucesso execução | V37: - | W37: ✓ Sucesso execução | X37: - | Y37: ✓ Sucesso execução | Z37: -
C38: 5. TARGET PLACE | D38: x=0.72, y=-0.20, z=0.42, q=(0,1,0,0) | E38: ros2 topic pub --once /target_pose geometry_msgs/msg/PoseStamped "{header: {frame_id: 'base'}, pose: {position: {x: 0.72, y: -0.20, z: 0.42}, orientation: {x: 0.0, y: 1.0, z: 0.0, w: 0.0}}}" | F38: OK TARGET_DONE | G38: ✓ Sucesso execução | H38: - | I38: ✓ Sucesso execução | J38: - | K38: ✓ Sucesso execução | L38: - | M38: ✓ Sucesso execução | N38: - | O38: ✓ Sucesso execução | P38: - | Q38: ✓ Sucesso execução | R38: - | S38: ✓ Sucesso execução | T38: - | U38: ✓ Sucesso execução | V38: - | W38: ✓ Sucesso execução | X38: - | Y38: ✓ Sucesso execução | Z38: -
C39: 6. IR_POSE | D39: transporte para place | E39: ros2 topic pub --once /tm12_step std_msgs/msg/String "{data: 'IR_POSE'}" | F39: OK MOVE_DONE | G39: ✓ Sucesso execução | H39: - | I39: ✓ Sucesso execução | J39: - | K39: ✓ Sucesso execução | L39: - | M39: ✓ Sucesso execução | N39: - | O39: ✓ Sucesso execução | P39: - | Q39: ✓ Sucesso execução | R39: - | S39: ✓ Sucesso execução | T39: - | U39: ✓ Sucesso execução | V39: - | W39: ✓ Sucesso execução | X39: - | Y39: ✓ Sucesso execução | Z39: -
C40: 7. ABRIR_GARRA | D40: detach virtual | E40: ros2 topic pub --once /tm12_step std_msgs/msg/String "{data: 'ABRIR_GARRA'}" | F40: OK OPEN_DONE | G40: ✓ Sucesso execução | H40: - | I40: ✓ Sucesso execução | J40: - | K40: ✓ Sucesso execução | L40: - | M40: ✓ Sucesso execução | N40: - | O40: ✓ Sucesso execução | P40: - | Q40: ✓ Sucesso execução | R40: - | S40: ✓ Sucesso execução | T40: - | U40: ✓ Sucesso execução | V40: - | W40: ✓ Sucesso execução | X40: - | Y40: ✓ Sucesso execução | Z40: -
C41: 8. TERMINAR_TAREFA | D41: ir para home | E41: ros2 topic pub --once /tm12_step std_msgs/msg/String "{data: 'TERMINAR_TAREFA'}" | F41: OK FINISH_DONE | G41: ✓ Sucesso execução | H41: - | I41: ✓ Sucesso execução | J41: - | K41: ✓ Sucesso execução | L41: - | M41: ✓ Sucesso execução | N41: - | O41: ✓ Sucesso execução | P41: - | Q41: ✓ Sucesso execução | R41: - | S41: ✓ Sucesso execução | T41: - | U41: ✓ Sucesso execução | V41: - | W41: ✓ Sucesso execução | X41: - | Y41: ✓ Sucesso execução | Z41: -
C42: 9. REMOVER_PEÇA | D42: eliminar peça do planning | E42: ros2 topic pub --once /tm12_step std_msgs/msg/String "{data: 'REMOVER_PECA:peca_1'}" | F42: OK REMOVE_DONE peca_ | G42: ✓ Sucesso execução | H42: - | I42: ✓ Sucesso execução | J42: - | K42: ✓ Sucesso execução | L42: - | M42: ✓ Sucesso execução | N42: - | O42: ✓ Sucesso execução | P42: - | Q42: ✓ Sucesso execução | R42: - | S42: ✓ Sucesso execução | T42: - | U42: ✓ Sucesso execução | V42: - | W42: ✓ Sucesso execução | X42: - | Y42: ✓ Sucesso execução | Z42: -
...

Sheet Métricas PICK_POSE
A1: Ciclo | B1: Repetição | C1: Pose X | D1: Pose Y | E1: Pose Z | F1: Validação (SIM/NÃO) | G1: Peça criada (SIM/NÃO) | H1: Tempo resposta (ms) | I1: Resultado esperado | J1: Resultado obtido | K1: Status (✓/✗) | M1: Ciclo | N1: Repetição | O1: Pose X | P1: Pose Y | Q1: Pose Z | R1: Validação (SIM/NÃO) | S1: Peça criada (SIM/NÃO) | T1: Tempo resposta (ms) | U1: Resultado esperado | V1: Resultado obtido | W1: Status (✓/✗)
A2: 1 | B2: 1 | C2: 0.55 | D2: -0.2 | E2: 0.35 | F2: SIM | G2: SIM | H2: 152.9291 | I2: OK PICK_DONE | J2: OK PICK_DONE | K2: ✓ | M2: 6 | N2: 1 | O2: 0.5 | P2: -0.3 | Q2: 0.35 | R2: SIM | S2: SIM | T2: 252.5365 | U2: OK PICK_DONE | V2: OK PICK_DONE | W2: ✓
A3: 1 | B3: 2 | C3: 0.55 | D3: -0.2 | E3: 0.35 | F3: SIM | G3: SIM | H3: 152.0171 | I3: OK PICK_DONE | J3: OK PICK_DONE | K3: ✓ | M3: 6 | N3: 2 | O3: 0.5 | P3: -0.3 | Q3: 0.35 | R3: SIM | S3: SIM | T3: 151.9229 | U3: OK PICK_DONE | V3: OK PICK_DONE | W3: ✓
A4: 1 | B4: 3 | C4: 0.55 | D4: -0.2 | E4: 0.35 | F4: SIM | G4: SIM | H4: 155.1752 | I4: OK PICK_DONE | J4: OK PICK_DONE | K4: ✓ | M4: 6 | N4: 3 | O4: 0.5 | P4: -0.3 | Q4: 0.35 | R4: SIM | S4: SIM | T4: 152.0145 | U4: OK PICK_DONE | V4: OK PICK_DONE | W4: ✓
A5: 1 | B5: 4 | C5: 0.55 | D5: -0.2 | E5: 0.35 | F5: SIM | G5: SIM | H5: 54.7836 | I5: OK PICK_DONE | J5: OK PICK_DONE | K5: ✓ | M5: 6 | N5: 4 | O5: 0.5 | P5: -0.3 | Q5: 0.35 | R5: SIM | S5: SIM | T5: 151.9032 | U5: OK PICK_DONE | V5: OK PICK_DONE | W5: ✓
A6: 1 | B6: 5 | C6: 0.55 | D6: -0.2 | E6: 0.35 | F6: SIM | G6: SIM | H6: 152.1132 | I6: OK PICK_DONE | J6: OK PICK_DONE | K6: ✓ | M6: 6 | N6: 5 | O6: 0.5 | P6: -0.3 | Q6: 0.35 | R6: SIM | S6: SIM | T6: 151.7724 | U6: OK PICK_DONE | V6: OK PICK_DONE | W6: ✓
A7: 1 | B7: 6 | C7: 0.55 | D7: -0.2 | E7: 0.35 | F7: SIM | G7: SIM | H7: 152.9052 | I7: OK PICK_DONE | J7: OK PICK_DONE | K7: ✓ | M7: 6 | N7: 6 | O7: 0.5 | P7: -0.3 | Q7: 0.35 | R7: SIM | S7: SIM | T7: 152.6575 | U7: OK PICK_DONE | V7: OK PICK_DONE | W7: ✓
A8: 1 | B8: 7 | C8: 0.55 | D8: -0.2 | E8: 0.35 | F8: SIM | G8: SIM | H8: 152.6349 | I8: OK PICK_DONE | J8: OK PICK_DONE | K8: ✓ | M8: 6 | N8: 7 | O8: 0.5 | P8: -0.3 | Q8: 0.35 | R8: SIM | S8: SIM | T8: 151.5257 | U8: OK PICK_DONE | V8: OK PICK_DONE | W8: ✓
A9: 1 | B9: 8 | C9: 0.55 | D9: -0.2 | E9: 0.35 | F9: SIM | G9: SIM | H9: 156.9684 | I9: OK PICK_DONE | J9: OK PICK_DONE | K9: ✓ | M9: 6 | N9: 8 | O9: 0.5 | P9: -0.3 | Q9: 0.35 | R9: SIM | S9: SIM | T9: 151.6747 | U9: OK PICK_DONE | V9: OK PICK_DONE | W9: ✓
A10: 1 | B10: 9 | C10: 0.55 | D10: -0.2 | E10: 0.35 | F10: SIM | G10: SIM | H10: 151.895 | I10: OK PICK_DONE | J10: OK PICK_DONE | K10: ✓ | M10: 6 | N10: 9 | O10: 0.5 | P10: -0.3 | Q10: 0.35 | R10: SIM | S10: SIM | T10: 151.6407 | U10: OK PICK_DONE | V10: OK PICK_DONE | W10: ✓
A11: 1 | B11: 10 | C11: 0.55 | D11: -0.2 | E11: 0.35 | F11: SIM | G11: SIM | H11: 152.9899 | I11: OK PICK_DONE | J11: OK PICK_DONE | K11: ✓ | M11: 6 | N11: 10 | O11: 0.5 | P11: -0.3 | Q11: 0.35 | R11: SIM | S11: SIM | T11: 152.8852 | U11: OK PICK_DONE | V11: OK PICK_DONE | W11: ✓
G12: Média | H12: =AVERAGE(H2:H11) -> 143.44116 | S12: Média | T12: =AVERAGE(T2:T11) -> 162.05333
A13: Ciclo | B13: Repetição | C13: Pose X | D13: Pose Y | E13: Pose Z | F13: Validação (SIM/NÃO) | G13: Peça criada (SIM/NÃO) | H13: Tempo resposta (ms) | I13: Resultado esperado | J13: Resultado obtido | K13: Status (✓/✗) | M13: Ciclo | N13: Repetição | O13: Pose X | P13: Pose Y | Q13: Pose Z | R13: Validação (SIM/NÃO) | S13: Peça criada (SIM/NÃO) | T13: Tempo resposta (ms) | U13: Resultado esperado | V13: Resultado obtido | W13: Status (✓/✗)
A14: 2 | B14: 1 | C14: 0.6 | D14: 0 | E14: 0.35 | F14: SIM | G14: SIM | H14: 151.5393 | I14: OK PICK_DONE | J14: OK PICK_DONE | K14: ✓ | M14: 7 | N14: 1 | O14: 0.75 | P14: -0.1 | Q14: 0.35 | R14: SIM | S14: SIM | T14: 155.0503 | U14: OK PICK_DONE | V14: OK PICK_DONE | W14: ✓
A15: 2 | B15: 2 | C15: 0.6 | D15: 0 | E15: 0.35 | F15: SIM | G15: SIM | H15: 153.4231 | I15: OK PICK_DONE | J15: OK PICK_DONE | K15: ✓ | M15: 7 | N15: 2 | O15: 0.75 | P15: -0.1 | Q15: 0.35 | R15: SIM | S15: SIM | T15: 159.3707 | U15: OK PICK_DONE | V15: OK PICK_DONE | W15: ✓
A16: 2 | B16: 3 | C16: 0.6 | D16: 0 | E16: 0.35 | F16: SIM | G16: SIM | H16: 156.8539 | I16: OK PICK_DONE | J16: OK PICK_DONE | K16: ✓ | M16: 7 | N16: 3 | O16: 0.75 | P16: -0.1 | Q16: 0.35 | R16: SIM | S16: SIM | T16: 152.4816 | U16: OK PICK_DONE | V16: OK PICK_DONE | W16: ✓
A17: 2 | B17: 4 | C17: 0.6 | D17: 0 | E17: 0.35 | F17: SIM | G17: SIM | H17: 152.025 | I17: OK PICK_DONE | J17: OK PICK_DONE | K17: ✓ | M17: 7 | N17: 4 | O17: 0.75 | P17: -0.1 | Q17: 0.35 | R17: SIM | S17: SIM | T17: 152.178 | U17: OK PICK_DONE | V17: OK PICK_DONE | W17: ✓
A18: 2 | B18: 5 | C18: 0.6 | D18: 0 | E18: 0.35 | F18: SIM | G18: SIM | H18: 151.8412 | I18: OK PICK_DONE | J18: OK PICK_DONE | K18: ✓ | M18: 7 | N18: 5 | O18: 0.75 | P18: -0.1 | Q18: 0.35 | R18: SIM | S18: SIM | T18: 151.7432 | U18: OK PICK_DONE | V18: OK PICK_DONE | W18: ✓
A19: 2 | B19: 6 | C19: 0.6 | D19: 0 | E19: 0.35 | F19: SIM | G19: SIM | H19: 152.6213 | I19: OK PICK_DONE | J19: OK PICK_DONE | K19: ✓ | M19: 7 | N19: 6 | O19: 0.75 | P19: -0.1 | Q19: 0.35 | R19: SIM | S19: SIM | T19: 152.6527 | U19: OK PICK_DONE | V19: OK PICK_DONE | W19: ✓
A20: 2 | B20: 7 | C20: 0.6 | D20: 0 | E20: 0.35 | F20: SIM | G20: SIM | H20: 152.0646 | I20: OK PICK_DONE | J20: OK PICK_DONE | K20: ✓ | M20: 7 | N20: 7 | O20: 0.75 | P20: -0.1 | Q20: 0.35 | R20: SIM | S20: SIM | T20: 151.7746 | U20: OK PICK_DONE | V20: OK PICK_DONE | W20: ✓
A21: 2 | B21: 8 | C21: 0.6 | D21: 0 | E21: 0.35 | F21: SIM | G21: SIM | H21: 155.8323 | I21: OK PICK_DONE | J21: OK PICK_DONE | K21: ✓ | M21: 7 | N21: 8 | O21: 0.75 | P21: -0.1 | Q21: 0.35 | R21: SIM | S21: SIM | T21: 155.0589 | U21: OK PICK_DONE | V21: OK PICK_DONE | W21: ✓
A22: 2 | B22: 9 | C22: 0.6 | D22: 0 | E22: 0.35 | F22: SIM | G22: SIM | H22: 151.6738 | I22: OK PICK_DONE | J22: OK PICK_DONE | K22: ✓ | M22: 7 | N22: 9 | O22: 0.75 | P22: -0.1 | Q22: 0.35 | R22: SIM | S22: SIM | T22: 152.0276 | U22: OK PICK_DONE | V22: OK PICK_DONE | W22: ✓
A23: 2 | B23: 10 | C23: 0.6 | D23: 0 | E23: 0.35 | F23: SIM | G23: SIM | H23: 153.3108 | I23: OK PICK_DONE | J23: OK PICK_DONE | K23: ✓ | M23: 7 | N23: 10 | O23: 0.75 | P23: -0.1 | Q23: 0.35 | R23: SIM | S23: SIM | T23: 152.8051 | U23: OK PICK_DONE | V23: OK PICK_DONE | W23: ✓
G24: Média | H24: =AVERAGE(H14:H23) -> 153.11853 | S24: Média | T24: =AVERAGE(T14:T23) -> 153.51427
A25: Ciclo | B25: Repetição | C25: Pose X | D25: Pose Y | E25: Pose Z | F25: Validação (SIM/NÃO) | G25: Peça criada (SIM/NÃO) | H25: Tempo resposta (ms) | I25: Resultado esperado | J25: Resultado obtido | K25: Status (✓/✗) | M25: Ciclo | N25: Repetição | O25: Pose X | P25: Pose Y | Q25: Pose Z | R25: Validação (SIM/NÃO) | S25: Peça criada (SIM/NÃO) | T25: Tempo resposta (ms) | U25: Resultado esperado | V25: Resultado obtido | W25: Status (✓/✗)
A26: 3 | B26: 1 | C26: 0.52 | D26: 0.25 | E26: 0.35 | F26: SIM | G26: SIM | H26: 152.4751 | I26: OK PICK_DONE | J26: OK PICK_DONE | K26: ✓ | M26: 8 | N26: 1 | O26: 0.55 | P26: 0.3 | Q26: 0.35 | R26: SIM | S26: SIM | T26: 154.0318 | U26: OK PICK_DONE | V26: OK PICK_DONE | W26: ✓
A27: 3 | B27: 2 | C27: 0.52 | D27: 0.25 | E27: 0.35 | F27: SIM | G27: SIM | H27: 152.5791 | I27: OK PICK_DONE | J27: OK PICK_DONE | K27: ✓ | M27: 8 | N27: 2 | O27: 0.55 | P27: 0.3 | Q27: 0.35 | R27: SIM | S27: SIM | T27: 151.9642 | U27: OK PICK_DONE | V27: OK PICK_DONE | W27: ✓
A28: 3 | B28: 3 | C28: 0.52 | D28: 0.25 | E28: 0.35 | F28: SIM | G28: SIM | H28: 161.6621 | I28: OK PICK_DONE | J28: OK PICK_DONE | K28: ✓ | M28: 8 | N28: 3 | O28: 0.55 | P28: 0.3 | Q28: 0.35 | R28: SIM | S28: SIM | T28: 152.4086 | U28: OK PICK_DONE | V28: OK PICK_DONE | W28: ✓
A29: 3 | B29: 4 | C29: 0.52 | D29: 0.25 | E29: 0.35 | F29: SIM | G29: SIM | H29: 156.4419 | I29: OK PICK_DONE | J29: OK PICK_DONE | K29: ✓ | M29: 8 | N29: 4 | O29: 0.55 | P29: 0.3 | Q29: 0.35 | R29: SIM | S29: SIM | T29: 151.7193 | U29: OK PICK_DONE | V29: OK PICK_DONE | W29: ✓
A30: 3 | B30: 5 | C30: 0.52 | D30: 0.25 | E30: 0.35 | F30: SIM | G30: SIM | H30: 142.0629 | I30: OK PICK_DONE | J30: OK PICK_DONE | K30: ✓ | M30: 8 | N30: 5 | O30: 0.55 | P30: 0.3 | Q30: 0.35 | R30: SIM | S30: SIM | T30: 156.5514 | U30: OK PICK_DONE | V30: OK PICK_DONE | W30: ✓
A31: 3 | B31: 6 | C31: 0.52 | D31: 0.25 | E31: 0.35 | F31: SIM | G31: SIM | H31: 151.8264 | I31: OK PICK_DONE | J31: OK PICK_DONE | K31: ✓ | M31: 8 | N31: 6 | O31: 0.55 | P31: 0.3 | Q31: 0.35 | R31: SIM | S31: SIM | T31: 152.8068 | U31: OK PICK_DONE | V31: OK PICK_DONE | W31: ✓
A32: 3 | B32: 7 | C32: 0.52 | D32: 0.25 | E32: 0.35 | F32: SIM | G32: SIM | H32: 151.7611 | I32: OK PICK_DONE | J32: OK PICK_DONE | K32: ✓ | M32: 8 | N32: 7 | O32: 0.55 | P32: 0.3 | Q32: 0.35 | R32: SIM | S32: SIM | T32: 154.1982 | U32: OK PICK_DONE | V32: OK PICK_DONE | W32: ✓
A33: 3 | B33: 8 | C33: 0.52 | D33: 0.25 | E33: 0.35 | F33: SIM | G33: SIM | H33: 152.1397 | I33: OK PICK_DONE | J33: OK PICK_DONE | K33: ✓ | M33: 8 | N33: 8 | O33: 0.55 | P33: 0.3 | Q33: 0.35 | R33: SIM | S33: SIM | T33: 151.2569 | U33: OK PICK_DONE | V33: OK PICK_DONE | W33: ✓
A34: 3 | B34: 9 | C34: 0.52 | D34: 0.25 | E34: 0.35 | F34: SIM | G34: SIM | H34: 120.0995 | I34: OK PICK_DONE | J34: OK PICK_DONE | K34: ✓ | M34: 8 | N34: 9 | O34: 0.55 | P34: 0.3 | Q34: 0.35 | R34: SIM | S34: SIM | T34: 151.9668 | U34: OK PICK_DONE | V34: OK PICK_DONE | W34: ✓
A35: 3 | B35: 10 | C35: 0.52 | D35: 0.25 | E35: 0.35 | F35: SIM | G35: SIM | H35: 152.0126 | I35: OK PICK_DONE | J35: OK PICK_DONE | K35: ✓ | M35: 8 | N35: 10 | O35: 0.55 | P35: 0.3 | Q35: 0.35 | R35: SIM | S35: SIM | T35: 151.8421 | U35: OK PICK_DONE | V35: OK PICK_DONE | W35: ✓
G36: Média | H36: =AVERAGE(H26:H35) -> 149.30604 | S36: Média | T36: =AVERAGE(T26:T35) -> 152.87461
A37: Ciclo | B37: Repetição | C37: Pose X | D37: Pose Y | E37: Pose Z | F37: Validação (SIM/NÃO) | G37: Peça criada (SIM/NÃO) | H37: Tempo resposta (ms) | I37: Resultado esperado | J37: Resultado obtido | K37: Status (✓/✗) | M37: Ciclo | N37: Repetição | O37: Pose X | P37: Pose Y | Q37: Pose Z | R37: Validação (SIM/NÃO) | S37: Peça criada (SIM/NÃO) | T37: Tempo resposta (ms) | U37: Resultado esperado | V37: Resultado obtido | W37: Status (✓/✗)
A38: 4 | B38: 1 | C38: 0.7 | D38: -0.25 | E38: 0.35 | F38: SIM | G38: SIM | H38: 151.8235 | I38: OK PICK_DONE | J38: OK PICK_DONE | K38: ✓ | M38: 9 | N38: 1 | O38: 0.5 | P38: -0.3 | Q38: 0.35 | R38: SIM | S38: SIM | T38: 151.1631 | U38: OK PICK_DONE | V38: OK PICK_DONE | W38: ✓
A39: 4 | B39: 2 | C39: 0.7 | D39: -0.25 | E39: 0.35 | F39: SIM | G39: SIM | H39: 151.8672 | I39: OK PICK_DONE | J39: OK PICK_DONE | K39: ✓ | M39: 9 | N39: 2 | O39: 0.5 | P39: -0.3 | Q39: 0.35 | R39: SIM | S39: SIM | T39: 151.9928 | U39: OK PICK_DONE | V39: OK PICK_DONE | W39: ✓
A40: 4 | B40: 3 | C40: 0.7 | D40: -0.25 | E40: 0.35 | F40: SIM | G40: SIM | H40: 151.6366 | I40: OK PICK_DONE | J40: OK PICK_DONE | K40: ✓ | M40: 9 | N40: 3 | O40: 0.5 | P40: -0.3 | Q40: 0.35 | R40: SIM | S40: SIM | T40: 151.9761 | U40: OK PICK_DONE | V40: OK PICK_DONE | W40: ✓
...

Sheet Métricas TARGET_POSE
A1: Ciclo | B1: Repetição | C1: Pose X | D1: Pose Y | E1: Pose Z | F1: Validação destino (SIM/NÃO) | G1: Aceitação/Rejeição | H1: Tempo resposta (ms) | I1: Resultado esperado | J1: Resultado obtido | K1: Status (✓/✗) | M1: Ciclo | N1: Repetição | O1: Pose X | P1: Pose Y | Q1: Pose Z | R1: Validação destino (SIM/NÃO) | S1: Aceitação/Rejeição | T1: Tempo resposta (ms) | U1: Resultado esperado | V1: Resultado obtido | W1: Status (✓/✗)
A2: 1 | B2: 1 | C2: 0.55 | D2: -0.2 | E2: 0.35 | F2: SIM | G2: Aceitação | H2: 1.863 | I2: OK TARGET_DONE | J2: OK TARGET_DONE | K2: ✓ | M2: 2 | N2: 1 | O2: 0.6 | P2: 0 | Q2: 0.35 | R2: SIM | S2: Aceitação | T2: 1.7669 | U2: OK TARGET_DONE | V2: OK TARGET_DONE | W2: ✓
A3: 1 | B3: 1 | C3: 0.7 | D3: 0.2 | E3: 0.42 | F3: SIM | G3: Aceitação | H3: 1.9202 | I3: OK TARGET_DONE | J3: OK TARGET_DONE | K3: ✓ | M3: 2 | N3: 1 | O3: 0.5 | P3: 0.25 | Q3: 0.42 | R3: SIM | S3: Aceitação | T3: 2.8882 | U3: OK TARGET_DONE | V3: OK TARGET_DONE | W3: ✓
A4: 1 | B4: 2 | C4: 0.55 | D4: -0.2 | E4: 0.35 | F4: SIM | G4: Aceitação | H4: 2.0883 | I4: OK TARGET_DONE | J4: OK TARGET_DONE | K4: ✓ | M4: 2 | N4: 2 | O4: 0.6 | P4: 0 | Q4: 0.35 | R4: SIM | S4: Aceitação | T4: 3.2291 | U4: OK TARGET_DONE | V4: OK TARGET_DONE | W4: ✓
A5: 1 | B5: 2 | C5: 0.7 | D5: 0.2 | E5: 0.42 | F5: SIM | G5: Aceitação | H5: 2.8312 | I5: OK TARGET_DONE | J5: OK TARGET_DONE | K5: ✓ | M5: 2 | N5: 2 | O5: 0.5 | P5: 0.25 | Q5: 0.42 | R5: SIM | S5: Aceitação | T5: 1.739 | U5: OK TARGET_DONE | V5: OK TARGET_DONE | W5: ✓
A6: 1 | B6: 3 | C6: 0.55 | D6: -0.2 | E6: 0.35 | F6: SIM | G6: Aceitação | H6: 1.6222 | I6: OK TARGET_DONE | J6: OK TARGET_DONE | K6: ✓ | M6: 2 | N6: 3 | O6: 0.6 | P6: 0 | Q6: 0.35 | R6: SIM | S6: Aceitação | T6: 1.5159 | U6: OK TARGET_DONE | V6: OK TARGET_DONE | W6: ✓
A7: 1 | B7: 3 | C7: 0.7 | D7: 0.2 | E7: 0.42 | F7: SIM | G7: Aceitação | H7: 1.4801 | I7: OK TARGET_DONE | J7: OK TARGET_DONE | K7: ✓ | M7: 2 | N7: 3 | O7: 0.5 | P7: 0.25 | Q7: 0.42 | R7: SIM | S7: Aceitação | T7: 1.802 | U7: OK TARGET_DONE | V7: OK TARGET_DONE | W7: ✓
A8: 1 | B8: 4 | C8: 0.55 | D8: -0.2 | E8: 0.35 | F8: SIM | G8: Aceitação | H8: 1.6222 | I8: OK TARGET_DONE | J8: OK TARGET_DONE | K8: ✓ | M8: 2 | N8: 4 | O8: 0.6 | P8: 0 | Q8: 0.35 | R8: SIM | S8: Aceitação | T8: 1.934 | U8: OK TARGET_DONE | V8: OK TARGET_DONE | W8: ✓
A9: 1 | B9: 4 | C9: 0.7 | D9: 0.2 | E9: 0.42 | F9: SIM | G9: Aceitação | H9: 1.4801 | I9: OK TARGET_DONE | J9: OK TARGET_DONE | K9: ✓ | M9: 2 | N9: 4 | O9: 0.5 | P9: 0.25 | Q9: 0.42 | R9: SIM | S9: Aceitação | T9: 1.9865 | U9: OK TARGET_DONE | V9: OK TARGET_DONE | W9: ✓
A10: 1 | B10: 5 | C10: 0.55 | D10: -0.2 | E10: 0.35 | F10: SIM | G10: Aceitação | H10: 1.8461 | I10: OK TARGET_DONE | J10: OK TARGET_DONE | K10: ✓ | M10: 2 | N10: 5 | O10: 0.6 | P10: 0 | Q10: 0.35 | R10: SIM | S10: Aceitação | T10: 2.0471 | U10: OK TARGET_DONE | V10: OK TARGET_DONE | W10: ✓
A11: 1 | B11: 5 | C11: 0.7 | D11: 0.2 | E11: 0.42 | F11: SIM | G11: Aceitação | H11: 2.6207 | I11: OK TARGET_DONE | J11: OK TARGET_DONE | K11: ✓ | M11: 2 | N11: 5 | O11: 0.5 | P11: 0.25 | Q11: 0.42 | R11: SIM | S11: Aceitação | T11: 1.8716 | U11: OK TARGET_DONE | V11: OK TARGET_DONE | W11: ✓
A12: 1 | B12: 6 | C12: 0.55 | D12: -0.2 | E12: 0.35 | F12: SIM | G12: Aceitação | H12: 2.0251 | I12: OK TARGET_DONE | J12: OK TARGET_DONE | K12: ✓ | M12: 2 | N12: 6 | O12: 0.6 | P12: 0 | Q12: 0.35 | R12: SIM | S12: Aceitação | T12: 2.5425 | U12: OK TARGET_DONE | V12: OK TARGET_DONE | W12: ✓
A13: 1 | B13: 6 | C13: 0.7 | D13: 0.2 | E13: 0.42 | F13: SIM | G13: Aceitação | H13: 1.7364 | I13: OK TARGET_DONE | J13: OK TARGET_DONE | K13: ✓ | M13: 2 | N13: 6 | O13: 0.5 | P13: 0.25 | Q13: 0.42 | R13: SIM | S13: Aceitação | T13: 2.0254 | U13: OK TARGET_DONE | V13: OK TARGET_DONE | W13: ✓
... A21: 1 | B21: 10 | C21: 0.7 | D21: 0.2 | E21: 0.42 | F21: SIM | G21: Aceitação | H21: 2.0235 | I21: OK TARGET_DONE | J21: OK TARGET_DONE | K21: ✓ | M21: 2 | N21: 10 | O21: 0.5 | P21: 0.25 | Q21: 0.42 | R21: SIM | S21: Aceitação | T21: 1.9956 | U21: OK TARGET_DONE | V21: OK TARGET_DONE | W21: ✓
G22: Média | H22: =AVERAGE(H2:H21) -> 1.878405 | S22: Média | T22: =AVERAGE(T2:T21) -> 2.221095
A23: Ciclo | B23: Repetição | C23: Pose X | D23: Pose Y | E23: Pose Z | F23: Validação destino (SIM/NÃO) | G23: Aceitação/Rejeição | H23: Tempo resposta (ms) | I23: Resultado esperado | J23: Resultado obtido | K23: Status (✓/✗) | M23: Ciclo | N23: Repetição | O23: Pose X | P23: Pose Y | Q23: Pose Z | R23: Validação destino (SIM/NÃO) | S23: Aceitação/Rejeição | T23: Tempo resposta (ms) | U23: Resultado esperado | V23: Resultado obtido | W23: Status (✓/✗)
A24: 3 | B24: 1 | C24: 0.52 | D24: 0.25 | E24: 0.35 | F24: SIM | G24: Aceitação | H24: 1.8642 | I24: OK TARGET_DONE | J24: OK TARGET_DONE | K24: ✓ | M24: 4 | N24: 1 | O24: 0.7 | P24: -0.25 | Q24: 0.35 | R24: SIM | S24: Aceitação | T24: 1.6856 | U24: OK TARGET_DONE | V24: OK TARGET_DONE | W24: ✓
A25: 3 | B25: 1 | C25: 0.72 | D25: -0.2 | E25: 0.42 | F25: SIM | G25: Aceitação | H25: 1.6754 | I25: OK TARGET_DONE | J25: OK TARGET_DONE | K25: ✓ | M25: 4 | N25: 1 | O25: 0.52 | P25: -0.25 | Q25: 0.42 | R25: SIM | S25: Aceitação | T25: 1.6775 | U25: OK TARGET_DONE | V25: OK TARGET_DONE | W25: ✓
A26: 3 | B26: 2 | C26: 0.52 | D26: 0.25 | E26: 0.35 | F26: SIM | G26: Aceitação | H26: 1.7283 | I26: OK TARGET_DONE | J26: OK TARGET_DONE | K26: ✓ | M26: 4 | N26: 2 | O26: 0.7 | P26: -0.25 | Q26: 0.35 | R26: SIM | S26: Aceitação | T26: 1.6598 | U26: OK TARGET_DONE | V26: OK TARGET_DONE | W26: ✓
A27: 3 | B27: 2 | C27: 0.72 | D27: -0.2 | E27: 0.42 | F27: SIM | G27: Aceitação | H27: 1.9629 | I27: OK TARGET_DONE | J27: OK TARGET_DONE | K27: ✓ | M27: 4 | N27: 2 | O27: 0.52 | P27: -0.25 | Q27: 0.42 | R27: SIM | S27: Aceitação | T27: 1.4706 | U27: OK TARGET_DONE | V27: OK TARGET_DONE | W27: ✓
A28: 3 | B28: 3 | C28: 0.52 | D28: 0.25 | E28: 0.35 | F28: SIM | G28: Aceitação | H28: 2.6596 | I28: OK TARGET_DONE | J28: OK TARGET_DONE | K28: ✓ | M28: 4 | N28: 3 | O28: 0.7 | P28: -0.25 | Q28: 0.35 | R28: SIM | S28: Aceitação | T28: 1.7114 | U28: OK TARGET_DONE | V28: OK TARGET_DONE | W28: ✓
A29: 3 | B29: 3 | C29: 0.72 | D29: -0.2 | E29: 0.42 | F29: SIM | G29: Aceitação | H29: 1.812 | I29: OK TARGET_DONE | J29: OK TARGET_DONE | K29: ✓ | M29: 4 | N29: 3 | O29: 0.52 | P29: -0.25 | Q29: 0.42 | R29: SIM | S29: Aceitação | T29: 1.585 | U29: OK TARGET_DONE | V29: OK TARGET_DONE | W29: ✓
A30: 3 | B30: 4 | C30: 0.52 | D30: 0.25 | E30: 0.35 | F30: SIM | G30: Aceitação | H30: 1.8268 | I30: OK TARGET_DONE | J30: OK TARGET_DONE | K30: ✓ | M30: 4 | N30: 4 | O30: 0.7 | P30: -0.25 | Q30: 0.35 | R30: SIM | S30: Aceitação | T30: 2.09 | U30: OK TARGET_DONE | V30: OK TARGET_DONE | W30: ✓
A31: 3 | B31: 4 | C31: 0.72 | D31: -0.2 | E31: 0.42 | F31: SIM | G31: Aceitação | H31: 1.5857 | I31: OK TARGET_DONE | J31: OK TARGET_DONE | K31: ✓ | M31: 4 | N31: 4 | O31: 0.52 | P31: -0.25 | Q31: 0.42 | R31: SIM | S31: Aceitação | T31: 2.9373 | U31: OK TARGET_DONE | V31: OK TARGET_DONE | W31: ✓
A32: 3 | B32: 5 | C32: 0.52 | D32: 0.25 | E32: 0.35 | F32: SIM | G32: Aceitação | H32: 2.2752 | I32: OK TARGET_DONE | J32: OK TARGET_DONE | K32: ✓ | M32: 4 | N32: 5 | O32: 0.7 | P32: -0.25 | Q32: 0.35 | R32: SIM | S32: Aceitação | T32: 1.5385 | U32: OK TARGET_DONE | V32: OK TARGET_DONE | W32: ✓
A33: 3 | B33: 5 | C33: 0.72 | D33: -0.2 | E33: 0.42 | F33: SIM | G33: Aceitação | H33: 1.6742 | I33: OK TARGET_DONE | J33: OK TARGET_DONE | K33: ✓ | M33: 4 | N33: 5 | O33: 0.52 | P33: -0.25 | Q33: 0.42 | R33: SIM | S33: Aceitação | T33: 3.0162 | U33: OK TARGET_DONE | V33: OK TARGET_DONE | W33: ✓
A34: 3 | B34: 6 | C34: 0.52 | D34: 0.25 | E34: 0.35 | F34: SIM | G34: Aceitação | H34: 1.9295 | I34: OK TARGET_DONE | J34: OK TARGET_DONE | K34: ✓ | M34: 4 | N34: 6 | O34: 0.7 | P34: -0.25 | Q34: 0.35 | R34: SIM | S34: Aceitação | T34: 1.8439 | U34: OK TARGET_DONE | V34: OK TARGET_DONE | W34: ✓
A35: 3 | B35: 6 | C35: 0.72 | D35: -0.2 | E35: 0.42 | F35: SIM | G35: Aceitação | H35: 2.9301 | I35: OK TARGET_DONE | J35: OK TARGET_DONE | K35: ✓ | M35: 4 | N35: 6 | O35: 0.52 | P35: -0.25 | Q35: 0.42 | R35: SIM | S35: Aceitação | T35: 1.7278 | U35: OK TARGET_DONE | V35: OK TARGET_DONE | W35: ✓
... A43: 3 | B43: 10 | C43: 0.72 | D43: -0.2 | E43: 0.42 | F43: SIM | G43: Aceitação | H43: 2.1536 | I43: OK TARGET_DONE | J43: OK TARGET_DONE | K43: ✓ | M43: 4 | N43: 10 | O43: 0.52 | P43: -0.25 | Q43: 0.42 | R43: SIM | S43: Aceitação | T43: 1.873 | U43: OK TARGET_DONE | V43: OK TARGET_DONE | W43: ✓
G44: Média | H44: =AVERAGE(H24:H43) -> 1.938595 | S44: Média | T44: =AVERAGE(T24:T43) -> 1.891855
A45: Ciclo | B45: Repetição | C45: Pose X | D45: Pose Y | E45: Pose Z | F45: Validação destino (SIM/NÃO) | G45: Aceitação/Rejeição | H45: Tempo resposta (ms) | I45: Resultado esperado | J45: Resultado obtido | K45: Status (✓/✗) | M45: Ciclo | N45: Repetição | O45: Pose X | P45: Pose Y | Q45: Pose Z | R45: Validação destino (SIM/NÃO) | S45: Aceitação/Rejeição | T45: Tempo resposta (ms) | U45: Resultado esperado | V45: Resultado obtido | W45: Status (✓/✗)
A46: 5 | B46: 1 | C46: 0.62 | D46: 0.18 | E46: 0.35 | F46: SIM | G46: Aceitação | H46: 1.6365 | I46: OK TARGET_DONE | J46: OK TARGET_DONE | K46: ✓ | M46: 6 | N46: 1 | O46: 0.5 | P46: -0.3 | Q46: 0.35 | R46: SIM | S46: Aceitação | T46: 1.7896 | U46: OK TARGET_DONE | V46: OK TARGET_DONE | W46: ✓
A47: 5 | B47: 1 | C47: 0.72 | D47: 0.28 | E47: 0.42 | F47: SIM | G47: Aceitação | H47: 2.0521 | I47: OK TARGET_DONE | J47: OK TARGET_DONE | K47: ✓ | M47: 6 | N47: 1 | O47: 0.75 | P47: 0.1 | Q47: 0.42 | R47: SIM | S47: Aceitação | T47: 2.6116 | U47: OK TARGET_DONE | V47: OK TARGET_DONE | W47: ✓
A48: 5 | B48: 2 | C48: 0.62 | D48: 0.18 | E48: 0.35 | F48: SIM | G48: Aceitação | H48: 1.5466 | I48: OK TARGET_DONE | J48: OK TARGET_DONE | K48: ✓ | M48: 6 | N48: 2 | O48: 0.5 | P48: -0.3 | Q48: 0.35 | R48: SIM | S48: Aceitação | T48: 1.9436 | U48: OK TARGET_DONE | V48: OK TARGET_DONE | W48: ✓
A49: 5 | B49: 2 | C49: 0.72 | D49: 0.28 | E49: 0.42 | F49: SIM | G49: Aceitação | H49: 1.6193 | I49: OK TARGET_DONE | J49: OK TARGET_DONE | K49: ✓ | M49: 6 | N49: 2 | O49: 0.75 | P49: 0.1 | Q49: 0.42 | R49: SIM | S49: Aceitação | T49: 2.198 | U49: OK TARGET_DONE | V49: OK TARGET_DONE | W49: ✓
A50: 5 | B50: 3 | C50: 0.62 | D50: 0.18 | E50: 0.35 | F50: SIM | G50: Aceitação | H50: 2.8617 | I50: OK TARGET_DONE | J50: OK TARGET_DONE | K50: ✓ | M50: 6 | N50: 3 | O50: 0.5 | P50: -0.3 | Q50: 0.35 | R50: SIM | S50: Aceitação | T50: 1.7622 | U50: OK TARGET_DONE | V50: OK TARGET_DONE | W50: ✓
A51: 5 | B51: 3 | C51: 0.72 | D51: 0.28 | E51: 0.42 | F51: SIM | G51: Aceitação | H51: 2.9683 | I51: OK TARGET_DONE | J51: OK TARGET_DONE | K51: ✓ | M51: 6 | N51: 3 | O51: 0.75 | P51: 0.1 | Q51: 0.42 | R51: SIM | S51: Aceitação | T51: 2.1009 | U51: OK TARGET_DONE | V51: OK TARGET_DONE | W51: ✓
A52: 5 | B52: 4 | C52: 0.62 | D52: 0.18 | E52: 0.35 | F52: SIM | G52: Aceitação | H52: 1.8072 | I52: OK TARGET_DONE | J52: OK TARGET_DONE | K52: ✓ | M52: 6 | N52: 4 | O52: 0.5 | P52: -0.3 | Q52: 0.35 | R52: SIM | S52: Aceitação | T52: 2.0564 | U52: OK TARGET_DONE | V52: OK TARGET_DONE | W52: ✓
A53: 5 | B53: 4 | C53: 0.72 | D53: 0.28 | E53: 0.42 | F53: SIM | G53: Aceitação | H53: 1.9119 | I53: OK TARGET_DONE | J53: OK TARGET_DONE | K53: ✓ | M53: 6 | N53: 4 | O53: 0.75 | P53: 0.1 | Q53: 0.42 | R53: SIM | S53: Aceitação | T53: 2.2185 | U53: OK TARGET_DONE | V53: OK TARGET_DONE | W53: ✓
A54: 5 | B54: 5 | C54: 0.62 | D54: 0.18 | E54: 0.35 | F54: SIM | G54: Aceitação | H54: 1.9355 | I54: OK TARGET_DONE | J54: OK TARGET_DONE | K54: ✓ | M54: 6 | N54: 5 | O54: 0.5 | P54: -0.3 | Q54: 0.35 | R54: SIM | S54: Aceitação | T54: 1.6861 | U54: OK TARGET_DONE | V54: OK TARGET_DONE | W54: ✓
...

Sheet Métricas IR_POSE
A1: Ciclo 1
A2: Repetição | B2: Tipo (Pick/Place) | C2: Pose X alvo (m) | D2: Pose Y alvo (m) | E2: Pose Z alvo (m) | F2: Pose X real (m) | H2: Pose Y real (m) | J2: Pose Z real (m) | L2: Erro X (mm) | N2: Erro Y (mm) | P2: Erro Z (mm) | R2: Erro euclidiano (mm) | T2: Desvio Padrão X (m) | V2: Desvio Padrão Y (m) | X2: Desvio Padrão Z (m) | Z2: Tempo planeamento (s) | AB2: Tempo execução (s) | AD2: Tempo total (s) | AF2: Sucesso / Falha | AG2: Trajetória alterada entre simulado e real (SIM / NÃO) | AH2: N.º tentativas | AI2: Status (✓ / ✗)
F3: Real | G3: Simulado | H3: Real | I3: Simulado | J3: Real | K3: Simulado | L3: Real | M3: Simulado | N3: Real | O3: Simulado | P3: Real | Q3: Simulado | R3: Real | S3: Simulado | T3: Real | U3: Simulado | V3: Real | W3: Simulado | X3: Real | Y3: Simulado | Z3: Simulado | AA3: Real | AB3: Simulado | AC3: Real | AD3: Simulado | AE3: Real
A4: 1 | B4: Pick | C4: 0.55 | D4: -0.2 | E4: 0.35 | F4: 0.5503 | G4: 0.5499 | H4: -0.1994 | I4: -0.2004 | J4: 0.3999 | K4: 0.35 | L4: =ABS(F4-C4)*1000 -> 0.3 | M4: =ABS(G4-C4)*1000 -> 0.1 | N4: =ABS(H4-D4)*1000 -> 0.6 | O4: =ABS(I4-D4)*1000 -> 0.4 | P4: =ABS(J4-E4)*1000 -> 49.9 | Q4: =ABS(K4-E4)*1000 -> 0 | R4: =SQRT(SUMSQ(L4,N4,P4)) -> 49.904509 | S4: =SQRT(SUMSQ(M4,O4,Q4)) -> 0.41231056 | T4: =_xlfn.STDEV.S(F4:F23) -> 0.076960531 | U4: =_xlfn.STDEV.S(G4:G23) -> 0.07694431 | V4: =_xlfn.STDEV.S(H4:H23) -> 0.20485822 | W4: =_xlfn.STDEV.S(I4:I23) -> 0.20525263 | X4: =_xlfn.STDEV.S(J4:J23) -> 0.036022263 | Y4: =_xlfn.STDEV.S(K4:K23) -> 0.03583934 | Z4: 0.5499 | AA4: 0.5568 | AB4: 5.7748 | AC4: 8.6633 | AD4: =AB4+Z4 -> 6.3247 | AE4: =AC4+AA4 -> 9.2201 | AF4: Sucesso | AG4: NÃO | AH4: 1 | AI4: ✓
A5: 1 | B5: Place | C5: 0.7 | D5: 0.2 | E5: 0.42 | F5: 0.7 | G5: 0.7001 | H5: 0.1985 | I5: 0.2003 | J5: 0.4704 | K5: 0.4198 | L5: =ABS(F5-C5)*1000 -> 0 | M5: =ABS(G5-C5)*1000 -> 0.1 | N5: =ABS(H5-D5)*1000 -> 1.5 | O5: =ABS(I5-D5)*1000 -> 0.3 | P5: =ABS(J5-E5)*1000 -> 50.4 | Q5: =ABS(K5-E5)*1000 -> 0.2 | R5: =SQRT(SUMSQ(L5,N5,P5)) -> 50.422316 | S5: =SQRT(SUMSQ(M5,O5,Q5)) -> 0.37416574 | Z5: 0.5377 | AA5: 0.5452 | AB5: 7.0453 | AC5: 8.9175 | AD5: =AB5+Z5 -> 7.583 | AE5: =AC5+AA5 -> 9.4627 | AF5: Sucesso | AG5: NÃO | AH5: 1 | AI5: ✓
A6: 2 | B6: Pick | C6: 0.55 | D6: -0.2 | E6: 0.35 | F6: 0.5495 | G6: 0.5503 | H6: -0.2007 | I6: -0.2005 | J6: 0.4004 | K6: 0.3496 | L6: =ABS(F6-C6)*1000 -> 0.5 | M6: =ABS(G6-C6)*1000 -> 0.3 | N6: =ABS(H6-D6)*1000 -> 0.7 | O6: =ABS(I6-D6)*1000 -> 0.5 | P6: =ABS(J6-E6)*1000 -> 50.4 | Q6: =ABS(K6-E6)*1000 -> 0.4 | R6: =SQRT(SUMSQ(L6,N6,P6)) -> 50.407341 | S6: =SQRT(SUMSQ(M6,O6,Q6)) -> 0.70710678 | Z6: 0.5476 | AA6: 0.5397 | AB6: 7.0447 | AC6: 8.3768 | AD6: =AB6+Z6 -> 7.5923 | AE6: =AC6+AA6 -> 8.9165 | AF6: Sucesso | AG6: NÃO | AH6: 1 | AI6: ✓
A7: 2 | B7: Place | C7: 0.7 | D7: 0.2 | E7: 0.42 | F7: 0.7007 | G7: 0.7005 | H7: 0.199 | I7: 0.2004 | J7: 0.4701 | K7: 0.4204 | L7: =ABS(F7-C7)*1000 -> 0.7 | M7: =ABS(G7-C7)*1000 -> 0.5 | N7: =ABS(H7-D7)*1000 -> 1 | O7: =ABS(I7-D7)*1000 -> 0.4 | P7: =ABS(J7-E7)*1000 -> 50.1 | Q7: =ABS(K7-E7)*1000 -> 0.4 | R7: =SQRT(SUMSQ(L7,N7,P7)) -> 50.114868 | S7: =SQRT(SUMSQ(M7,O7,Q7)) -> 0.75498344 | Z7: 0.54663 | AA7: 0.5287 | AB7: 7.0579 | AC7: 7.2565 | AD7: =AB7+Z7 -> 7.60453 | AE7: =AC7+AA7 -> 7.7852 | AF7: Sucesso | AG7: NÃO | AH7: 1 | AI7: ✓
A8: 3 | B8: Pick | C8: 0.55 | D8: -0.2 | E8: 0.35 | F8: 0.5497 | G8: 0.5494 | H8: -0.1996 | I8: -0.1995 | J8: 0.4004 | K8: 0.3504 | L8: =ABS(F8-C8)*1000 -> 0.3 | M8: =ABS(G8-C8)*1000 -> 0.6 | N8: =ABS(H8-D8)*1000 -> 0.4 | O8: =ABS(I8-D8)*1000 -> 0.5 | P8: =ABS(J8-E8)*1000 -> 50.4 | Q8: =ABS(K8-E8)*1000 -> 0.4 | R8: =SQRT(SUMSQ(L8,N8,P8)) -> 50.40248 | S8: =SQRT(SUMSQ(M8,O8,Q8)) -> 0.87749644 | Z8: 0.5506 | AA8: 0.5258 | AB8: 7.0635 | AC8: 8.7325 | AD8: =AB8+Z8 -> 7.6141 | AE8: =AC8+AA8 -> 9.2583 | AF8: Sucesso | AG8: NÃO | AH8: 1 | AI8: ✓
A9: 3 | B9: Place | C9: 0.7 | D9: 0.2 | E9: 0.42 | F9: 0.701 | G9: 0.7002 | H9: 0.1992 | I9: 0.1996 | J9: 0.4702 | K9: 0.4204 | L9: =ABS(F9-C9)*1000 -> 1 | M9: =ABS(G9-C9)*1000 -> 0.2 | N9: =ABS(H9-D9)*1000 -> 0.8 | O9: =ABS(I9-D9)*1000 -> 0.4 | P9: =ABS(J9-E9)*1000 -> 50.2 | Q9: =ABS(K9-E9)*1000 -> 0.4 | R9: =SQRT(SUMSQ(L9,N9,P9)) -> 50.216332 | S9: =SQRT(SUMSQ(M9,O9,Q9)) -> 0.6 | Z9: 0.6024 | AA9: 0.5479 | AB9: 7.0443 | AC9: 9.6724 | AD9: =AB9+Z9 -> 7.6467 | AE9: =AC9+AA9 -> 10.2203 | AF9: Sucesso | AG9: NÃO | AH9: 1 | AI9: ✓
A10: 4 | B10: Pick | C10: 0.55 | D10: -0.2 | E10: 0.35 | F10: 0.5497 | G10: 0.5496 | H10: -0.2005 | I10: -0.1995 | J10: 0.3992 | K10: 0.3504 | L10: =ABS(F10-C10)*1000 -> 0.3 | M10: =ABS(G10-C10)*1000 -> 0.4 | N10: =ABS(H10-D10)*1000 -> 0.5 | O10: =ABS(I10-D10)*1000 -> 0.5 | P10: =ABS(J10-E10)*1000 -> 49.2 | Q10: =ABS(K10-E10)*1000 -> 0.4 | R10: =SQRT(SUMSQ(L10,N10,P10)) -> 49.203455 | S10: =SQRT(SUMSQ(M10,O10,Q10)) -> 0.75498344 | Z10: 0.5506 | AA10: 0.5359 | AB10: 7.0635 | AC10: 8.8219 | AD10: =AB10+Z10 -> 7.6141 | AE10: =AC10+AA10 -> 9.3578 | AF10: Sucesso | AG10: NÃO | AH10: 1 | AI10: ✓
A11: 4 | B11: Place | C11: 0.7 | D11: 0.2 | E11: 0.42 | F11: 0.6989 | G11: 0.7002 | H11: 0.1996 | I11: 0.1996 | J11: 0.4698 | K11: 0.4204 | L11: =ABS(F11-C11)*1000 -> 1.1 | M11: =ABS(G11-C11)*1000 -> 0.2 | N11: =ABS(H11-D11)*1000 -> 0.4 | O11: =ABS(I11-D11)*1000 -> 0.4 | P11: =ABS(J11-E11)*1000 -> 49.8 | Q11: =ABS(K11-E11)*1000 -> 0.4 | R11: =SQRT(SUMSQ(L11,N11,P11)) -> 49.813753 | S11: =SQRT(SUMSQ(M11,O11,Q11)) -> 0.6 | Z11: 0.6024 | AA11: 0.4331 | AB11: 7.0443 | AC11: 7.2138 | AD11: =AB11+Z11 -> 7.6467 | AE11: =AC11+AA11 -> 7.6469 | AF11: Sucesso | AG11: NÃO | AH11: 1 | AI11: ✓
A12: 5 | B12: Pick | C12: 0.55 | D12: -0.2 | E12: 0.35 | F12: 0.5495 | G12: 0.5503 | H12: -0.2008 | I12: -0.2008 | J12: 0.4012 | K12: 0.3496 | L12: =ABS(F12-C12)*1000 -> 0.5 | M12: =ABS(G12-C12)*1000 -> 0.3 | N12: =ABS(H12-D12)*1000 -> 0.8 | O12: =ABS(I12-D12)*1000 -> 0.8 | P12: =ABS(J12-E12)*1000 -> 51.2 | Q12: =ABS(K12-E12)*1000 -> 0.4 | R12: =SQRT(SUMSQ(L12,N12,P12)) -> 51.208691 | S12: =SQRT(SUMSQ(M12,O12,Q12)) -> 0.94339811 | Z12: 0.5338 | AA12: 0.5404 | AB12: 7.0512 | AC12: 8.3639 | AD12: =AB12+Z12 -> 7.585 | AE12: =AC12+AA12 -> 8.9043 | AF12: Sucesso | AG12: NÃO | AH12: 1 | AI12: ✓
A13: 5 | B13: Place | C13: 0.7 | D13: 0.2 | E13: 0.42 | F13: 0.7001 | G13: 0.6996 | H13: 0.1989 | I13: 0.2006 | J13: 0.4709 | K13: 0.4201 | L13: =ABS(F13-C13)*1000 -> 0.1 | M13: =ABS(G13-C13)*1000 -> 0.4 | N13: =ABS(H13-D13)*1000 -> 1.1 | O13: =ABS(I13-D13)*1000 -> 0.6 | P13: =ABS(J13-E13)*1000 -> 50.9 | Q13: =ABS(K13-E13)*1000 -> 0.1 | R13: =SQRT(SUMSQ(L13,N13,P13)) -> 50.911983 | S13: =SQRT(SUMSQ(M13,O13,Q13)) -> 0.72801099 | Z13: 0.6472 | AA13: 0.5284 | AB13: 7.0461 | AC13: 7.2703 | AD13: =AB13+Z13 -> 7.6933 | AE13: =AC13+AA13 -> 7.7987 | AF13: Sucesso | AG13: NÃO | AH13: 1 | AI13: ✓
A14: 6 | B14: Pick | C14: 0.55 | D14: -0.2 | E14: 0.35 | F14: 0.55 | G14: 0.5499 | H14: -0.1994 | I14: -0.2007 | J14: 0.4004 | K14: 0.3501 | L14: =ABS(F14-C14)*1000 -> 0 | M14: =ABS(G14-C14)*1000 -> 0.1 | N14: =ABS(H14-D14)*1000 -> 0.6 | O14: =ABS(I14-D14)*1000 -> 0.7 | P14: =ABS(J14-E14)*1000 -> 50.4 | Q14: =ABS(K14-E14)*1000 -> 0.1 | R14: =SQRT(SUMSQ(L14,N14,P14)) -> 50.403571 | S14: =SQRT(SUMSQ(M14,O14,Q14)) -> 0.71414284 | Z14: 0.5451 | AA14: 0.558 | AB14: 7.057 | AC14: 9.6507 | AD14: =AB14+Z14 -> 7.6021 | AE14: =AC14+AA14 -> 10.2087 | AF14: Sucesso | AG14: NÃO | AH14: 1 | AI14: ✓
A15: 6 | B15: Place | C15: 0.7 | D15: 0.2 | E15: 0.42 | F15: 0.7004 | G15: 0.6997 | H15: 0.2001 | I15: 0.1997 | J15: 0.4714 | K15: 0.4195 | L15: =ABS(F15-C15)*1000 -> 0.4 | M15: =ABS(G15-C15)*1000 -> 0.3 | N15: =ABS(H15-D15)*1000 -> 0.1 | O15: =ABS(I15-D15)*1000 -> 0.3 | P15: =ABS(J15-E15)*1000 -> 51.4 | Q15: =ABS(K15-E15)*1000 -> 0.5 | R15: =SQRT(SUMSQ(L15,N15,P15)) -> 51.401654 | S15: =SQRT(SUMSQ(M15,O15,Q15)) -> 0.65574385 | Z15: 0.5509 | AA15: 0.5398 | AB15: 7.0517 | AC15: 9.037 | AD15: =AB15+Z15 -> 7.6026 | AE15: =AC15+AA15 -> 9.5768 | AF15: Sucesso | AG15: NÃO | AH15: 1 | AI15: ✓
A16: 7 | B16: Pick | C16: 0.55 | D16: -0.2 | E16: 0.35 | F16: 0.5501 | G16: 0.5505 | H16: -0.1993 | I16: -0.2001 | J16: 0.4002 | K16: 0.3504 | L16: =ABS(F16-C16)*1000 -> 0.1 | M16: =ABS(G16-C16)*1000 -> 0.5 | N16: =ABS(H16-D16)*1000 -> 0.7 | O16: =ABS(I16-D16)*1000 -> 0.1 | P16: =ABS(J16-E16)*1000 -> 50.2 | Q16: =ABS(K16-E16)*1000 -> 0.4 | R16: =SQRT(SUMSQ(L16,N16,P16)) -> 50.20498 | S16: =SQRT(SUMSQ(M16,O16,Q16)) -> 0.64807407 | Z16: 0.5222 | AA16: 0.5557 | AB16: 7.0449 | AC16: 8.8342 | AD16: =AB16+Z16 -> 7.5671 | AE16: =AC16+AA16 -> 9.3899 | AF16: Sucesso | AG16: NÃO | AH16: 1 | AI16: ✓
... A23: 10 | B23: Place | C23: 0.7 | D23: 0.2 | E23: 0.42 | F23: 0.7003 | G23: 0.6993 | H23: 0.1984 | I23: 0.2004 | J23: 0.4698 | K23: 0.4195 | L23: =ABS(F23-C23)*1000 -> 0.3 | M23: =ABS(G23-C23)*1000 -> 0.7 | N23: =ABS(H23-D23)*1000 -> 1.6 | O23: =ABS(I23-D23)*1000 -> 0.4 | P23: =ABS(J23-E23)*1000 -> 49.8 | Q23: =ABS(K23-E23)*1000 -> 0.5 | R23: =SQRT(SUMSQ(L23,N23,P23)) -> 49.826599 | S23: =SQRT(SUMSQ(M23,O23,Q23)) -> 0.9486833 | Z23: 0.6486 | AA23: 0.5583 | AB23: 7.0392 | AC23: 9.2757 | AD23: =AB23+Z23 -> 7.6878 | AE23: =AC23+AA23 -> 9.834 | AF23: Sucesso | AG23: NÃO | AH23: 1 | AI23: ✓
A24: Diferença entre real e simulado | F24: =AVERAGE(F4:F23)-AVERAGE(G4:G23) -> 7.5e-05 | H24: =AVERAGE(H4:H23)-AVERAGE(I4:I23) -> -0.000225 | J24: =AVERAGE(J4:J23)-AVERAGE(K4:K23) -> 0.050125 | L24: =AVERAGE(L4:L23)-AVERAGE(M4:M23) -> 0.065 | N24: =AVERAGE(N4:N23)-AVERAGE(O4:O23) -> 0.275 | P24: =AVERAGE(P4:P23)-AVERAGE(Q4:Q23) -> 49.845 | R24: =AVERAGE(R4:R23)-AVERAGE(S4:S23) -> 49.491955 | T24: =AVERAGE(T4:T23)-AVERAGE(U4:U23) -> 1.622072e-05 | V24: =AVERAGE(V4:V23)-AVERAGE(W4:W23) -> -0.00039441423 | X24: =AVERAGE(X4:X23)-AVERAGE(Y4:Y23) -> 0.00018292288 | Z24: =AVERAGE(AA4:AA23)-AVERAGE(Z4:Z23) -> -0.0241515 | AB24: =AVERAGE(AC4:AC23)-AVERAGE(AB4:AB23) -> 1.772625 | AD24: =AVERAGE(AE4:AE23)-AVERAGE(AD4:AD23) -> 1.7484735
A25: Ciclo 2
A26: Repetição | B26: Tipo (Pick/Place) | C26: Pose X alvo (m) | D26: Pose Y alvo (m) | E26: Pose Z alvo (m) | F26: Pose X real (m) | H26: Pose Y real (m) | J26: Pose Z real (m) | L26: Erro X (mm) | N26: Erro Y (mm) | P26: Erro Z (mm) | R26: Erro euclidiano (mm) | T26: Desvio Padrão X (m) | V26: Desvio Padrão Y (m) | X26: Desvio Padrão Z (m) | Z26: Tempo planeamento (s) | AB26: Tempo execução (s) | AD26: Tempo total (s) | AF26: Sucesso / Falha | AG26: Trajetória alterada entre simulado e real (SIM / NÃO) | AH26: N.º tentativas | AI26: Status (✓ / ✗)
F27: Real | G27: Simulado | H27: Real | I27: Simulado | J27: Real | K27: Simulado | L27: Real | M27: Simulado | N27: Real | O27: Simulado | P27: Real | Q27: Simulado | R27: Real | S27: Simulado | T27: Real | U27: Simulado | V27: Real | W27: Simulado | X27: Real | Y27: Simulado | Z27: Simulado | AA27: Real | AB27: Simulado | AC27: Real | AD27: Simulado | AE27: Real
A28: 1 | B28: Pick | C28: 0.6 | D28: 0 | E28: 0.35 | F28: 0.5998 | G28: 0.6 | H28: 0.0003 | I28: 0.0002 | J28: 0.4 | K28: 0.3495 | L28: =ABS(F28-C28)*1000 -> 0.2 | M28: =ABS(G28-C28)*1000 -> 0 | N28: =ABS(H28-D28)*1000 -> 0.3 | O28: =ABS(I28-D28)*1000 -> 0.2 | P28: =ABS(J28-E28)*1000 -> 50 | Q28: =ABS(K28-E28)*1000 -> 0.5 | R28: =SQRT(SUMSQ(L28,N28,P28)) -> 50.0013 | S28: =SQRT(SUMSQ(M28,O28,Q28)) -> 0.53851648 | T28: =_xlfn.STDEV.S(F28:F47) -> 0.051401242 | U28: =_xlfn.STDEV.S(G28:G47) -> 0.051309962 | V28: =_xlfn.STDEV.S(H28:H47) -> 0.12814092 | W28: =_xlfn.STDEV.S(I28:I47) -> 0.12828413 | X28: =_xlfn.STDEV.S(J28:J47) -> 0.035944176 | Y28: =_xlfn.STDEV.S(K28:K47) -> 0.035865293 | Z28: 0.5589 | AA28: 0.567 | AB28: 7.0352 | AC28: 8.8171 | AD28: =AB28+Z28 -> 7.5941 | AE28: =AC28+AA28 -> 9.3841 | AF28: Sucesso | AG28: NÃO | AH28: 1 | AI28: ✓
A29: 1 | B29: Place | C29: 0.5 | D29: 0.25 | E29: 0.42 | F29: 0.4993 | G29: 0.5 | H29: 0.2504 | I29: 0.2506 | J29: 0.4696 | K29: 0.4204 | L29: =ABS(F29-C29)*1000 -> 0.7 | M29: =ABS(G29-C29)*1000 -> 0 | N29: =ABS(H29-D29)*1000 -> 0.4 | O29: =ABS(I29-D29)*1000 -> 0.6 | P29: =ABS(J29-E29)*1000 -> 49.6 | Q29: =ABS(K29-E29)*1000 -> 0.4 | R29: =SQRT(SUMSQ(L29,N29,P29)) -> 49.606552 | S29: =SQRT(SUMSQ(M29,O29,Q29)) -> 0.72111026 | Z29: 0.5621 | AA29: 0.5654 | AB29: 7.0342 | AC29: 10.9812 | AD29: =AB29+Z29 -> 7.5963 | AE29: =AC29+AA29 -> 11.5466 | AF29: Sucesso | AG29: NÃO | AH29: 1 | AI29: ✓
A30: 2 | B30: Pick | C30: 0.6 | D30: 0 | E30: 0.35 | F30: 0.6005 | G30: 0.5998 | H30: -0.0001 | I30: -0.0007 | J30: 0.4003 | K30: 0.3503 | L30: =ABS(F30-C30)*1000 -> 0.5 | M30: =ABS(G30-C30)*1000 -> 0.2 | N30: =ABS(H30-D30)*1000 -> 0.1 | O30: =ABS(I30-D30)*1000 -> 0.7 | P30: =ABS(J30-E30)*1000 -> 50.3 | Q30: =ABS(K30-E30)*1000 -> 0.3 | R30: =SQRT(SUMSQ(L30,N30,P30)) -> 50.302584 | S30: =SQRT(SUMSQ(M30,O30,Q30)) -> 0.78740079 | Z30: 0.5447 | AA30: 0.567 | AB30: 7.045 | AC30: 11.7254 | AD30: =AB30+Z30 -> 7.5897 | AE30: =AC30+AA30 -> 12.2924 | AF30: Sucesso | AG30: NÃO | AH30: 1 | AI30: ✓
A31: 2 | B31: Place | C31: 0.5 | D31: 0.25 | E31: 0.42 | F31: 0.5002 | G31: 0.4998 | H31: 0.2498 | I31: 0.2509 | J31: 0.47 | K31: 0.42 | L31: =ABS(F31-C31)*1000 -> 0.2 | M31: =ABS(G31-C31)*1000 -> 0.2 | N31: =ABS(H31-D31)*1000 -> 0.2 | O31: =ABS(I31-D31)*1000 -> 0.9 | P31: =ABS(J31-E31)*1000 -> 50 | Q31: =ABS(K31-E31)*1000 -> 0 | R31: =SQRT(SUMSQ(L31,N31,P31)) -> 50.0008 | S31: =SQRT(SUMSQ(M31,O31,Q31)) -> 0.92195445 | Z31: 0.5554 | AA31: 0.5299 | AB31: 7.0515 | AC31: 7.184 | AD31: =AB31+Z31 -> 7.6069 | AE31: =AC31+AA31 -> 7.7139 | AF31: Sucesso | AG31: NÃO | AH31: 1 | AI31: ✓
A32: 3 | B32: Pick | C32: 0.6 | D32: 0 | E32: 0.35 | F32: 0.5998 | G32: 0.6004 | H32: -0.0008 | I32: 0.0006 | J32: 0.3996 | K32: 0.3501 | L32: =ABS(F32-C32)*1000 -> 0.2 | M32: =ABS(G32-C32)*1000 -> 0.4 | N32: =ABS(H32-D32)*1000 -> 0.8 | O32: =ABS(I32-D32)*1000 -> 0.6 | P32: =ABS(J32-E32)*1000 -> 49.6 | Q32: =ABS(K32-E32)*1000 -> 0.1 | R32: =SQRT(SUMSQ(L32,N32,P32)) -> 49.606854 | S32: =SQRT(SUMSQ(M32,O32,Q32)) -> 0.72801099 | Z32: 0.5447 | AA32: 0.5384 | AB32: 7.0394 | AC32: 8.8259 | AD32: =AB32+Z32 -> 7.5841 | AE32: =AC32+AA32 -> 9.3643 | AF32: Sucesso | AG32: NÃO | AH32: 1 | AI32: ✓
A33: 3 | B33: Place | C33: 0.5 | D33: 0.25 | E33: 0.42 | F33: 0.499 | G33: 0.5003 | H33: 0.249 | I33: 0.2501 | J33: 0.4694 | K33: 0.4192 | L33: =ABS(F33-C33)*1000 -> 1 | M33: =ABS(G33-C33)*1000 -> 0.3 | N33: =ABS(H33-D33)*1000 -> 1 | O33: =ABS(I33-D33)*1000 -> 0.1 | P33: =ABS(J33-E33)*1000 -> 49.4 | Q33: =ABS(K33-E33)*1000 -> 0.8 | R33: =SQRT(SUMSQ(L33,N33,P33)) -> 49.420239 | S33: =SQRT(SUMSQ(M33,O33,Q33)) -> 0.86023253 | Z33: 0.5418 | AA33: 0.5394 | AB33: 7.0476 | AC33: 7.13244 | AD33: =AB33+Z33 -> 7.5894 | AE33: =AC33+AA33 -> 7.67184 | AF33: Sucesso | AG33: NÃO | AH33: 1 | AI33: ✓
A34: 4 | B34: Pick | C34: 0.6 | D34: 0 | E34: 0.35 | F34: 0.6011 | G34: 0.6005 | H34: -0.0004 | I34: 0.0004 | J34: 0.4009 | K34: 0.3495 | L34: =ABS(F34-C34)*1000 -> 1.1 | M34: =ABS(G34-C34)*1000 -> 0.5 | N34: =ABS(H34-D34)*1000 -> 0.4 | O34: =ABS(I34-D34)*1000 -> 0.4 | P34: =ABS(J34-E34)*1000 -> 50.9 | Q34: =ABS(K34-E34)*1000 -> 0.5 | R34: =SQRT(SUMSQ(L34,N34,P34)) -> 50.913456 | S34: =SQRT(SUMSQ(M34,O34,Q34)) -> 0.81240384 | Z34: 0.5378 | AA34: 0.5373 | AB34: 7.0307 | AC34: 8.3726 | AD34: =AB34+Z34 -> 7.5685 | AE34: =AC34+AA34 -> 8.9099 | AF34: Sucesso | AG34: NÃO | AH34: 1 | AI34: ✓
A35: 4 | B35: Place | C35: 0.5 | D35: 0.25 | E35: 0.42 | F35: 0.5001 | G35: 0.5003 | H35: 0.2487 | I35: 0.2493 | J35: 0.4707 | K35: 0.4195 | L35: =ABS(F35-C35)*1000 -> 0.1 | M35: =ABS(G35-C35)*1000 -> 0.3 | N35: =ABS(H35-D35)*1000 -> 1.3 | O35: =ABS(I35-D35)*1000 -> 0.7 | P35: =ABS(J35-E35)*1000 -> 50.7 | Q35: =ABS(K35-E35)*1000 -> 0.5 | R35: =SQRT(SUMSQ(L35,N35,P35)) -> 50.716763 | S35: =SQRT(SUMSQ(M35,O35,Q35)) -> 0.91104336 | Z35: 0.5494 | AA35: 0.5367 | AB35: 7.0617 | AC35: 7.1747 | AD35: =AB35+Z35 -> 7.6111 | AE35: =AC35+AA35 -> 7.7114 | AF35: Sucesso | AG35: NÃO | AH35: 1 | AI35: ✓
A36: 5 | B36: Pick | C36: 0.6 | D36: 0 | E36: 0.35 | F36: 0.6007 | G36: 0.6002 | H36: -0.0006 | I36: 0.0001 | J36: 0.401 | K36: 0.3503 | L36: =ABS(F36-C36)*1000 -> 0.7 | M36: =ABS(G36-C36)*1000 -> 0.2 | N36: =ABS(H36-D36)*1000 -> 0.6 | O36: =ABS(I36-D36)*1000 -> 0.1 | P36: =ABS(J36-E36)*1000 -> 51 | Q36: =ABS(K36-E36)*1000 -> 0.3 | R36: =SQRT(SUMSQ(L36,N36,P36)) -> 51.008333 | S36: =SQRT(SUMSQ(M36,O36,Q36)) -> 0.37416574 | Z36: 0.5459 | AA36: 0.541 | AB36: 7.0456 | AC36: 8.3183 | AD36: =AB36+Z36 -> 7.5915 | AE36: =AC36+AA36 -> 8.8593 | AF36: Sucesso | AG36: NÃO | AH36: 1 | AI36: ✓
A37: 5 | B37: Place | C37: 0.5 | D37: 0.25 | E37: 0.42 | F37: 0.4999 | G37: 0.5005 | H37: 0.2498 | I37: 0.2498 | J37: 0.4711 | K37: 0.4205 | L37: =ABS(F37-C37)*1000 -> 0.1 | M37: =ABS(G37-C37)*1000 -> 0.5 | N37: =ABS(H37-D37)*1000 -> 0.2 | O37: =ABS(I37-D37)*1000 -> 0.2 | P37: =ABS(J37-E37)*1000 -> 51.1 | Q37: =ABS(K37-E37)*1000 -> 0.5 | R37: =SQRT(SUMSQ(L37,N37,P37)) -> 51.100489 | S37: =SQRT(SUMSQ(M37,O37,Q37)) -> 0.73484692 | Z37: 0.5408 | AA37: 0.5265 | AB37: 7.0603 | AC37: 7.1853 | AD37: =AB37+Z37 -> 7.6011 | AE37: =AC37+AA37 -> 7.7118 | AF37: Sucesso | AG37: NÃO | AH37: 1 | AI37: ✓
A38: 6 | B38: Pick | C38: 0.6 | D38: 0 | E38: 0.35 | F38: 0.6003 | G38: 0.6004 | H38: 0.0004 | I38: 0 | J38: 0.3999 | K38: 0.3495 | L38: =ABS(F38-C38)*1000 -> 0.3 | M38: =ABS(G38-C38)*1000 -> 0.4 | N38: =ABS(H38-D38)*1000 -> 0.4 | O38: =ABS(I38-D38)*1000 -> 0 | P38: =ABS(J38-E38)*1000 -> 49.9 | Q38: =ABS(K38-E38)*1000 -> 0.5 | R38: =SQRT(SUMSQ(L38,N38,P38)) -> 49.902505 | S38: =SQRT(SUMSQ(M38,O38,Q38)) -> 0.64031242 | Z38: 0.5648 | AA38: 0.5476 | AB38: 7.0386 | AC38: 8.8632 | AD38: =AB38+Z38 -> 7.6034 | AE38: =AC38+AA38 -> 9.4108 | AF38: Sucesso | AG38: NÃO | AH38: 1 | AI38: ✓
A39: 6 | B39: Place | C39: 0.5 | D39: 0.25 | E39: 0.42 | F39: 0.5017 | G39: 0.4997 | H39: 0.2495 | I39: 0.2497 | J39: 0.4704 | K39: 0.4202 | L39: =ABS(F39-C39)*1000 -> 1.7 | M39: =ABS(G39-C39)*1000 -> 0.3 | N39: =ABS(H39-D39)*1000 -> 0.5 | O39: =ABS(I39-D39)*1000 -> 0.3 | P39: =ABS(J39-E39)*1000 -> 50.4 | Q39: =ABS(K39-E39)*1000 -> 0.2 | R39: =SQRT(SUMSQ(L39,N39,P39)) -> 50.431141 | S39: =SQRT(SUMSQ(M39,O39,Q39)) -> 0.46904158 | Z39: 0.5435 | AA39: 0.5656 | AB39: 7.0618 | AC39: 8.9458 | AD39: =AB39+Z39 -> 7.6053 | AE39: =AC39+AA39 -> 9.5114 | AF39: Sucesso | AG39: NÃO | AH39: 1 | AI39: ✓
A40: 7 | B40: Pick | C40: 0.6 | D40: 0 | E40: 0.35 | F40: 0.6002 | G40: 0.6001 | H40: 0.0006 | I40: 0.0009 | J40: 0.4008 | K40: 0.35 | L40: =ABS(F40-C40)*1000 -> 0.2 | M40: =ABS(G40-C40)*1000 -> 0.1 | N40: =ABS(H40-D40)*1000 -> 0.6 | O40: =ABS(I40-D40)*1000 -> 0.9 | P40: =ABS(J40-E40)*1000 -> 50.8 | Q40: =ABS(K40-E40)*1000 -> 0 | R40: =SQRT(SUMSQ(L40,N40,P40)) -> 50.803937 | S40: =SQRT(SUMSQ(M40,O40,Q40)) -> 0.90553851 | Z40: 0.542 | AA40: 0.5655 | AB40: 7.0557 | AC40: 9.6304 | AD40: =AB40+Z40 -> 7.5977 | AE40: =AC40+AA40 -> 10.1959 | AF40: Sucesso | AG40: NÃO | AH40: 1 | AI40: ✓
... A47: 10 | B47: Place | C47: 0.5 | D47: 0.25 | E47: 0.42 | F47: 0.5011 | G47: 0.5003 | H47: 0.249 | I47: 0.2502 | J47: 0.4705 | K47: 0.4198 | L47: =ABS(F47-C47)*1000 -> 1.1 | M47: =ABS(G47-C47)*1000 -> 0.3 | N47: =ABS(H47-D47)*1000 -> 1 | O47: =ABS(I47-D47)*1000 -> 0.2 | P47: =ABS(J47-E47)*1000 -> 50.5 | Q47: =ABS(K47-E47)*1000 -> 0.2 | R47: =SQRT(SUMSQ(L47,N47,P47)) -> 50.521876 | S47: =SQRT(SUMSQ(M47,O47,Q47)) -> 0.41231056 | Z47: 0.5474 | AA47: 0.4222 | AB47: 7.0403 | AC47: 7.0995 | AD47: =AB47+Z47 -> 7.5877 | AE47: =AC47+AA47 -> 7.5217 | AF47: Sucesso | AG47: NÃO | AH47: 1 | AI47: ✓
