Workbook

Sheet Definição obstáculos
A1: Definição dos obstáculos físicos e respetiva posição de colocação
A2: ID | B2: Objeto físico | C2: Comprimento (m) | D2: Largura (m) | E2: Altura (m) | F2: Centro X (m) | G2: Centro Y (m) | H2: Centro Z (m) | I2: Referencial | J2: Onde colocar fisicamente | K2: Comando para aparecer no RViz/Planning Scene
A3: OBS_H_P1 | B3: Caixa de sapatos horizontal | C3: 0.355 | D3: 0.255 | E3: 0.12 | F3: 0.932 | G3: 0.239 | H3: -0.18 | I3: base (45° rotação) | J3: Em cima da mesa — posição 1 | K3: ros2 topic pub --once /obstaculo_cmd std_msgs/msg/String "{data: 'ADD A OBS_H 0.9320 0.2390 -0.1800'}"
A4: OBS_H_P2 | B4: Caixa de sapatos horizontal | C4: 0.355 | D4: 0.255 | E4: 0.12 | F4: 0.577 | G4: 0.757 | H4: -0.18 | I4: base (45° rotação) | J4: Em cima da mesa no limite esquerdo da mesa — posição 2,5cm de extermidade | K4: ros2 topic pub --once /obstaculo_cmd std_msgs/msg/String "{data: 'ADD B OBS_H 0.5770 0.7570 -0.1800'}"
A5: OBS_H_P3 | B5: Caixa de sapatos horizontal | C5: 0.355 | D5: 0.255 | E5: 0.12 | F5: 1.45 | G5: -0.12 | H5: -0.18 | I5: base (45° rotação) | J5: Em cima da mesa encostado à parede direita -posição 3 | K5: ros2 topic pub --once /obstaculo_cmd std_msgs/msg/String "{data: 'ADD C OBS_H 1.4500 -0.1200 -0.1800'}"
A6: OBS_V_P1 | B6: Caixa de sapatos vertical | C6: 0.255 | D6: 0.12 | E6: 0.355 | F6: 1.017 | G6: 0.322 | H6: -0.0625 | I6: base (45° rotação) | J6: Em cima da mesa centrada— posição vertical 1 Medidas:centro nos 90cm riscas do meio a bater | K6: ros2 topic pub --once /obstaculo_cmd std_msgs/msg/String "{data: 'ADD D OBS_V 1.0170 0.3220 -0.0625'}"
A7: OBS_V_P2 | B7: Caixa de sapatos vertical | C7: 0.255 | D7: 0.12 | E7: 0.355 | F7: 0.495 | G7: 0.845 | H7: -0.0625 | I7: base (45° rotação) | J7: Em cima da mesa na extermidade esquerda da mesa — posição vertical 2 EXTERMIDADE ESQUERDA A 8,5CM | K7: ros2 topic pub --once /obstaculo_cmd std_msgs/msg/String "{data: 'ADD E OBS_V 0.4950 0.8450 -0.0625'}"
A8: OBS_H_P4 | B8: Caixa de sapatos horizontal | C8: 0.355 | D8: 0.255 | E8: 0.12 | F8: 1.02 | G8: 0.32 | H8: -0.18 | I8: base (45° rotação) | J8: Em cima da mesa centrada— posição horizontal 4 | K8: ros2 topic pub --once /obstaculo_cmd std_msgs/msg/String "{data: 'ADD F OBS_H 1.0200 0.3200 -0.1800'}"
A9: OBS_H_P5 | B9: Caixa de sapatos horizontal | C9: 0.355 | D9: 0.255 | E9: 0.12 | F9: 0.577 | G9: 0.757 | H9: -0.059 | I9: base (45° rotação) | J9: Em cima da mesa no limite esquerdo da mesa — posição 5 | K9: ros2 topic pub --once /obstaculo_cmd std_msgs/msg/String "{data: 'ADD G OBS_H 0.5770 0.7570 -0.0590'}"

Sheet Testes obstáculos
A1: Plano de testes com obstáculos — TM12 real + RViz/MoveIt — Caixa horizontal e vertical
A2: ID TESTE | B2: Tipo de teste | C2: Objetivo do teste | D2: ID obstáculo | E2: Onde colocar o objeto | F2: Comandos da sequência | G2: Resultado esperado | H2: Resultado obtido comando | I2: Resultado | J2: Observações | K2: Colisão evitada? | L2: Trajetória alterada? | M2: Distância tcp- obstáculo na sua pose final— IR_POSE 1 (mm) | N2: Distância tcp- obstáculo na sua pose final — IR_POSE 2 (mm) | O2: Distância tcp- obstáculo na sua pose final — IR_POSE 3 (mm) | P2: Nº de tentativas
A3: O01 | B3: Visualização | C3: Criar OBS_H na posição 1 e confirmar coincidência com a caixa física horizontal. | D3: OBS_H_P1 | E3: Em cima da mesa, caixa horizontal, posição 1. | F3: ros2 topic pub --once /obstaculo_cmd std_msgs/msg/String "{data: 'ADD A OBS_H 0.9320 0.2390 -0.1800'}" | G3: Obstáculo visível no RViz e coincidente com a caixa real. | H3: Obstáculo visível no RViz | I3: ✓ Sucesso visual | J3: Trajetória feita com sucesso sem colisão; desvia-se em vez de seguir em linha reta. | K3: - | L3: - | P3: 1
A4: O02 | B4: Bloqueio | C4: Validar que o robô não atravessa a caixa horizontal na posição 1. | D4: OBS_H_P1 | E4: Mesmo posicionamento do O01. | F4: ros2 topic pub --once /target_pose geometry_msgs/msg/PoseStamped "{header: {frame_id: 'base'}, pose: {position: {x: 0.932, y: 0.239, z: -0.180}, orientation: {x: 0.0, y: 1.0, z: 0.0, w: 0.0}}}" ros2 topic pub --once /tm12_step std_msgs/msg/String "{data: 'IR_POSE'}" | G4: ERROR MOVE_FAILED ou planeamento rejeitado de forma segura. | H4: ERRO MOVE_FAILED falha na descida | I4: ✓ Bloqueio seguro | J4: Erro esperado na descida por colisão com o objeto. TESTE DE SEGURANÇA APROVADO | K4: SIM | L4: NÃO | M4: 549.4247 | P4: 1
A5: O03 | B5: Contorno | C5: Executar movimento de um lado para o outro da caixa horizontal na posição 1. | D5: OBS_H_P1 | E5: Mesmo posicionamento do O01. | F5: ros2 topic pub --once /target_pose geometry_msgs/msg/PoseStamped "{header: {frame_id: 'base'}, pose: {position: {x: 1.050, y: -0.050, z: -0.140}, orientation: {x: 0.0, y: 1.0, z: 0.0, w: 0.0}}}" ros2 topic pub --once /tm12_step std_msgs/msg/String "{data: 'IR_POSE'}" ros2 topic pub --once /target_pose geometry_msgs/msg/PoseStamped "{header: {frame_id: 'base'}, pose: {position: {x: 0.700, y: 0.320, z: -0.140}, orientation: {x: 0.0, y: 1.0, z: 0.0, w: 0.0}}}" ros2 topic pub --once /tm12_step std_msgs/msg/String "{data: 'IR_POSE'}" | G5: OK MOVE_DONE com trajetória desviada e sem tocar no obstáculo. | H5: OK MOVE_DONE | I5: ✓ Sucesso execução | J5: Trajetória feita com sucesso sem colisão; desvia-se em vez de seguir em linha reta. | K5: SIM | L5: SIM | M5: 110.0773 | N5: 42.0562 | P5: 1
A6: O04 | B6: Repetição contorno | C6: Repetir O03 para confirmar consistência do planeamento com OBS_H_P1. | D6: OBS_H_P1 | E6: Mesmo posicionamento do O01. | F6: Repetir sequência do O03. | G6: OK MOVE_DONE. | H6: OK MOVE_DONE | I6: ✓ Sucesso execução | J6: ---- | K6: SIM | L6: SIM | P6: 1
A7: O05 | B7: Visualização | C7: Criar OBS_H numa segunda posição da mesa e confirmar coincidência RViz/real. | D7: OBS_H_P2 | E7: Em cima da mesa, posição 2 lateral. | F7: ros2 topic pub --once /obstaculo_cmd std_msgs/msg/String "{data: 'CLEAR'}" ros2 topic pub --once /obstaculo_cmd std_msgs/msg/String "{data: 'ADD B OBS_H 0.5770 0.7570 -0.1800'}" | G7: Obstáculo visível e coincidente na nova posição. | H7: Obstáculo visível no RViz | I7: ✓ Sucesso visual | J7: ---- | K7: - | L7: - | P7: 1
A8: O06 | B8: Bloqueio | C8: Validar bloqueio na posição 2. | D8: OBS_H_P2 | E8: Mesmo posicionamento do O05. | F8: ros2 topic pub --once /target_pose geometry_msgs/msg/PoseStamped "{header: {frame_id: 'base'}, pose: {position: {x: 0.577, y: 0.757, z: -0.180}, orientation: {x: 0.0, y: 1.0, z: 0.0, w: 0.0}}}" ros2 topic pub --once /tm12_step std_msgs/msg/String "{data: 'IR_POSE'}" | G8: ERROR MOVE_FAILED ou falha segura na descida. | H8: ERRO MOVE_FAILED falha na descida | I8: ✓ Bloqueio seguro | J8: Erro esperado na descida por colisão com o objeto. TESTE DE SEGURANÇA APROVADO | K8: SIM | L8: NÃO | M8: 570.3572 | P8: 1
A9: O07 | B9: Contorno | C9: Executar contorno da caixa na posição 2. | D9: OBS_H_P2 | E9: Mesmo posicionamento do O05. | F9: ros2 topic pub --once /target_pose geometry_msgs/msg/PoseStamped "{header: {frame_id: 'base'}, pose: {position: {x: 0.88, y: 0.45, z: -0.10}, orientation: {x: 0.0, y: 1.0, z: 0.0, w: 0.0}}}" ros2 topic pub --once /tm12_step std_msgs/msg/String "{data: 'IR_POSE'}" ros2 topic pub --once /target_pose geometry_msgs/msg/PoseStamped "{header: {frame_id: 'base'}, pose: {position: {x: 0.390, y: 0.930, z: -0.140}, orientation: {x: 0.0, y: 1.0, z: 0.0, w: 0.0}}}" ros2 topic pub --once /tm12_step std_msgs/msg/String "{data: 'IR_POSE'}" | G9: OK MOVE_DONE com desvio e sem colisão. | H9: OK MOVE_DONE | I9: ✓ Sucesso execução | J9: Trajetória feita com sucesso sem colisão; desvia-se em vez de seguir em linha reta. | K9: SIM | L9: SIM | M9: 253.9262 | N9: 76.1514 | P9: 1
A10: O08 | B10: Repetição contorno | C10: Repetir O07 para verificar consistência noutra posição. | D10: OBS_H_P2 | E10: Mesmo posicionamento do O05. | F10: Repetir sequência do O07. | G10: OK MOVE_DONE. | H10: OK MOVE_DONE | I10: ✓ Sucesso execução | J10: ---- | K10: SIM | L10: SIM | P10: 1
A11: O09 | B11: Visualização | C11: Criar OBS_H numa terceira posição da mesa. | D11: OBS_H_P3 | E11: Em cima da mesa, posição 3 mais avançada/lateral. | F11: ros2 topic pub --once /obstaculo_cmd std_msgs/msg/String "{data: 'CLEAR'}" ros2 topic pub --once /obstaculo_cmd std_msgs/msg/String "{data: 'ADD C OBS_H 1.4500 -0.1200 -0.1800'}" | G11: Obstáculo visível e coincidente na terceira posição. | H11: Obstáculo visível no RViz | I11: ✓ Sucesso visual | J11: ---- | K11: - | L11: - | P11: 1
A12: O10 | B12: Bloqueio | C12: Validar bloqueio na posição 3. | D12: OBS_H_P3 | E12: Mesmo posicionamento do O09. | F12: ros2 topic pub --once /target_pose geometry_msgs/msg/PoseStamped "{header: {frame_id: 'base'}, pose: {position: {x: 1.250, y: -0.12, z: -0.180}, orientation: {x: 0.0, y: 1.0, z: 0.0, w: 0.0}}}" ros2 topic pub --once /tm12_step std_msgs/msg/String "{data: 'IR_POSE'}" | G12: ERROR MOVE_FAILED ou falha segura na descida. | H12: ERRO MOVE_FAILED | I12: ✓ Bloqueio seguro | J12: Erro esperado na descida por colisão com o objeto. TESTE DE SEGURANÇA APROVADO | K12: SIM | L12: NÃO | M12: 2017.57 | P12: 1
A13: O11 | B13: Visualização | C13: Criar OBS_V na posição vertical 1 e confirmar coincidência RViz/real. | D13: OBS_V_P1 | E13: Em cima da mesa, caixa em pé, posição 1. | F13: ros2 topic pub --once /obstaculo_cmd std_msgs/msg/String "{data: 'CLEAR'}" ros2 topic pub --once /obstaculo_cmd std_msgs/msg/String "{data: 'ADD D OBS_V 1.0170 0.3220 -0.0625'}" | G13: Obstáculo vertical visível no RViz e coincidente com a caixa real. | H13: Obstáculo visível no RViz | I13: ✓ Sucesso visual | J13: ---- | K13: - | L13: - | P13: 1
A14: O12 | B14: Bloqueio | C14: Validar que o robô não atravessa a caixa vertical na posição 1. | D14: OBS_V_P1 | E14: Mesmo posicionamento do O11. | F14: ros2 topic pub --once /target_pose geometry_msgs/msg/PoseStamped "{header: {frame_id: 'base'}, pose: {position: {x: 1.017, y: 0.322, z: -0.0625}, orientation: {x: 0.0, y: 1.0, z: 0.0, w: 0.0}}}" ros2 topic pub --once /tm12_step std_msgs/msg/String "{data: 'IR_POSE'}" | G14: ERROR MOVE_FAILED ou planeamento rejeitado de forma segura. | H14: ERRO MOVE_FAILED | I14: ✓ Bloqueio seguro | J14: Erro esperado na descida por colisão com o objeto. TESTE DE SEGURANÇA APROVADO | K14: SIM | L14: NÃO | M14: 334.9116 | P14: 1
A15: O13 | B15: Contorno | C15: Executar movimento de um lado para o outro da caixa vertical na posição 1. | D15: OBS_V_P1 | E15: Mesmo posicionamento do O11. | F15: ros2 topic pub --once /target_pose geometry_msgs/msg/PoseStamped "{header: {frame_id: 'base'}, pose: {position: {x: 1.21, y: 0.11, z: -0.02}, orientation: {x: 0.0, y: 1.0, z: 0.0, w: 0.0}}}" ros2 topic pub --once /tm12_step std_msgs/msg/String "{data: 'IR_POSE'}" ros2 topic pub --once /target_pose geometry_msgs/msg/PoseStamped "{header: {frame_id: 'base'}, pose: {position: {x: 0.88, y: 0.48, z: -0.03}, orientation: {x: 0.0, y: 1.0, z: 0.0, w: 0.0}}}" ros2 topic pub --once /tm12_step std_msgs/msg/String "{data: 'IR_POSE'}" | G15: OK MOVE_DONE com trajetória desviada e sem tocar no obstáculo. | H15: OK MOVE_DONE | I15: ✓ Sucesso execução | J15: Trajetória feita com sucesso sem colisão; desvia-se em vez de seguir em linha reta. | K15: SIM | L15: SIM | M15: 226.3392 | N15: 145.3764 | P15: 1
A16: O14 | B16: Repetição contorno | C16: Repetir O13 para confirmar consistência do planeamento com OBS_V_P1. | D16: OBS_V_P1 | E16: Mesmo posicionamento do O11. | F16: Repetir sequência do O13. | G16: OK MOVE_DONE. | H16: OK MOVE_DONE | I16: ✓ Sucesso execução | J16: ---- | K16: SIM | L16: SIM | P16: 1
A17: O15 | B17: Visualização | C17: Criar OBS_V numa segunda posição vertical da mesa e confirmar coincidência RViz/real. | D17: OBS_V_P2 | E17: Em cima da mesa, caixa em pé, posição 2. | F17: ros2 topic pub --once /obstaculo_cmd std_msgs/msg/String "{data: 'CLEAR'}" ros2 topic pub --once /obstaculo_cmd std_msgs/msg/String "{data: 'ADD E OBS_V 0.4950 0.8450 -0.0625'}" | G17: Obstáculo vertical visível no RViz e coincidente com a caixa real. | H17: Obstáculo visível no RViz | I17: ✓ Sucesso visual | J17: ---- | K17: - | L17: - | P17: 1
A18: O16 | B18: Bloqueio | C18: Validar bloqueio da caixa vertical na posição 2. | D18: OBS_V_P2 | E18: Mesmo posicionamento do O15. | F18: ros2 topic pub --once /target_pose geometry_msgs/msg/PoseStamped "{header: {frame_id: 'base'}, pose: {position: {x: 0.495, y: 0.845, z: -0.0625}, orientation: {x: 0.0, y: 1.0, z: 0.0, w: 0.0}}}" ros2 topic pub --once /tm12_step std_msgs/msg/String "{data: 'IR_POSE'}" | G18: ERROR MOVE_FAILED ou falha segura na descida. | H18: ERRO MOVE_FAILED | I18: ✓ Bloqueio seguro | J18: Erro esperado na descida por colisão com o objeto. TESTE DE SEGURANÇA APROVADO | K18: SIM | L18: NÃO | M18: 335.1222 | P18: 1
A19: O17 | B19: Contorno | C19: Executar contorno da caixa vertical na posição 2. | D19: OBS_V_P2 | E19: Mesmo posicionamento do O15. | F19: ros2 topic pub --once /target_pose geometry_msgs/msg/PoseStamped "{header: {frame_id: 'base'}, pose: {position: {x: 0.72, y: 0.63, z: -0.03}, orientation: {x: 0.0, y: 1.0, z: 0.0, w: 0.0}}}" ros2 topic pub --once /tm12_step std_msgs/msg/String "{data: 'IR_POSE'}" ros2 topic pub --once /target_pose geometry_msgs/msg/PoseStamped "{header: {frame_id: 'base'}, pose: {position: {x: 0.25, y: 0.97, z: -0.05}, orientation: {x: 0.0, y: 1.0, z: 0.0, w: 0.0}}}" ros2 topic pub --once /tm12_step std_msgs/msg/String "{data: 'IR_POSE'}" | G19: OK MOVE_DONE com trajetória desviada. | H19: OK MOVE_DONE | I19: ✓ Sucesso execução | J19: Trajetória feita com sucesso sem colisão; desvia-se em vez de seguir em linha reta. | K19: SIM | L19: SIM | M19: 250.2779 | N19: 202.2882 | P19: 1
A20: O18 | B20: Repetição contorno | C20: Repetir O17 para confirmar consistência do planeamento com OBS_V_P2. | D20: OBS_V_P2 | E20: Mesmo posicionamento do O15. | F20: Repetir sequência do O17. | G20: OK MOVE_DONE. | H20: OK MOVE_DONE | I20: ✓ Sucesso execução | J20: ---- | K20: SIM | L20: SIM | P20: 1
A21: Dois obstáculos na mesma cena
A22: O19 | B22: Desvio de trajetória sem colisão | C22: Mostrar contorno pelos 2 objetos | D22: OBS_V_P1 + OBS_V_P2 | E22: Posição 1 e 2 das caixas verticais | F22: ros2 topic pub --once /obstaculo_cmd std_msgs/msg/String "{data: 'ADD D OBS_V 1.0170 0.3220 -0.0625'}" ros2 topic pub --once /obstaculo_cmd std_msgs/msg/String "{data: 'ADD E OBS_V 0.4950 0.8450 -0.0625'}" ros2 topic pub --once /target_pose geometry_msgs/msg/PoseStamped "{header: {frame_id: 'base'}, pose: {position: {x: 0.223, y: 1.140, z: 0.037}, orientation: {x: -0.12164731150558128, y: 0.7417252259015115, z: -0.1309097106398482, w: 0.6464582496379847}}}" ros2 topic pub --once /tm12_step std_msgs/msg/String "{data: 'IR_POSE'}" ros2 topic pub --once /target_pose geometry_msgs/msg/PoseStamped "{header: {frame_id: 'base'}, pose: {position: {x: 0.883, y: 0.587, z: 0.051}, orientation: {x: 0.47930059157978466, y: 0.8494841402145467, z: 0.2205587952337683, w: -0.0012067643720697907}}}" ros2 topic pub --once /tm12_step std_msgs/msg/String "{data: 'IR_POSE'}" ros2 topic pub --once /target_pose geometry_msgs/msg/PoseStamped "{header: {frame_id: 'base'}, pose: {position: {x: 1.15, y: -0.05, z: 0.05}, orientation: {x: -0.7730392009226255, y: -0.6182865791650175, z: 0.11703008521554474, w: 0.08022505229522497}}}" ros2 topic pub --once /tm12_step std_msgs/msg/String "{data: 'IR_POSE'}" | G22: OK MOVE_DONE | H22: OK MOVE_DONE | I22: ✓ Sucesso execução | J22: Trajetória feita com sucesso sem colisão; desvia-se em vez de seguir em linha reta. | K22: SIM | L22: SIM | M22: 341.1691 | N22: 216.982 | O22: 300.1122 | P22: 1
A23: O20 (CORREDOR ESTREITO) | B23: Desvio de trajetória sem colisão | C23: Mostrar contorno pelos 2 objetos | D23: OBS_H_P4 + OBS_H_P2 | E23: Posição 2 e 4 da caixa horizontal | F23: ros2 topic pub --once /obstaculo_cmd std_msgs/msg/String "{data: 'ADD F OBS_H 1.0200 0.3200 -0.1800'}" ros2 topic pub --once /obstaculo_cmd std_msgs/msg/String "{data: 'ADD B OBS_H 0.5770 0.7570 -0.1800'}" ros2 topic pub --once /target_pose geometry_msgs/msg/PoseStamped "{header: {frame_id: 'base'}, pose: {position: {x: 0.339, y: 0.954, z: -0.049}, orientation: {x: -0.19048426829942827, y: -0.9724934308561571, z: 0.1332808507788149, w: -0.01443901962488419}}}" ros2 topic pub --once /tm12_step std_msgs/msg/String "{data: 'IR_POSE'}" ros2 topic pub --once /target_pose geometry_msgs/msg/PoseStamped "{header: {frame_id: 'base'}, pose: {position: {x: 0.828, y: 0.631, z: -0.080}, orientation: {x: -0.46234949028963895, y: -0.8776495638375028, z: 0.12437648489733448, w: 0.022241446206014523}}}" ros2 topic pub --once /tm12_step std_msgs/msg/String "{data: 'IR_POSE'}" ros2 topic pub --once /target_pose geometry_msgs/msg/PoseStamped "{header: {frame_id: 'base'}, pose: {position: {x: 1.201, y: 0.005, z: -0.086}, orientation: {x: -0.7315420258177688, y: -0.6816260642905323, z: 0.014026416482747238, w: -0.0059525274368440045}}}" ros2 topic pub --once /tm12_step std_msgs/msg/String "{data: 'IR_POSE'}" | G23: OK MOVE_DONE | H23: OK MOVE_DONE | I23: ✓ Sucesso execução | J23: Trajetória feita com sucesso sem colisão; desvia-se em vez de seguir em linha reta. | K23: SIM | L23: SIM | M23: 147.4497 | N23: 98.0725 | O23: 177.0927 | P23: 1
A24: O21 | B24: Contorno | C24: Mostrar contorno pelos 2 objetos(um em cima do outro para dar mais altura) | D24: OBS_H_P2 + OBS_H_P5 | E24: Posição 2 e 5 horizontal | F24: ros2 topic pub --once /obstaculo_cmd std_msgs/msg/String "{data: 'ADD G OBS_H 0.5770 0.7570 -0.0590'}" ros2 topic pub --once /obstaculo_cmd std_msgs/msg/String "{data: 'ADD B OBS_H 0.5770 0.7570 -0.1800'}" ros2 topic pub --once /target_pose geometry_msgs/msg/PoseStamped "{header: {frame_id: 'base'}, pose: {position: {x: 0.792, y: 0.964, z: 0.058}, orientation: {x: 0.3684941753801578, y: 0.9048163675734938, z: 0.2074448309317149, w: 0.04986006219127582}}}" ros2 topic pub --once /tm12_step std_msgs/msg/String "{data: 'IR_POSE'}" | G24: OK MOVE_DONE | H24: OK MOVE_DONE | I24: ✓ Sucesso execução | J24: Trajetória feita com sucesso sem colisão; desvia-se em vez de seguir em linha reta. | K24: SIM | L24: SIM | M24: 180.7128 | P24: 1
A25: O22 | B25: Controlo sem obstáculos | C25: Executar a mesma trajetória de O03 sem qualquer obstáculo, criando a referência para comparar métricas | D25: SEM_OBSTACULOS | E25: Retirar fisicamente as caixas da zona de trabalho e confirmar que a planning scene está vazia. | F25: ros2 topic pub --once /obstaculo_cmd std_msgs/msg/String "{data: 'CLEAR'}" ros2 topic pub --once /target_pose geometry_msgs/msg/PoseStamped "{header: {frame_id: 'base'}, pose: {position: {x: 1.050, y: -0.050, z: -0.140}, orientation: {x: 0.0, y: 1.0, z: 0.0, w: 0.0}}}" ros2 topic pub --once /tm12_step std_msgs/msg/String "{data: 'IR_POSE'}" ros2 topic pub --once /target_pose geometry_msgs/msg/PoseStamped "{header: {frame_id: 'base'}, pose: {position: {x: 0.700, y: 0.320, z: -0.140}, orientation: {x: 0.0, y: 1.0, z: 0.0, w: 0.0}}}" ros2 topic pub --once /tm12_step std_msgs/msg/String "{data: 'IR_POSE'}" | G25: OK MOVE_DONE | H25: OK MOVE_DONE | I25: ✓ Sucesso execução | J25: Usar exatamente as mesmas poses, planeador, tolerâncias e fatores de velocidade/aceleração usados no cenário com obstáculo. | K25: - | L25: Não | P25: 1

Sheet Métricas Quantitativas
A1: Métricas
A2: ID TESTE | B2: O02 | E2: O03 | K2: O06 | N2: O07 | T2: O12 | W2: O13 | AC2: O16 | AF2: O17 | AL2: O19 | AU2: O20 | BD2: O21 | BG2: O22 (IGUAL A O03 MAS S/OBSTÁCULO)
A3: MÉTRICAS | B3: IR_POSE1 | E3: IR_POSE1 | H3: IR_POSE2 | K3: IR_POSE1 | N3: IR_POSE1 | Q3: IR_POSE2 | T3: IR_POSE1 | W3: IR_POSE1 | Z3: IR_POSE2 | AC3: IR_POSE1 | AF3: IR_POSE1 | AI3: IR_POSE2 | AL3: IR_POSE1 | AO3: IR_POSE2 | AR3: IR_POSE3 | AU3: IR_POSE1 | AX3: IR_POSE2 | BA3: IR_POSE3 | BD3: IR_POSE1 | BG3: IR_POSE1 | BJ3: IR_POSE2
B4: Diferença entre físico e simulado | C4: Simulação | D4: Físico | E4: Diferença entre físico e simulado | F4: Simulação | G4: Físico | H4: Diferença entre físico e simulado | I4: Simulação | J4: Físico | K4: Diferença entre físico e simulado | L4: Simulação | M4: Físico | N4: Diferença entre físico e simulado | O4: Simulação | P4: Físico | Q4: Diferença entre físico e simulado | R4: Simulação | S4: Físico | T4: Diferença entre físico e simulado | U4: Simulação | V4: Físico | W4: Diferença entre físico e simulado | X4: Simulação | Y4: Físico | Z4: Diferença entre físico e simulado | AA4: Simulação | AB4: Físico | AC4: Diferença entre físico e simulado | AD4: Simulação | AE4: Físico | AF4: Diferença entre físico e simulado | AG4: Simulação | AH4: Físico | AI4: Diferença entre físico e simulado | AJ4: Simulação | AK4: Físico | AL4: Diferença entre físico e simulado | AM4: Simulação | AN4: Físico | AO4: Diferença entre físico e simulado | AP4: Simulação | AQ4: Físico | AR4: Diferença entre físico e simulado | AS4: Simulação | AT4: Físico | AU4: Diferença entre físico e simulado | AV4: Simulação | AW4: Físico | AX4: Diferença entre físico e simulado | AY4: Simulação | AZ4: Físico | BA4: Diferença entre físico e simulado | BB4: Simulação | BC4: Físico | BD4: Diferença entre físico e simulado | BE4: Simulação | BF4: Físico | BG4: Diferença entre físico e simulado | BH4: Simulação | BI4: Físico | BJ4: Diferença entre físico e simulado | BK4: Simulação | BL4: Físico
A5: Tempo de Planeamento (s) | B5: =D5-C5 -> 1.2883 | C5: 0.2657 | D5: 1.554 | E5: =G5-F5 -> 1.0272 | F5: 0.5309 | G5: 1.5581 | H5: =J5-I5 -> 0.9862 | I5: 0.5539 | J5: 1.5401 | K5: =M5-L5 -> 1.0001 | L5: 0.5496 | M5: 1.5497 | N5: =P5-O5 -> 1.0285 | O5: 0.5222 | P5: 1.5507 | Q5: =S5-R5 -> 1.035 | R5: 0.5161 | S5: 1.5511 | T5: =V5-U5 -> 1.0096 | U5: 0.5377 | V5: 1.5473 | W5: =Y5-X5 -> 0.9944 | X5: 0.5367 | Y5: 1.5311 | Z5: =AB5-AA5 -> 1.0101 | AA5: 0.5375 | AB5: 1.5476 | AC5: =AE5-AD5 -> 1.0547 | AD5: 0.5459 | AE5: 1.6006 | AF5: =AH5-AG5 -> 1.04 | AG5: 0.527 | AH5: 1.567 | AI5: =AK5-AJ5 -> 1.037 | AJ5: 0.5253 | AK5: 1.5623 | AL5: =AN5-AM5 -> 1.0243 | AM5: 0.5419 | AN5: 1.5662 | AO5: =AQ5-AP5 -> 1.0221 | AP5: =0.5323 -> 0.5323 | AQ5: 1.5544 | AR5: =AT5-AS5 -> 1.028 | AS5: 0.542 | AT5: 1.57 | AU5: =AW5-AV5 -> 1.1166 | AV5: 0.5409 | AW5: 1.6575 | AX5: =AZ5-AY5 -> 1.0138 | AY5: 0.5226 | AZ5: 1.5364 | BA5: =BC5-BB5 -> 1.1287 | BB5: 0.4346 | BC5: 1.5633 | BD5: =BF5-BE5 -> 0.8248 | BE5: 0.5439 | BF5: 1.3687 | BG5: =BI5-BH5 -> 0.8378 | BH5: 0.5309 | BI5: 1.3687 | BJ5: =BL5-BK5 -> 0.9029 | BK5: 0.5539 | BL5: 1.4568
A6: Tempo de Execução (s) | B6: =D6-C6 -> 17.8968 | C6: 15.5215 | D6: 33.4183 | E6: =G6-F6 -> 3.0238 | F6: 5.9262 | G6: 8.95 | H6: =J6-I6 -> 4.1568 | I6: 7.0375 | J6: 11.1943 | K6: =M6-L6 -> 18.4228 | L6: 15.5098 | M6: 33.9326 | N6: =P6-O6 -> 4.4421 | O6: 7.0386 | P6: 11.4807 | Q6: =S6-R6 -> 4.9676 | R6: 5.8838 | S6: 10.8514 | T6: =V6-U6 -> 16.1364 | U6: 15.5428 | V6: 31.6792 | W6: =Y6-X6 -> 4.4226 | X6: 7.0585 | Y6: 11.4811 | Z6: =AB6-AA6 -> 3.6153 | AA6: 7.049 | AB6: 10.6643 | AC6: =AE6-AD6 -> 16.9542 | AD6: 15.5202 | AE6: 32.4744 | AF6: =AH6-AG6 -> 4.8864 | AG6: 7.0578 | AH6: 11.9442 | AI6: =AK6-AJ6 -> 3.7398 | AJ6: 7.0509 | AK6: 10.7907 | AL6: =AN6-AM6 -> 6.0639 | AM6: 5.879 | AN6: 11.9429 | AO6: =AQ6-AP6 -> 4.6499 | AP6: 7.0558 | AQ6: 11.7057 | AR6: =AT6-AS6 -> 5.355 | AS6: 7.0347 | AT6: 12.3897 | AU6: =AW6-AV6 -> 2.6579 | AV6: 7.0434 | AW6: 9.7013 | AX6: =AZ6-AY6 -> 3.5867 | AY6: 7.0445 | AZ6: 10.6312 | BA6: =BC6-BB6 -> 3.077 | BB6: 7.0434 | BC6: 10.1204 | BD6: =BF6-BE6 -> 5.5495 | BE6: 7.0467 | BF6: 12.5962 | BG6: =BI6-BH6 -> 2.5238 | BH6: 5.9262 | BI6: 8.45 | BJ6: =BL6-BK6 -> 3.8754 | BK6: 7.0375 | BL6: 10.9129
A7: Tempo Total de ciclo (s) | B7: =D7-C7 -> 19.1851 | C7: 15.7872 | D7: =D6+D5 -> 34.9723 | E7: =G7-F7 -> 4.051 | F7: =F6+F5 -> 6.4571 | G7: =G6+G5 -> 10.5081 | H7: =J7-I7 -> 5.143 | I7: 7.5914 | J7: =J6+J5 -> 12.7344 | K7: =M7-L7 -> 19.4229 | L7: =L6+L5 -> 16.0594 | M7: =M6+M5 -> 35.4823 | N7: =P7-O7 -> 5.4706 | O7: =O6+O5 -> 7.5608 | P7: =P6+P5 -> 13.0314 | Q7: =S7-R7 -> 6.0026 | R7: =R6+R5 -> 6.3999 | S7: =S6+S5 -> 12.4025 | T7: =V7-U7 -> 17.146 | U7: 16.0805 | V7: =V6+V5 -> 33.2265 | W7: =Y7-X7 -> 5.417 | X7: 7.5952 | Y7: =Y6+Y5 -> 13.0122 | Z7: =AB7-AA7 -> 4.6254 | AA7: 7.5865 | AB7: =AB6+AB5 -> 12.2119 | AC7: =AE7-AD7 -> 18.009 | AD7: 16.066 | AE7: =AE6+AE5 -> 34.075 | AF7: =AH7-AG7 -> 5.9265 | AG7: 7.5847 | AH7: =AH6+AH5 -> 13.5112 | AI7: =AK7-AJ7 -> 4.7768 | AJ7: =AJ6+AJ5 -> 7.5762 | AK7: =AK6+AK5 -> 12.353 | AL7: =AN7-AM7 -> 7.0882 | AM7: =AM6+AM5 -> 6.4209 | AN7: =AN6+AN5 -> 13.5091 | AO7: =AQ7-AP7 -> 5.672 | AP7: =AP6+AP5 -> 7.5881 | AQ7: =AQ6+AQ5 -> 13.2601 | AR7: =AT7-AS7 -> 6.383 | AS7: 7.5767 | AT7: =AT6+AT5 -> 13.9597 | AU7: =AW7-AV7 -> 3.7745 | AV7: 7.5843 | AW7: =AW6+AW5 -> 11.3588 | AX7: =AZ7-AY7 -> 4.6005 | AY7: =AY6+AY5 -> 7.5671 | AZ7: =AZ6+AZ5 -> 12.1676 | BA7: =BC7-BB7 -> 4.2057 | BB7: =BB6+BB5 -> 7.478 | BC7: =BC6+BC5 -> 11.6837 | BD7: =BF7-BE7 -> 6.3743 | BE7: =BE6+BE5 -> 7.5906 | BF7: =BF6+BF5 -> 13.9649 | BG7: =BI7-BH7 -> 3.3616 | BH7: =BH6+BH5 -> 6.4571 | BI7: =BI6+BI5 -> 9.8187 | BJ7: =BL7-BK7 -> 4.7783 | BK7: 7.5914 | BL7: =BL6+BL5 -> 12.3697
A8: Pose X alvo (m) | B8: =D8-C8 -> 0 | C8: 0.932 | D8: 0.932 | E8: =G8-F8 -> 0 | F8: 1.05 | G8: 1.05 | H8: =J8-I8 -> 0 | I8: 0.7 | J8: 0.7 | K8: =M8-L8 -> 0 | L8: 0.577 | M8: 0.577 | N8: =P8-O8 -> 0 | O8: 0.88 | P8: 0.88 | Q8: =S8-R8 -> 0 | R8: 0.39 | S8: 0.39 | T8: =V8-U8 -> 0 | U8: 1.017 | V8: 1.017 | W8: =Y8-X8 -> 0 | X8: 1.21 | Y8: 1.21 | Z8: =AB8-AA8 -> 0 | AA8: 0.88 | AB8: 0.88 | AC8: =AE8-AD8 -> 0 | AD8: 0.495 | AE8: 0.495 | AF8: =AH8-AG8 -> 0 | AG8: 0.72 | AH8: 0.72 | AI8: =AK8-AJ8 -> 0 | AJ8: 0.25 | AK8: 0.25 | AL8: =AN8-AM8 -> 0 | AM8: 0.223 | AN8: 0.223 | AO8: =AQ8-AP8 -> 0 | AP8: 0.883 | AQ8: 0.883 | AR8: =AT8-AS8 -> 0 | AS8: 1.15 | AT8: 1.15 | AU8: =AW8-AV8 -> 0 | AV8: 0.339 | AW8: 0.339 | AX8: =AZ8-AY8 -> 0 | AY8: 0.828 | AZ8: 0.828 | BA8: =BC8-BB8 -> 0 | BB8: 1.201 | BC8: 1.201 | BD8: =BF8-BE8 -> 0 | BE8: 0.792 | BF8: 0.792 | BG8: =BI8-BH8 -> 0 | BH8: 1.05 | BI8: 1.05 | BJ8: =BL8-BK8 -> 0 | BK8: 0.7 | BL8: 0.7
A9: Pose Y alvo (m) | B9: =D9-C9 -> 0 | C9: 0.239 | D9: 0.239 | E9: =G9-F9 -> 0 | F9: -0.05 | G9: -0.05 | H9: =J9-I9 -> 0 | I9: 0.32 | J9: 0.32 | K9: =M9-L9 -> 0 | L9: 0.757 | M9: 0.757 | N9: =P9-O9 -> 0 | O9: 0.45 | P9: 0.45 | Q9: =S9-R9 -> 0 | R9: 0.93 | S9: 0.93 | T9: =V9-U9 -> 0 | U9: 0.322 | V9: 0.322 | W9: =Y9-X9 -> 0 | X9: 0.11 | Y9: 0.11 | Z9: =AB9-AA9 -> 0 | AA9: 0.48 | AB9: 0.48 | AC9: =AE9-AD9 -> 0 | AD9: 0.845 | AE9: 0.845 | AF9: =AH9-AG9 -> 0 | AG9: 0.63 | AH9: 0.63 | AI9: =AK9-AJ9 -> 0 | AJ9: 0.97 | AK9: 0.97 | AL9: =AN9-AM9 -> 0 | AM9: 1.14 | AN9: 1.14 | AO9: =AQ9-AP9 -> 0 | AP9: 0.587 | AQ9: 0.587 | AR9: =AT9-AS9 -> 0 | AS9: -0.05 | AT9: -0.05 | AU9: =AW9-AV9 -> 0 | AV9: 0.954 | AW9: 0.954 | AX9: =AZ9-AY9 -> 0 | AY9: 0.631 | AZ9: 0.631 | BA9: =BC9-BB9 -> 0 | BB9: 0.005 | BC9: 0.005 | BD9: =BF9-BE9 -> 0 | BE9: 0.964 | BF9: 0.964 | BG9: =BI9-BH9 -> 0 | BH9: -0.05 | BI9: -0.05 | BJ9: =BL9-BK9 -> 0 | BK9: 0.32 | BL9: 0.32
A10: Pose Z alvo (m) | B10: =D10-C10 -> 0 | C10: -0.18 | D10: -0.18 | E10: =G10-F10 -> 0 | F10: -0.14 | G10: -0.14 | H10: =J10-I10 -> 0 | I10: -0.14 | J10: -0.14 | K10: =M10-L10 -> 0 | L10: -0.18 | M10: -0.18 | N10: =P10-O10 -> 0 | O10: -0.1 | P10: -0.1 | Q10: =S10-R10 -> 0 | R10: -0.14 | S10: -0.14 | T10: =V10-U10 -> 0 | U10: -0.0625 | V10: -0.0625 | W10: =Y10-X10 -> 0 | X10: -0.02 | Y10: -0.02 | Z10: =AB10-AA10 -> 0 | AA10: -0.03 | AB10: -0.03 | AC10: =AE10-AD10 -> 0 | AD10: -0.0625 | AE10: -0.0625 | AF10: =AH10-AG10 -> 0 | AG10: -0.03 | AH10: -0.03 | AI10: =AK10-AJ10 -> 0 | AJ10: -0.05 | AK10: -0.05 | AL10: =AN10-AM10 -> 0 | AM10: 0.037 | AN10: 0.037 | AO10: =AQ10-AP10 -> 0 | AP10: 0.051 | AQ10: 0.051 | AR10: =AT10-AS10 -> 0 | AS10: 0.05 | AT10: 0.05 | AU10: =AW10-AV10 -> 0 | AV10: -0.049 | AW10: -0.049 | AX10: =AZ10-AY10 -> 0 | AY10: -0.08 | AZ10: -0.08 | BA10: =BC10-BB10 -> 0 | BB10: -0.086 | BC10: -0.086 | BD10: =BF10-BE10 -> 0 | BE10: 0.058 | BF10: 0.058 | BG10: =BI10-BH10 -> 0 | BH10: -0.14 | BI10: -0.14 | BJ10: =BL10-BK10 -> 0 | BK10: -0.14 | BL10: -0.14
A11: Pose X real (m) | B11: =D11-C11 -> 0.0011 | C11: 0.9317 | D11: 0.9328 | E11: =G11-F11 -> 0.0005 | F11: 1.0494 | G11: 1.0499 | H11: =J11-I11 -> -0.0001 | I11: 0.7008 | J11: 0.7007 | K11: =M11-L11 -> 0 | L11: 0.5763 | M11: 0.5763 | N11: =P11-O11 -> -0.0008 | O11: 0.8802 | P11: 0.8794 | Q11: =S11-R11 -> 0.0002 | R11: 0.3907 | S11: =0.3909 -> 0.3909 | T11: =V11-U11 -> 0.0002 | U11: 1.0168 | V11: 1.017 | W11: =Y11-X11 -> 0.0003 | X11: 1.2098 | Y11: 1.2101 | Z11: =AB11-AA11 -> 0.0011 | AA11: 0.8795 | AB11: 0.8806 | AC11: =AE11-AD11 -> -0.0001 | AD11: 0.4954 | AE11: 0.4953 | AF11: =AH11-AG11 -> 0 | AG11: 0.7198 | AH11: 0.7198 | AI11: =AK11-AJ11 -> -0.0003 | AJ11: 0.2502 | AK11: 0.2499 | AL11: =AN11-AM11 -> -0.0498 | AM11: 0.2233 | AN11: 0.1735 | AO11: =AQ11-AP11 -> -0.0096 | AP11: 0.8827 | AQ11: 0.8731 | AR11: =AT11-AS11 -> 0.0131 | AS11: 1.1506 | AT11: 1.1637 | AU11: =AW11-AV11 -> 0.0016 | AV11: 0.3389 | AW11: 0.3405 | AX11: =AZ11-AY11 -> 0.0079 | AY11: 0.8283 | AZ11: 0.8362 | BA11: =BC11-BB11 -> 0.0004 | BB11: 1.2015 | BC11: 1.2019 | BD11: =BF11-BE11 -> -0.013 | BE11: 0.7928 | BF11: 0.7798 | BG11: =BI11-BH11 -> 0.0005 | BH11: 1.0494 | BI11: 1.0499 | BJ11: =BL11-BK11 -> -0.0009 | BK11: 0.7008 | BL11: 0.6999
A12: Pose Y real (m) | B12: =D12-C12 -> 0.0007 | C12: 0.2387 | D12: 0.2394 | E12: =G12-F12 -> 0.0003 | F12: -0.0499 | G12: -0.0496 | H12: =J12-I12 -> 0.0006 | I12: 0.3195 | J12: 0.3201 | K12: =M12-L12 -> 0.0002 | L12: 0.7571 | M12: 0.7573 | N12: =P12-O12 -> 0.0012 | O12: 0.4496 | P12: 0.4508 | Q12: =S12-R12 -> 0.0003 | R12: 0.9304 | S12: 0.9307 | T12: =V12-U12 -> -0.0012 | U12: 0.3222 | V12: 0.321 | W12: =Y12-X12 -> -0.0018 | X12: 0.1108 | Y12: 0.109 | Z12: =AB12-AA12 -> -0.0004 | AA12: 0.4803 | AB12: 0.4799 | AC12: =AE12-AD12 -> 0.0006 | AD12: 0.845 | AE12: 0.8456 | AF12: =AH12-AG12 -> -0.0003 | AG12: 0.6306 | AH12: 0.6303 | AI12: =AK12-AJ12 -> -0.0006 | AJ12: 0.9705 | AK12: 0.9699 | AL12: =AN12-AM12 -> 0.0019 | AM12: 1.14 | AN12: 1.1419 | AO12: =AQ12-AP12 -> -0.019 | AP12: 0.5868 | AQ12: 0.5678 | AR12: =AT12-AS12 -> 0.0003 | AS12: -0.05 | AT12: -0.0497 | AU12: =AW12-AV12 -> 0.0126 | AV12: 0.9541 | AW12: 0.9667 | AX12: =AZ12-AY12 -> 0.0093 | AY12: 0.6306 | AZ12: 0.6399 | BA12: =BC12-BB12 -> 0.0007 | BB12: 0.0053 | BC12: 0.006 | BD12: =BF12-BE12 -> -0.0171 | BE12: 0.9641 | BF12: 0.947 | BG12: =BI12-BH12 -> -0.0008 | BH12: -0.0499 | BI12: -0.0507 | BJ12: =BL12-BK12 -> 0.0012 | BK12: 0.3195 | BL12: 0.3207
A13: Pose Z real (m) | B13: =D13-C13 -> 0.0501 | C13: 0.4503 | D13: 0.5004 | E13: =G13-F13 -> 0.0499 | F13: -0.1394 | G13: -0.0895 | H13: =J13-I13 -> 0.0519 | I13: -0.1399 | J13: -0.088 | K13: =M13-L13 -> 0.0485 | L13: 0.4502 | M13: 0.4987 | N13: =P13-O13 -> 0.0501 | O13: -0.0996 | P13: -0.0495 | Q13: =S13-R13 -> 0.0512 | R13: -0.1403 | S13: -0.0891 | T13: =V13-U13 -> 0.0503 | U13: 0.4502 | V13: 0.5005 | W13: =Y13-X13 -> 0.0501 | X13: -0.0194 | Y13: 0.0307 | Z13: =AB13-AA13 -> 0.0502 | AA13: -0.0295 | AB13: 0.0207 | AC13: =AE13-AD13 -> 0.0501 | AD13: 0.4505 | AE13: 0.5006 | AF13: =AH13-AG13 -> 0.049 | AG13: -0.0293 | AH13: 0.0197 | AI13: =AK13-AJ13 -> 0.0503 | AJ13: -0.0501 | AK13: 0.0002 | AL13: =AN13-AM13 -> 0.0057 | AM13: 0.0371 | AN13: 0.0428 | AO13: =AQ13-AP13 -> 0.0449 | AP13: 0.0502 | AQ13: 0.0951 | AR13: =AT13-AS13 -> 0.0473 | AS13: 0.0507 | AT13: 0.098 | AU13: =AW13-AV13 -> 0.0494 | AV13: -0.0495 | AW13: -0.0001 | AX13: =AZ13-AY13 -> 0.0473 | AY13: -0.0792 | AZ13: -0.0319 | BA13: =BC13-BB13 -> 0.0501 | BB13: -0.0857 | BC13: -0.0356 | BD13: =BF13-BE13 -> 0.0453 | BE13: 0.0577 | BF13: 0.103 | BG13: =BI13-BH13 -> 0.0482 | BH13: -0.1394 | BI13: -0.0912 | BJ13: =BL13-BK13 -> -0.0518 | BK13: -0.1399 | BL13: -0.1917
A14: Erro de pose X (mm) | B14: =D14-C14 -> 0.5 | C14: =ABS(C11-C8)*1000 -> 0.3 | D14: =ABS(D11-D8)*1000 -> 0.8 | E14: =G14-F14 -> -0.5 | F14: =ABS(F11-F8)*1000 -> 0.6 | G14: =ABS(G11-G8)*1000 -> 0.1 | H14: =J14-I14 -> -0.1 | I14: =ABS(I11-I8)*1000 -> 0.8 | J14: =ABS(J11-J8)*1000 -> 0.7 | K14: =M14-L14 -> 0 | L14: =ABS(L11-L8)*1000 -> 0.7 | M14: =ABS(M11-M8)*1000 -> 0.7 | N14: =P14-O14 -> 0.4 | O14: =ABS(O11-O8)*1000 -> 0.2 | P14: =ABS(P11-P8)*1000 -> 0.6 | Q14: =S14-R14 -> 0.2 | R14: =ABS(R11-R8)*1000 -> 0.7 | S14: =ABS(S11-S8)*1000 -> 0.9 | T14: =V14-U14 -> -0.2 | U14: =ABS(U11-U8)*1000 -> 0.2 | V14: =ABS(V11-V8)*1000 -> 0 | W14: =Y14-X14 -> -0.1 | X14: =ABS(X11-X8)*1000 -> 0.2 | Y14: =ABS(Y11-Y8)*1000 -> 0.1 | Z14: =AB14-AA14 -> 0.1 | AA14: =ABS(AA11-AA8)*1000 -> 0.5 | AB14: =ABS(AB11-AB8)*1000 -> 0.6 | AC14: =AE14-AD14 -> -0.1 | AD14: =ABS(AD8-AD11)*1000 -> 0.4 | AE14: =ABS(AE8-AE11)*1000 -> 0.3 | AF14: =AH14-AG14 -> 0 | AG14: =ABS(AG11-AG8)*1000 -> 0.2 | AH14: =ABS(AH11-AH8)*1000 -> 0.2 | AI14: =AK14-AJ14 -> -0.1 | AJ14: =ABS(AJ11-AJ8)*1000 -> 0.2 | AK14: =ABS(AK11-AK8)*1000 -> 0.1 | AL14: =AN14-AM14 -> 49.2 | AM14: =ABS(AM11-AM8)*1000 -> 0.3 | AN14: =ABS(AN11-AN8)*1000 -> 49.5 | AO14: =AQ14-AP14 -> 9.6 | AP14: =ABS(AP11-AP8)*1000 -> 0.3 | AQ14: =ABS(AQ11-AQ8)*1000 -> 9.9 | AR14: =AT14-AS14 -> 13.1 | AS14: =ABS(AS11-AS8)*1000 -> 0.6 | AT14: =ABS(AT11-AT8)*1000 -> 13.7 | AU14: =AW14-AV14 -> 1.4 | AV14: =ABS(AV11-AV8)*1000 -> 0.1 | AW14: =ABS(AW11-AW8)*1000 -> 1.5 | AX14: =AZ14-AY14 -> 7.9 | AY14: =ABS(AY11-AY8)*1000 -> 0.3 | AZ14: =ABS(AZ11-AZ8)*1000 -> 8.2 | BA14: =BC14-BB14 -> 0.4 | BB14: =ABS(BB11-BB8)*1000 -> 0.5 | BC14: =ABS(BC11-BC8)*1000 -> 0.9 | BD14: =BF14-BE14 -> 11.4 | BE14: =ABS(BE11-BE8)*1000 -> 0.8 | BF14: =ABS(BF11-BF8)*1000 -> 12.2 | BG14: =BI14-BH14 -> -0.5 | BH14: =ABS(BH11-BH8)*1000 -> 0.6 | BI14: =ABS(BI11-BI8)*1000 -> 0.1 | BJ14: =BL14-BK14 -> -0.7 | BK14: =ABS(BK11-BK8)*1000 -> 0.8 | BL14: =ABS(BL11-BL8)*1000 -> 0.1
A15: Erro de pose Y (mm) | B15: =D15-C15 -> 0.1 | C15: =ABS(C12-C9)*1000 -> 0.3 | D15: =ABS(D12-D9)*1000 -> 0.4 | E15: =G15-F15 -> 0.3 | F15: =ABS(F12-F9)*1000 -> 0.1 | G15: =ABS(G12-G9)*1000 -> 0.4 | H15: =J15-I15 -> -0.4 | I15: =ABS(I12-I9)*1000 -> 0.5 | J15: =ABS(J12-J9)*1000 -> 0.1 | K15: =M15-L15 -> 0.2 | L15: =ABS(L12-L9)*1000 -> 0.1 | M15: =ABS(M12-M9)*1000 -> 0.3 | N15: =P15-O15 -> 0.4 | O15: =ABS(O12-O9)*1000 -> 0.4 | P15: =ABS(P12-P9)*1000 -> 0.8 | Q15: =S15-R15 -> 0.3 | R15: =ABS(R12-R9)*1000 -> 0.4 | S15: =ABS(S12-S9)*1000 -> 0.7 | T15: =V15-U15 -> 0.8 | U15: =ABS(U12-U9)*1000 -> 0.2 | V15: =ABS(V12-V9)*1000 -> 1 | W15: =Y15-X15 -> 0.2 | X15: =ABS(X12-X9)*1000 -> 0.8 | Y15: =ABS(Y12-Y9)*1000 -> 1 | Z15: =AB15-AA15 -> -0.2 | AA15: =ABS(AA12-AA9)*1000 -> 0.3 | AB15: =ABS(AB12-AB9)*1000 -> 0.1 | AC15: =AE15-AD15 -> 0.6 | AD15: =ABS(AD9-AD12)*1000 -> 0 | AE15: =ABS(AE9-AE12)*1000 -> 0.6 | AF15: =AH15-AG15 -> -0.3 | AG15: =ABS(AG12-AG9)*1000 -> 0.6 | AH15: =ABS(AH12-AH9)*1000 -> 0.3 | AI15: =AK15-AJ15 -> -0.4 | AJ15: =ABS(AJ12-AJ9)*1000 -> 0.5 | AK15: =ABS(AK12-AK9)*1000 -> 0.1 | AL15: =AN15-AM15 -> 1.9 | AM15: =ABS(AM12-AM9)*1000 -> 0 | AN15: =ABS(AN12-AN9)*1000 -> 1.9 | AO15: =AQ15-AP15 -> 19 | AP15: =ABS(AP12-AP9)*1000 -> 0.2 | AQ15: =ABS(AQ12-AQ9)*1000 -> 19.2 | AR15: =AT15-AS15 -> 0.3 | AS15: =ABS(AS12-AS9)*1000 -> 0 | AT15: =ABS(AT12-AT9)*1000 -> 0.3 | AU15: =AW15-AV15 -> 12.6 | AV15: =ABS(AV12-AV9)*1000 -> 0.1 | AW15: =ABS(AW12-AW9)*1000 -> 12.7 | AX15: =AZ15-AY15 -> 8.5 | AY15: =ABS(AY12-AY9)*1000 -> 0.4 | AZ15: =ABS(AZ12-AZ9)*1000 -> 8.9 | BA15: =BC15-BB15 -> 0.7 | BB15: =ABS(BB12-BB9)*1000 -> 0.3 | BC15: =ABS(BC12-BC9)*1000 -> 1 | BD15: =BF15-BE15 -> 16.9 | BE15: =ABS(BE12-BE9)*1000 -> 0.1 | BF15: =ABS(BF12-BF9)*1000 -> 17 | BG15: =BI15-BH15 -> 0.6 | BH15: =ABS(BH12-BH9)*1000 -> 0.1 | BI15: =ABS(BI12-BI9)*1000 -> 0.7 | BJ15: =BL15-BK15 -> 0.2 | BK15: =ABS(BK12-BK9)*1000 -> 0.5 | BL15: =ABS(BL12-BL9)*1000 -> 0.7
A16: Erro de pose Z (mm) | B16: =D16-C16 -> 50.1 | C16: =ABS(C13-C10)*1000 -> 630.3 | D16: =ABS(D13-D10)*1000 -> 680.4 | E16: =G16-F16 -> 49.9 | F16: =ABS(F13-F10)*1000 -> 0.6 | G16: =ABS(G13-G10)*1000 -> 50.5 | H16: =J16-I16 -> 51.9 | I16: =ABS(I13-I10)*1000 -> 0.1 | J16: =ABS(J13-J10)*1000 -> 52 | K16: =M16-L16 -> 48.5 | L16: =ABS(L13-L10)*1000 -> 630.2 | M16: =ABS(M13-M10)*1000 -> 678.7 | N16: =P16-O16 -> 50.1 | O16: =ABS(O13-O10)*1000 -> 0.4 | P16: =ABS(P13-P10)*1000 -> 50.5 | Q16: =S16-R16 -> 50.6 | R16: =ABS(R13-R10)*1000 -> 0.3 | S16: =ABS(S13-S10)*1000 -> 50.9 | T16: =V16-U16 -> 50.3 | U16: =ABS(U13-U10)*1000 -> 512.7 | V16: =ABS(V13-V10)*1000 -> 563 | W16: =Y16-X16 -> 50.1 | X16: =ABS(X13-X10)*1000 -> 0.6 | Y16: =ABS(Y13-Y10)*1000 -> 50.7 | Z16: =AB16-AA16 -> 50.2 | AA16: =ABS(AA13-AA10)*1000 -> 0.5 | AB16: =ABS(AB13-AB10)*1000 -> 50.7 | AC16: =AE16-AD16 -> 50.1 | AD16: =ABS(AD10-AD13)*1000 -> 513 | AE16: =ABS(AE10-AE13)*1000 -> 563.1 | AF16: =AH16-AG16 -> 49 | AG16: =ABS(AG13-AG10)*1000 -> 0.7 | AH16: =ABS(AH13-AH10)*1000 -> 49.7 | AI16: =AK16-AJ16 -> 50.1 | AJ16: =ABS(AJ13-AJ10)*1000 -> 0.1 | AK16: =ABS(AK13-AK10)*1000 -> 50.2 | AL16: =AN16-AM16 -> 5.7 | AM16: =ABS(AM13-AM10)*1000 -> 0.1 | AN16: =ABS(AN13-AN10)*1000 -> 5.8 | AO16: =AQ16-AP16 -> 43.3 | AP16: =ABS(AP13-AP10)*1000 -> 0.8 | AQ16: =ABS(AQ13-AQ10)*1000 -> 44.1 | AR16: =AT16-AS16 -> 47.3 | AS16: =ABS(AS13-AS10)*1000 -> 0.7 | AT16: =ABS(AT13-AT10)*1000 -> 48 | AU16: =AW16-AV16 -> 48.4 | AV16: =ABS(AV13-AV10)*1000 -> 0.5 | AW16: =ABS(AW13-AW10)*1000 -> 48.9 | AX16: =AZ16-AY16 -> 47.3 | AY16: =ABS(AY13-AY10)*1000 -> 0.8 | AZ16: =ABS(AZ13-AZ10)*1000 -> 48.1 | BA16: =BC16-BB16 -> 50.1 | BB16: =ABS(BB13-BB10)*1000 -> 0.3 | BC16: =ABS(BC13-BC10)*1000 -> 50.4 | BD16: =BF16-BE16 -> 44.7 | BE16: =ABS(BE13-BE10)*1000 -> 0.3 | BF16: =ABS(BF13-BF10)*1000 -> 45 | BG16: =BI16-BH16 -> 48.2 | BH16: =ABS(BH13-BH10)*1000 -> 0.6 | BI16: =ABS(BI13-BI10)*1000 -> 48.8 | BJ16: =BL16-BK16 -> 51.6 | BK16: =ABS(BK13-BK10)*1000 -> 0.1 | BL16: =ABS(BL13-BL10)*1000 -> 51.7
A17: Erro euclidiano de pose (mm) | B17: =D17-C17 -> 50.100445 | C17: =SQRT(SUMSQ(C14:C16)) -> 630.30014 | D17: =SQRT(SUMSQ(D14:D16)) -> 680.40059 | E17: =G17-F17 -> 49.647283 | F17: =SQRT(SUMSQ(F14:F16)) -> 0.85440037 | G17: =SQRT(SUMSQ(G14:G16)) -> 50.501683 | H17: =J17-I17 -> 51.056124 | I17: =SQRT(SUMSQ(I14:I16)) -> 0.9486833 | J17: =SQRT(SUMSQ(J14:J16)) -> 52.004807 | K17: =M17-L17 -> 48.500031 | L17: =SQRT(SUMSQ(L14:L16)) -> 630.2004 | M17: =SQRT(SUMSQ(M14:M16)) -> 678.70043 | N17: =P17-O17 -> 49.9099 | O17: =SQRT(SUMSQ(O14:O16)) -> 0.6 | P17: =SQRT(SUMSQ(P14:P16)) -> 50.5099 | Q17: =S17-R17 -> 50.052536 | R17: =SQRT(SUMSQ(R14:R16)) -> 0.86023253 | S17: =SQRT(SUMSQ(S14:S16)) -> 50.912769 | T17: =V17-U17 -> 50.30081 | U17: =SQRT(SUMSQ(U14:U16)) -> 512.70008 | V17: =SQRT(SUMSQ(V14:V16)) -> 563.00089 | W17: =Y17-X17 -> 49.690156 | X17: =SQRT(SUMSQ(X14:X16)) -> 1.0198039 | Y17: =SQRT(SUMSQ(Y14:Y16)) -> 50.70996 | Z17: =AB17-AA17 -> 49.935534 | AA17: =SQRT(SUMSQ(AA14:AA16)) -> 0.76811457 | AB17: =SQRT(SUMSQ(AB14:AB16)) -> 50.703649 | AC17: =AE17-AD17 -> 50.100244 | AD17: =SQRT(SUMSQ(AD14:AD16)) -> 513.00016 | AE17: =SQRT(SUMSQ(AE14:AE16)) -> 563.1004 | AF17: =AH17-AG17 -> 48.75791 | AG17: =SQRT(SUMSQ(AG14:AG16)) -> 0.94339811 | AH17: =SQRT(SUMSQ(AH14:AH16)) -> 49.701308 | AI17: =AK17-AJ17 -> 49.652477 | AJ17: =SQRT(SUMSQ(AJ14:AJ16)) -> 0.54772256 | AK17: =SQRT(SUMSQ(AK14:AK16)) -> 50.200199 | AL17: =AN17-AM17 -> 49.558616 | AM17: =SQRT(SUMSQ(AM14:AM16)) -> 0.31622777 | AN17: =SQRT(SUMSQ(AN14:AN16)) -> 49.874843 | AO17: =AQ17-AP17 -> 48.229122 | AP17: =SQRT(SUMSQ(AP14:AP16)) -> 0.87749644 | AQ17: =SQRT(SUMSQ(AQ14:AQ16)) -> 49.106619 | AR17: =AT17-AS17 -> 48.995778 | AS17: =SQRT(SUMSQ(AS14:AS16)) -> 0.92195445 | AT17: =SQRT(SUMSQ(AT14:AT16)) -> 49.917732 | AU17: =AW17-AV17 -> 50.02492 | AV17: =SQRT(SUMSQ(AV14:AV16)) -> 0.51961524 | AW17: =SQRT(SUMSQ(AW14:AW16)) -> 50.544535 | AX17: =AZ17-AY17 -> 48.655594 | AY17: =SQRT(SUMSQ(AY14:AY16)) -> 0.94339811 | AZ17: =SQRT(SUMSQ(AZ14:AZ16)) -> 49.598992 | BA17: =BC17-BB17 -> 49.762209 | BB17: =SQRT(SUMSQ(BB14:BB16)) -> 0.65574385 | BC17: =SQRT(SUMSQ(BC14:BC16)) -> 50.417953 | BD17: =BF17-BE17 -> 48.766776 | BE17: =SQRT(SUMSQ(BE14:BE16)) -> 0.86023253 | BF17: =SQRT(SUMSQ(BF14:BF16)) -> 49.627009 | BG17: =BI17-BH17 -> 47.950722 | BH17: =SQRT(SUMSQ(BH14:BH16)) -> 0.85440037 | BI17: =SQRT(SUMSQ(BI14:BI16)) -> 48.805123 | BJ17: =BL17-BK17 -> 50.756152 | BK17: =SQRT(SUMSQ(BK14:BK16)) -> 0.9486833 | BL17: =SQRT(SUMSQ(BL14:BL16)) -> 51.704835
A18: Trajetória visualmente coerente | B18: ----- | C18: coincide | D18: coincide | E18: ----- | F18: coincide | G18: coincide | H18: ----- | I18: coincide | J18: coincide | K18: ----- | L18: coincide | M18: coincide | N18: ----- | O18: coincide | P18: coincide | Q18: ----- | R18: coincide | S18: coincide | T18: ----- | U18: coincide | V18: coincide | W18: ---- | X18: coincide | Y18: coincide | Z18: ---- | AA18: coincide | AB18: coincide | AC18: ----- | AD18: coincide | AE18: coincide | AF18: ---- | AG18: coincide | AH18: coincide | AI18: ---- | AJ18: coincide | AK18: coincide | AL18: ---- | AM18: coincide | AN18: coincide | AO18: ---- | AP18: coincide | AQ18: coincide | AR18: ---- | AS18: coincide | AT18: coincide | AU18: ---- | AV18: coincide | AW18: coincide | AX18: ---- | AY18: coincide | AZ18: coincide | BA18: ---- | BB18: coincide | BC18: coincide | BD18: ---- | BE18: coincide | BF18: coincide | BG18: --- | BH18: coincide | BI18: coincide | BJ18: --- | BK18: coincide | BL18: coincide
A19: Observações | B19: Os testes de segurança mostram um erro de pose elevado mas não são considerados erros de posicionamento pois o robô bloqueia para não colidir com os objetos
B20: Quando a orientação não é 0 1 0 0 há um erro em todos os eixos que tem a ver com as diferenças do tcp porque o mbiente simulado encontra-se rodado 45°
A22: Métricas com Correção do TCP
A23: ID TESTE | B23: O02 | C23: O03 | E23: O06 | F23: O07 | H23: O12 | I23: O13 | K23: O16 | L23: O17 | N23: O19 | Q23: O20 | T23: O21 | U23: O22 (IGUAL A O03 MAS S/OBSTÁCULO)
A24: MÉTRICAS | B24: IR_POSE1 | C24: IR_POSE1 | D24: IR_POSE2 | E24: IR_POSE1 | F24: IR_POSE1 | G24: IR_POSE2 | H24: IR_POSE1 | I24: IR_POSE1 | J24: IR_POSE2 | K24: IR_POSE1 | L24: IR_POSE1 | M24: IR_POSE2 | N24: IR_POSE1 | O24: IR_POSE2 | P24: IR_POSE3 | Q24: IR_POSE1 | R24: IR_POSE2 | S24: IR_POSE3 | T24: IR_POSE1 | U24: IR_POSE1 | V24: IR_POSE2
B25: Físico | C25: Físico | D25: Físico | E25: Físico | F25: Físico | G25: Físico | H25: Físico | I25: Físico | J25: Físico | K25: Físico | L25: Físico | M25: Físico | N25: Físico | O25: Físico | P25: Físico | Q25: Físico | R25: Físico | S25: Físico | T25: Físico | U25: Físico | V25: Físico
A26: Tempo de Planeamento (s) | B26: 1.671 | C26: 1.5466 | D26: 1.5475 | E26: 1.5276 | F26: 1.4602 | G26: 1.5374 | H26: 1.5578 | I26: 1.5428 | J26: 1.5411 | K26: 1.5544 | L26: 1.5543 | M26: 1.5329 | N26: 1.4611 | O26: 1.5432 | P26: 1.5523 | Q26: 1.5536 | R26: 1.6523 | S26: 1.5614 | T26: 1.5545 | U26: 1.5417 | V26: 1.5362
A27: Tempo de Execução (s) | B27: 33.4368 | C27: 11.5061 | D27: 11.1997 | E27: 30.0213 | F27: 12.2299 | G27: 10.8336 | H27: 33.4239 | I27: 11.4886 | J27: 10.6769 | K27: 33.9799 | L27: 12.046 | M27: 10.7363 | N27: 11.9198 | O27: 10.6542 | P27: 12.4917 | Q27: 11.3744 | R27: 10.6547 | S27: 10.9386 | T27: 13.1569 | U27: 10.2163 | V27: 10.5496
A28: Tempo Total de ciclo (s) | B28: =B27+B26 -> 35.1078 | C28: =C27+C26 -> 13.0527 | D28: =D27+D26 -> 12.7472 | E28: =E27+E26 -> 31.5489 | F28: =F27+F26 -> 13.6901 | G28: =G27+G26 -> 12.371 | H28: =H27+H26 -> 34.9817 | I28: =I27+I26 -> 13.0314 | ... V28: =V27+V26 -> 12.0858
A29: Pose X alvo (m) | B29: 0.932 | C29: 1.05 | D29: 0.7 | E29: 0.577 | F29: 0.88 | G29: 0.39 | H29: 1.017 | I29: 1.21 | J29: 0.88 | K29: 0.495 | L29: 0.72 | M29: 0.25 | N29: 0.223 | O29: 0.883 | P29: 1.15 | Q29: 0.339 | R29: 0.828 | S29: 1.201 | T29: 0.792 | U29: 1.05 | V29: 0.7
A30: Pose Y alvo (m) | B30: 0.239 | C30: -0.05 | D30: 0.32 | E30: 0.757 | F30: 0.45 | G30: 0.93 | H30: 0.322 | I30: 0.11 | J30: 0.48 | K30: 0.845 | L30: 0.63 | M30: 0.97 | N30: 1.14 | O30: 0.587 | P30: -0.05 | Q30: 0.954 | R30: 0.631 | S30: 0.005 | T30: 0.964 | U30: -0.05 | V30: 0.32
A31: Pose Z alvo (m) | B31: -0.18 | C31: -0.14 | D31: -0.14 | E31: -0.18 | F31: -0.1 | G31: -0.14 | H31: -0.0625 | I31: -0.02 | J31: -0.03 | K31: -0.0625 | L31: -0.03 | M31: -0.05 | N31: 0.037 | O31: 0.051 | P31: 0.05 | Q31: -0.049 | R31: -0.08 | S31: -0.086 | T31: 0.058 | U31: -0.14 | V31: -0.14
A32: Pose X real (m) | B32: 0.9319 | C32: 1.0497 | D32: 0.7007 | E32: 0.5782 | F32: 0.8799 | G32: 0.3901 | H32: 1.0172 | I32: 1.2102 | J32: 0.8805 | K32: 0.4949 | L32: 0.7204 | M32: 0.2499 | N32: 0.2226 | O32: 0.8825 | P32: 1.1504 | Q32: 0.3399 | R32: 0.8275 | S32: 1.2007 | T32: 0.7914 | U32: 1.0493 | V32: 0.7002
A33: Pose Y real (m) | B33: 0.2389 | C33: -0.051 | D33: 0.3202 | E33: 0.7569 | F33: 0.4495 | G33: 0.9293 | H33: 0.3219 | I33: 0.1094 | J33: 0.4795 | K33: 0.8452 | L33: 0.6297 | M33: 0.9696 | N33: 1.1401 | O33: 0.5871 | P33: -0.0505 | Q33: 0.9546 | R33: 0.6306 | S33: 0.0044 | T33: 0.9636 | U33: -0.0503 | V33: 0.3199
A34: Pose Z real (m) | B34: 0.4503 | C34: -0.139 | D34: -0.1393 | E34: 0.4506 | F34: -0.1015 | G34: -0.1409 | H34: 0.4506 | I34: -0.0187 | J34: -0.0296 | K34: 0.4501 | L34: -0.0309 | M34: -0.0507 | N34: 0.0361 | O34: 0.05104 | P34: 0.0503 | Q34: -0.0489 | R34: -0.0799 | S34: -0.0859 | T34: 0.0575 | U34: -0.1399 | V34: -0.1402
A35: Erro de pose X (mm) | B35: =ABS(B32-B29)*1000 -> 0.1 | C35: =ABS(C32-C29)*1000 -> 0.3 | D35: =ABS(D32-D29)*1000 -> 0.7 | E35: =ABS(E32-E29)*1000 -> 1.2 | F35: =ABS(F32-F29)*1000 -> 0.1 | G35: =ABS(G32-G29)*1000 -> 0.1 | H35: =ABS(H32-H29)*1000 -> 0.2 | I35: =ABS(I32-I29)*1000 -> 0.2 | ... V35: =ABS(V32-V29)*1000 -> 0.2
A36: Erro de pose Y (mm) | B36: =ABS(B33-B30)*1000 -> 0.1 | C36: =ABS(C33-C30)*1000 -> 1 | D36: =ABS(D33-D30)*1000 -> 0.2 | E36: =ABS(E33-E30)*1000 -> 0.1 | F36: =ABS(F33-F30)*1000 -> 0.5 | G36: =ABS(G33-G30)*1000 -> 0.7 | H36: =ABS(H33-H30)*1000 -> 0.1 | I36: =ABS(I33-I30)*1000 -> 0.6 | ... V36: =ABS(V33-V30)*1000 -> 0.1
A37: Erro de pose Z (mm) | B37: =ABS(B34-B31)*1000 -> 630.3 | C37: =ABS(C34-C31)*1000 -> 1 | D37: =ABS(D34-D31)*1000 -> 0.7 | E37: =ABS(E34-E31)*1000 -> 630.6 | F37: =ABS(F34-F31)*1000 -> 1.5 | G37: =ABS(G34-G31)*1000 -> 0.9 | H37: =ABS(H34-H31)*1000 -> 513.1 | I37: =ABS(I34-I31)*1000 -> 1.3 | ... V37: =ABS(V34-V31)*1000 -> 0.2
A38: Erro euclidiano de pose (mm) | B38: =SQRT(SUMSQ(B35:B37)) -> 630.30002 | C38: =SQRT(SUMSQ(C35:C37)) -> 1.4456832 | D38: =SQRT(SUMSQ(D35:D37)) -> 1.0099505 | E38: =SQRT(SUMSQ(E35:E37)) -> 630.60115 | F38: =SQRT(SUMSQ(F35:F37)) -> 1.584298 | G38: =SQRT(SUMSQ(G35:G37)) -> 1.1445523 | H38: =SQRT(SUMSQ(H35:H37)) -> 513.10005 | I38: =SQRT(SUMSQ(I35:I37)) -> 1.4456832 | ... V38: =SQRT(SUMSQ(V35:V37)) -> 0.3
A39: Observações | B39: Os testes de segurança mostram um erro de pose elevado mas não são considerados erros de posicionamento pois o robô bloqueia para não colidir com os objetos
B40: Definiu-se um TCP no TMFlow com 5cm na cordenada Z

Sheet Planners
A1: 1ª Execução | R1: 2ª Execução
A2: ID TESTE | B2: Planner | C2: Tempo planeamento (s) | D2: Tempo execução (s) | E2: Tempo total (s) | F2: Nº de pontos da trajetória planeados | G2: Comprimento trajetória planeada (m) | H2: Sucesso/Falha | I2: Observações | R2: ID TESTE | S2: Planner | T2: Tempo planeamento (s) | U2: Tempo execução (s) | V2: Tempo total (s) | W2: Nº de pontos da trajetória planeados | X2: Comprimento cartesiano TCP (m) | Y2: Sucesso/Falha | Z2: Observações
A3: O03_1 | B3: RRTConnect | C3: 0.11664 | D3: 4.494514 | E3: =D3+C3 -> 4.611154 | F3: 47 | G3: 2.831715 | H3: ✓ | R3: O03_1 | S3: RRTConnect | T3: 0.082687 | U3: 3.739917 | V3: =U3+T3 -> 3.822604 | W3: 39 | X3: 2.25386 | Y3: ✓
B4: RRTstar | C4: 0.093886 | D4: 3.685982 | E4: =D4+C4 -> 3.779868 | F4: 39 | G4: 2.255318 | H4: ✓ | S4: RRTstar | T4: 0.08838 | U4: 3.699086 | V4: =U4+T4 -> 3.787466 | W4: 39 | X4: 2.254267 | Y4: ✓
B5: PRMstar | C5: 0.074256 | D5: 3.738554 | E5: =D5+C5 -> 3.81281 | F5: 39 | G5: 2.255818 | H5: ✓ | S5: PRMstar | T5: 0.083433 | U5: 3.747185 | V5: =U5+T5 -> 3.830618 | W5: 39 | X5: 2.253931 | Y5: ✓
A6: O03_2 | B6: RRTConnect | C6: 0.123007 | D6: 5.293729 | E6: =D6+C6 -> 5.416736 | F6: 55 | G6: 4.304988 | H6: ✓ | I6: Replaneou a meio | R6: O03_2 | S6: RRTConnect | T6: 0.077683 | U6: 3.449855 | V6: =U6+T6 -> 3.527538 | W6: 36 | X6: 1.413859 | Y6: ✓
B7: RRTstar | C7: 0.10512 | D7: 3.443286 | E7: =D7+C7 -> 3.548406 | F7: 36 | G7: 1.41831 | H7: ✓ | K7: Planeadores | S7: RRTstar | T7: 0.106917 | U7: 3.451487 | V7: =U7+T7 -> 3.558404 | W7: 36 | X7: 1.414253 | Y7: ✓
B8: PRMstar | C8: 0.068455 | D8: 3.447129 | E8: =D8+C8 -> 3.515584 | F8: 36 | G8: 1.417461 | H8: ✓ | S8: PRMstar | T8: 0.078604 | U8: 3.455093 | V8: =U8+T8 -> 3.533697 | W8: 36 | X8: 1.418623 | Y8: ✓
A9: O07_1 | B9: RRTConnect | C9: 0.108201 | D9: 4.441911 | E9: =D9+C9 -> 4.550112 | F9: 46 | G9: 3.661822 | H9: ✓ | K9: planner_id: "RRTConnectkConfigDefault", | R9: O07_1 | S9: RRTConnect | T9: 0.187847 | U9: 6.851211 | V9: =U9+T9 -> 7.039058 | W9: 70 | X9: 2.498504 | Y9: ✓
B10: RRTstar | C10: 0.086584 | D10: 3.729423 | E10: =D10+C10 -> 3.816007 | F10: 39 | G10: 2.376257 | H10: ✓ | K10: planner_id: "RRTstarkConfigDefault", | S10: RRTstar | T10: 0.105006 | U10: 4.425236 | V10: =U10+T10 -> 4.530242 | W10: 46 | X10: 3.031576 | Y10: ✓
B11: PRMstar | C11: 0.190614 | D11: 8.247355 | E11: =D11+C11 -> 8.437969 | F11: 84 | G11: 4.425095 | H11: ✓ | I11: Replaneou a meio | K11: planner_id: "PRMstarkConfigDefault", | S11: PRMstar | T11: 0.085344 | U11: 4.443298 | V11: =U11+T11 -> 4.528642 | W11: 46 | X11: 3.653151 | Y11: ✓
A12: O07_2 | B12: RRTConnect | C12: 0.072171 | D12: 3.111598 | E12: =D12+C12 -> 3.183769 | F12: 32 | G12: 1.511817 | H12: ✓ | R12: O07_2 | S12: RRTConnect | T12: 0.080012 | U12: 3.101438 | V12: =U12+T12 -> 3.18145 | W12: 32 | X12: 1.512641 | Y12: ✓
B13: RRTstar | C13: 0.074056 | D13: 3.044419 | E13: =D13+C13 -> 3.118475 | F13: 32 | G13: 1.511741 | H13: ✓ | S13: RRTstar | T13: 0.092744 | U13: 3.154359 | V13: =U13+T13 -> 3.247103 | W13: 33 | X13: 1.51659 | Y13: ✓
B14: PRMstar | C14: - | D14: - | E14: - | F14: - | G14: - | H14: ⮾ | I14: tcp exceeds limit | S14: PRMstar | T14: 0.070766 | U14: 3.051946 | V14: =U14+T14 -> 3.122712 | W14: 32 | X14: 1.512954 | Y14: ✓
A15: O13_1 | B15: RRTConnect | C15: 0.088377 | D15: 3.693585 | E15: =D15+C15 -> 3.781962 | F15: 39 | G15: 2.2684 | H15: ✓ | R15: O13_1 | S15: RRTConnect | T15: 0.083687 | U15: 4.588965 | V15: =U15+T15 -> 4.672652 | W15: 48 | X15: 2.985891 | Y15: ✓
B16: RRTstar | C16: 0.073994 | D16: 4.58583 | E16: =D16+C16 -> 4.659824 | F16: 48 | G16: 2.984332 | H16: ✓ | S16: RRTstar | T16: 0.089515 | U16: 3.684394 | V16: =U16+T16 -> 3.773909 | W16: 39 | X16: 2.269585 | Y16: ✓
B17: PRMstar | C17: 0.0867 | D17: 4.544273 | E17: =D17+C17 -> 4.630973 | F17: 47 | G17: 2.984081 | H17: ✓ | S17: PRMstar | T17: 0.086239 | U17: 3.691285 | V17: =U17+T17 -> 3.777524 | W17: 39 | X17: 2.268542 | Y17: ✓
A18: O13_2 | B18: RRTConnect | C18: 0.087823 | D18: 2.887438 | E18: =D18+C18 -> 2.975261 | F18: 30 | G18: 1.184259 | H18: ✓ | R18: O13_2 | S18: RRTConnect | T18: 0.089548 | U18: 3.1045 | V18: =U18+T18 -> 3.194048 | W18: 33 | X18: 1.6754 | Y18: ✓
B19: RRTstar | C19: 0.096217 | D19: 4.496373 | E19: =D19+C19 -> 4.59259 | F19: 47 | G19: 3.916942 | H19: ✓ | S19: RRTstar | T19: 0.084791 | U19: 2.898822 | V19: =U19+T19 -> 2.983613 | W19: 30 | X19: 1.183167 | Y19: ✓
B20: PRMstar | C20: 0.105846 | D20: 4.546747 | E20: =D20+C20 -> 4.652593 | F20: 47 | G20: 3.91334 | H20: ✓ | L20: Tempo planeamento (s) | M20: Tempo execução(s) | N20: Tempo total (s) | O20: Pontos planeados | P20: Comprimento cartesiano TCP (m) | S20: PRMstar | T20: 0.076033 | U20: 2.893637 | V20: =U20+T20 -> 2.96967 | W20: 30 | X20: 1.184255 | Y20: ✓ | AC20: Tempo planeamento (s) | AD20: Tempo execução(s) | AE20: Tempo total (s) | AF20: Pontos planeados | AG20: Comprimento cartesiano TCP (m)
A21: O17_1 | B21: RRTConnect | C21: 0.104859 | D21: 4.243808 | E21: =D21+C21 -> 4.348667 | F21: 44 | G21: 3.388631 | H21: ✓ | K21: RRTConnect | L21: =AVERAGEIF(B3:B53,"RRTConnect",C3:C53) -> 0.10392818 | M21: =AVERAGEIF(B3:B53,"RRTConnect",D3:D53) -> 3.8426905 | N21: =AVERAGEIF(B3:B53,"RRTConnect",E3:E53) -> 3.9466187 | O21: =AVERAGEIF(B3:B53,"RRTConnect",F3:F53) -> 40.058824 | P21: =AVERAGEIF(B3:B53,"RRTConnect",G3:G53) -> 2.5743561 | R21: O17_1 | S21: RRTConnect | T21: 0.103292 | U21: 4.245147 | V21: =U21+T21 -> 4.348439 | W21: 44 | X21: 3.38228 | Y21: ✓ | AB21: RRTConnect | AC21: =AVERAGEIF(S3:S53,"RRTConnect",T3:T53) -> 0.090371647 | AD21: =AVERAGEIF(S3:S53,"RRTConnect",U3:U53) -> 3.9676868 | AE21: =AVERAGEIF(S3:S53,"RRTConnect",V3:V53) -> 4.0580584 | AF21: =AVERAGEIF(S3:S53,"RRTConnect",W3:W53) -> 40.588235 | AG21: =AVERAGEIF(S3:S53,"RRTConnect",X3:X53) -> 2.0454483
B22: RRTstar | C22: 0.081578 | D22: 4.247989 | E22: =D22+C22 -> 4.329567 | F22: 44 | G22: 3.382157 | H22: ✓ | K22: RRTstar | L22: =AVERAGEIF(B3:B53,"RRTstar",C3:C53) -> 0.086073118 | M22: =AVERAGEIF(B3:B53,"RRTstar",D3:D53) -> 3.6146478 | N22: =AVERAGEIF(B3:B53,"RRTstar",E3:E53) -> 3.7007209 | O22: =AVERAGEIF(B3:B53,"RRTstar",F3:F53) -> 38 | P22: =AVERAGEIF(B3:B53,"RRTstar",G3:G53) -> 2.1414779 | S22: RRTstar | T22: 0.107875 | U22: 3.63856 | V22: =U22+T22 -> 3.746435 | W22: 38 | X22: 2.275929 | Y22: ✓ | AB22: RRTstar | AC22: =AVERAGEIF(S3:S53,"RRTstar",T3:T53) -> 0.084629235 | AD22: =AVERAGEIF(S3:S53,"RRTstar",U3:U53) -> 3.5984899 | AE22: =AVERAGEIF(S3:S53,"RRTstar",V3:V53) -> 3.6831192 | AF22: =AVERAGEIF(S3:S53,"RRTstar",W3:W53) -> 37.647059 | AG22: =AVERAGEIF(S3:S53,"RRTstar",X3:X53) -> 1.9166411
B23: PRMstar | C23: 0.166186 | D23: 8.191961 | E23: =D23+C23 -> 8.358147 | F23: 83 | G23: 4.795527 | H23: ✓ | I23: Replaneou a meio | K23: PRMstar | L23: =AVERAGEIF(B3:B53,"PRMstar",C3:C53) -> 0.097574187 | M23: =AVERAGEIF(B3:B53,"PRMstar",D3:D53) -> 4.2471065 | N23: =AVERAGEIF(B3:B53,"PRMstar",E3:E53) -> 4.3446807 | O23: =AVERAGEIF(B3:B53,"PRMstar",F3:F53) -> 43.8125 | P23: =AVERAGEIF(B3:B53,"PRMstar",G3:G53) -> 2.4810594 | S23: PRMstar | T23: 0.069604 | U23: 3.648179 | V23: =U23+T23 -> 3.717783 | W23: 38 | X23: 2.40037 | Y23: ✓ | AB23: PRMstar | AC23: =AVERAGEIF(S3:S53,"PRMstar",T3:T53) -> 0.077802312 | AD23: =AVERAGEIF(S3:S53,"PRMstar",U3:U53) -> 3.5955822 | AE23: =AVERAGEIF(S3:S53,"PRMstar",V3:V53) -> 3.6733845 | AF23: =AVERAGEIF(S3:S53,"PRMstar",W3:W53) -> 37.5 | AG23: =AVERAGEIF(S3:S53,"PRMstar",X3:X53) -> 2.048612
A24: O17_2 | B24: RRTConnect | C24: 0.061878 | D24: 2.956337 | E24: =D24+C24 -> 3.018215 | F24: 31 | G24: 1.283322 | H24: ✓ | R24: O17_2 | S24: RRTConnect | T24: 0.082259 | U24: 2.94945 | V24: =U24+T24 -> 3.031709 | W24: 31 | X24: 1.281542 | Y24: ✓
B25: RRTstar | C25: 0.07636 | D25: 2.951064 | E25: =D25+C25 -> 3.027424 | F25: 31 | G25: 1.282566 | H25: ✓ | S25: RRTstar | T25: 0.062057 | U25: 4.894455 | V25: =U25+T25 -> 4.956512 | W25: 50 | X25: 2.268277 | Y25: ✓
B26: PRMstar | C26: 0.084393 | D26: 2.892393 | E26: =D26+C26 -> 2.976786 | F26: 30 | G26: 1.282419 | H26: ✓ | S26: PRMstar | T26: - | U26: - | V26: - | W26: - | X26: - | Y26: ⮾ | Z26: tcp exceeds limit
A27: O19_1 | B27: RRTConnect | C27: 0.113818 | D27: 4.150699 | E27: =D27+C27 -> 4.264517 | F27: 43 | G27: 3.20211 | H27: ✓ | R27: O19_1 | S27: RRTConnect | T27: 0.111239 | U27: 4.13184 | V27: =U27+T27 -> 4.243079 | W27: 43 | X27: 3.208593 | Y27: ✓
B28: RRTstar | C28: 0.099738 | D28: 3.49491 | E28: =D28+C28 -> 3.594648 | F28: 36 | G28: 2.843293 | H28: ✓ | S28: RRTstar | T28: 0.081919 | U28: 3.64681 | V28: =U28+T28 -> 3.728729 | W28: 38 | X28: 2.287549 | Y28: ✓
B29: PRMstar | C29: 0.093214 | D29: 3.549021 | E29: =D29+C29 -> 3.642235 | F29: 37 | G29: 2.842954 | H29: ✓ | S29: PRMstar | T29: 0.075128 | U29: 3.345159 | V29: =U29+T29 -> 3.420287 | W29: 35 | X29: 2.841398 | Y29: ✓
A30: O19_2 | B30: RRTConnect | C30: 0.139846 | D30: 5.009147 | E30: =D30+C30 -> 5.148993 | F30: 52 | G30: 3.038456 | H30: ✓ | R30: O19_2 | S30: RRTConnect | T30: 0.084166 | U30: 5.14577 | V30: =U30+T30 -> 5.229936 | W30: 53 | X30: 1.736696 | Y30: ✓
B31: RRTstar | C31: 0.063221 | D31: 3.438989 | E31: =D31+C31 -> 3.50221 | F31: 36 | G31: 1.387474 | H31: ✓ | S31: RRTstar | T31: 0.079678 | U31: 3.448502 | V31: =U31+T31 -> 3.52818 | W31: 36 | X31: 1.387032 | Y31: ✓
B32: PRMstar | C32: 0.11085 | D32: 3.489886 | E32: =D32+C32 -> 3.600736 | F32: 37 | G32: 1.387841 | H32: ✓ | S32: PRMstar | T32: 0.083302 | U32: 3.496417 | V32: =U32+T32 -> 3.579719 | W32: 36 | X32: 1.385943 | Y32: ✓
A33: O19_3 | B33: RRTConnect | C33: 0.160476 | D33: 4.697104 | E33: =D33+C33 -> 4.85758 | F33: 49 | G33: 5.27046 | H33: ✓ | R33: O19_3 | S33: RRTConnect | T33: 0.100665 | U33: 5.459283 | V33: =U33+T33 -> 5.559948 | W33: 50 | X33: 1.7896 | Y33: ✓
B34: RRTstar | C34: 0.074505 | D34: 3.749834 | E34: =D34+C34 -> 3.824339 | F34: 39 | G34: 1.290953 | H34: ✓ | S34: RRTstar | T34: 0.089813 | U34: 4.141409 | V34: =U34+T34 -> 4.231222 | W34: 43 | X34: 1.382786 | Y34: ✓
B35: PRMstar | C35: 0.08474 | D35: 4.051823 | E35: =D35+C35 -> 4.136563 | F35: 42 | G35: 1.385651 | H35: ✓ | S35: PRMstar | T35: 0.07881 | U35: 5.304874 | V35: =U35+T35 -> 5.383684 | W35: 55 | X35: 2.145516 | Y35: ✓
A36: O20_1 | B36: RRTConnect | C36: 0.093743 | D36: 3.667051 | E36: =D36+C36 -> 3.760794 | F36: 38 | G36: 2.729094 | H36: ✓ | R36: O20_1 | S36: RRTConnect | T36: 0.079825 | U36: 3.651495 | V36: =U36+T36 -> 3.73132 | W36: 38 | X36: 2.729487 | Y36: ✓
B37: RRTstar | C37: 0.102947 | D37: 3.650575 | E37: =D37+C37 -> 3.753522 | F37: 38 | G37: 2.72712 | H37: ✓ | S37: RRTstar | T37: 0.08062 | U37: 3.64263 | V37: =U37+T37 -> 3.72325 | W37: 38 | X37: 2.726754 | Y37: ✓
B38: PRMstar | C38: 0.084037 | D38: 3.646173 | E38: =D38+C38 -> 3.73021 | F38: 38 | G38: 2.728413 | H38: ✓ | S38: PRMstar | T38: 0.083501 | U38: 3.613625 | V38: =U38+T38 -> 3.697126 | W38: 37 | X38: 2.728794 | Y38: ✓
A39: O20_2 | B39: RRTConnect | C39: 0.078314 | D39: 2.897795 | E39: =D39+C39 -> 2.976109 | F39: 30 | G39: 1.326621 | H39: ✓ | R39: O20_2 | S39: RRTConnect | T39: 0.056326 | U39: 2.909568 | V39: =U39+T39 -> 2.965894 | W39: 30 | X39: 1.329051 | Y39: ✓
B40: RRTstar | C40: 0.083118 | D40: 2.885476 | E40: =D40+C40 -> 2.968594 | F40: 30 | G40: 1.328577 | H40: ✓ | S40: RRTstar | T40: 0.08446 | U40: 2.906466 | V40: =U40+T40 -> 2.990926 | W40: 30 | X40: 1.330644 | Y40: ✓
...

Sheet Resumo
A1: Resumo dos testes com obstáculos — caixa horizontal e vertical
A2: Teste de Obstáculos
A3: Sucesso de Comando /Comunicação | B3: Sucesso de Movimento | C3: Sucesso de Ciclo | D3: Sucesso de Teste de Seurança (Bloqueios por colisão) | E3: Falha de Planeamento | F3: Falha de Execução | G3: Falha de Comunicação
A4: 21 | B4: 12 | C4: 12 | D4: 5 | E4: 0 | F4: 0 | G4: 0
A5: Total de testes | B5: Falhas | C5: Sucessos | D5: Taxa de Sucesso
A6: 22 | B6: 0 | C6: 22 | D6: =C6/(B6+C6) -> 1
A8: Planeador | B8: Sucessos (✓) | C8: Falhas (✗) | D8: Taxa (%) | E8: Tempo Médio Total (s) | F8: Comprimento médio da trajetória cartesiano do TCP (m) | G8: Média do nº de pontos planeados | H8: Tempo médio de planeamento (s) | I8: Tempo médio de execução (s)
A9: RRTConnect | B9: ='Análise Estatística'!C4 -> 85 | C9: ='Análise Estatística'!D4 -> 0 | D9: ='Análise Estatística'!E4*100 -> 100 | E9: ='Análise Estatística'!D13 -> 3.8778369 | F9: ='Análise Estatística'!D14 -> 2.2710603 | G9: ='Análise Estatística'!D15 -> 39.188235 | H9: ='Análise Estatística'!D11 -> 0.091132341 | I9: ='Análise Estatística'!D12 -> 3.7867046
A10: PRMstar | B10: ='Análise Estatística'!C6 -> 79 | C10: ='Análise Estatística'!D6 -> 6 | D10: ='Análise Estatística'!E6*100 -> 92.941176 | E10: ='Análise Estatística'!D23 -> 3.9200068 | F10: ='Análise Estatística'!D24 -> 2.4807808 | G10: ='Análise Estatística'!D25 -> 40.164557 | H10: ='Análise Estatística'!D21 -> 0.091157316 | I10: ='Análise Estatística'!D22 -> 3.8288495
A11: RRTstar | B11: ='Análise Estatística'!C5 -> 82 | C11: ='Análise Estatística'!D5 -> 3 | D11: ='Análise Estatística'!E5*100 -> 96.470588 | E11: ='Análise Estatística'!D18 -> 3.827677 | F11: ='Análise Estatística'!D19 -> 2.205147 | G11: ='Análise Estatística'!D20 -> 39 | H11: ='Análise Estatística'!D16 -> 0.088657866 | I11: ='Análise Estatística'!D17 -> 3.7390192
